Workbook

Sheet 01
A3: LOST TIME EXCAVATOR PIT 55
A4: PERIODE DESEMBER 204
A5: Tanggal : | B5: 45627
A6: Shift | B6: No Unit | C6: HM Awal | D6: HM Akhir | E6: Total HM | F6: EWH | G6: Prodty | H6: PA | I6: UA | J6: DELAY OPERATION
J7: BD | K7: Perbaikan Front | L7: Pindah Front | M7: Stop loading menjelang istirahat | N7: Stop loading akhir shift | O7: Greasing | P7: Travel | Q7: Oli hydrolik & coolant | R7: Blasting | S7: Hujan | T7: Slippery | U7: Pengisian Fuel | V7: General | W7: STB | X7: Perbaikan Jalan | Y7: Washing | Z7: Start loading setealh sholat jumat | AA7: Total Loss Time
A8: Pagi | B8: PC1250-02 | AA8: =SUM(J8:Z8) -> 0
B9: PC1250-05 | AA9: =SUM(J9:Z9) -> 0
B10: PC1250-06 | AA10: =SUM(J10:Z10) -> 0
B11: PC1250-07 | N11: 0.0069444444 | W11: 0.32291667 | AA11: =SUM(J11:Z11) -> 0.32986111
B12: PC1250-10 | AA12: =SUM(J12:Z12) -> 0
B13: CAT395-02 | J13: 0.18611111 | K13: 0.00625 | M13: 0.0027777778 | T13: 0.052083333 | AA13: =SUM(J13:Z13) -> 0.24722222
B14: EC750-02 | AA14: =SUM(J14:Z14) -> 0
A15: Malam | B15: PC1250-02 | AA15: =SUM(J15:Z15) -> 0
B16: PC1250-05 | J16: 0.065277778 | M16: 0.0034722222 | N16: 0.00625 | AA16: =SUM(J16:Z16) -> 0.075
B17: PC1250-06 | AA17: =SUM(J17:Z17) -> 0
B18: PC1250-07 | K18: 0.0041666667 | M18: 0.0069444444 | N18: 0.0069444444 | AA18: =SUM(J18:Z18) -> 0.018055556
B19: PC1250-10 | J19: 0.14861111 | K19: 0.011111111 | M19: 0.0013888889 | AA19: =SUM(J19:Z19) -> 0.16111111
B20: CAT395-02 | M20: 0.0069444444 | N20: 0.0069444444 | AA20: =SUM(J20:Z20) -> 0.013888889
B21: EC750-02 | K21: 0.0076388889 | M21: 0.0069444444 | N21: 0.0069444444 | AA21: =SUM(J21:Z21) -> 0.021527778
A22: Total | B22: PC1250-02 | E22: =E8+E15 -> 0 | F22: =F8+F15 -> 0 | J22: =J8+J15 -> 0 | K22: =K8+K15 -> 0 | L22: =L8+L15 -> 0 | M22: =M8+M15 -> 0 | N22: =N8+N15 -> 0 | O22: =O8+O15 -> 0 | P22: =P8+P15 -> 0 | Q22: =Q8+Q15 -> 0 | ... Z22: =Z8+Z15 -> 0 | AA22: =SUM(J22:Z22) -> 0
B23: PC1250-05 | E23: =E9+E16 -> 0 | F23: =F9+F16 -> 0 | J23: =J9+J16 -> 0.065277778 | K23: =K9+K16 -> 0 | L23: =L9+L16 -> 0 | M23: =M9+M16 -> 0.0034722222 | N23: =N9+N16 -> 0.00625 | O23: =O9+O16 -> 0 | P23: =P9+P16 -> 0 | Q23: =Q9+Q16 -> 0 | ... Z23: =Z9+Z16 -> 0 | AA23: =SUM(J23:Z23) -> 0.075
B24: PC1250-06 | E24: =E10+E17 -> 0 | F24: =F10+F17 -> 0 | J24: =J10+J17 -> 0 | K24: =K10+K17 -> 0 | L24: =L10+L17 -> 0 | M24: =M10+M17 -> 0 | N24: =N10+N17 -> 0 | O24: =O10+O17 -> 0 | P24: =P10+P17 -> 0 | Q24: =Q10+Q17 -> 0 | ... Z24: =Z10+Z17 -> 0 | AA24: =SUM(J24:Z24) -> 0
B25: PC1250-07 | E25: =E11+E18 -> 0 | F25: =F11+F18 -> 0 | J25: =J11+J18 -> 0 | K25: =K11+K18 -> 0.0041666667 | L25: =L11+L18 -> 0 | M25: =M11+M18 -> 0.0069444444 | N25: =N11+N18 -> 0.013888889 | O25: =O11+O18 -> 0 | P25: =P11+P18 -> 0 | Q25: =Q11+Q18 -> 0 | ... Z25: =Z11+Z18 -> 0 | AA25: =SUM(J25:Z25) -> 0.34791667
B26: PC1250-10 | E26: =E12+E19 -> 0 | F26: =F12+F19 -> 0 | J26: =J12+J19 -> 0.14861111 | K26: =K12+K19 -> 0.011111111 | L26: =L12+L19 -> 0 | M26: =M12+M19 -> 0.0013888889 | N26: =N12+N19 -> 0 | O26: =O12+O19 -> 0 | P26: =P12+P19 -> 0 | Q26: =Q12+Q19 -> 0 | ... Z26: =Z12+Z19 -> 0 | AA26: =SUM(J26:Z26) -> 0.16111111
B27: CAT395-02 | E27: =E13+E20 -> 0 | F27: =F13+F20 -> 0 | J27: =J13+J20 -> 0.18611111 | K27: =K13+K20 -> 0.00625 | L27: =L13+L20 -> 0 | M27: =M13+M20 -> 0.0097222222 | N27: =N13+N20 -> 0.0069444444 | O27: =O13+O20 -> 0 | P27: =P13+P20 -> 0 | Q27: =Q13+Q20 -> 0 | ... Z27: =Z13+Z20 -> 0 | AA27: =SUM(J27:Z27) -> 0.26111111
B28: EC750-02 | E28: =E14+E21 -> 0 | F28: =F14+F21 -> 0 | J28: =J14+J21 -> 0 | K28: =K14+K21 -> 0.0076388889 | L28: =L14+L21 -> 0 | M28: =M14+M21 -> 0.0069444444 | N28: =N14+N21 -> 0.0069444444 | O28: =O14+O21 -> 0 | P28: =P14+P21 -> 0 | Q28: =Q14+Q21 -> 0 | ... Z28: =Z14+Z21 -> 0 | AA28: =SUM(J28:Z28) -> 0.021527778

Sheet 02
A3: LOST TIME EXCAVATOR PIT 55
A4: PERIODE DESEMBER 204
A5: Tanggal : | B5: ='01'!B5+1 -> 45628
A6: Shift | B6: No Unit | C6: HM Awal | D6: HM Akhir | E6: Total HM | F6: EWH | G6: Prodty | H6: PA | I6: UA | J6: DELAY OPERATION
J7: BD | K7: Perbaikan Front | L7: Pindah Front | M7: Stop loading menjelang istirahat | N7: Stop loading akhir shift | O7: Greasing | P7: Travel | Q7: Oli hydrolik & coolant | R7: Blasting | S7: Hujan | T7: Slippery | U7: Pengisian Fuel | V7: General | W7: STB | X7: Perbaikan Jalan | Y7: Washing | Z7: Start loading setealh sholat jumat | AA7: Total Loss Time
A8: Pagi | B8: PC1250-02 | J8: 0.41666667 | AA8: =SUM(J8:Z8) -> 0.41666667
B9: PC1250-05 | J9: 0.052083333 | K9: 0.0034722222 | M9: 0.0069444444 | R9: 0.017361111 | AA9: =SUM(J9:Z9) -> 0.079861111
B10: PC1250-06 | AA10: =SUM(J10:Z10) -> 0
B11: PC1250-07 | M11: 0.00625 | N11: 0.010416667 | R11: 0.013888889 | AA11: =SUM(J11:Z11) -> 0.030555556
B12: PC1250-10 | J12: 0.41666667 | AA12: =SUM(J12:Z12) -> 0.41666667
B13: CAT395-02 | J13: 0.030555556 | K13: 0.0027777778 | M13: 0.0069444444 | N13: 0.0041666667 | AA13: =SUM(J13:Z13) -> 0.044444444
B14: EC750-02 | K14: 0.0055555556 | M14: 0.0034722222 | V14: 0.092361111 | W14: 0.015277778 | AA14: =SUM(J14:Z14) -> 0.11666667
A15: Malam | B15: PC1250-02 | J15: 0.34375 | S15: 0.052083333 | AA15: =SUM(J15:Z15) -> 0.39583333
B16: PC1250-05 | J16: 0.34375 | S16: 0.052083333 | AA16: =SUM(J16:Z16) -> 0.39583333
B17: PC1250-06 | AA17: =SUM(J17:Z17) -> 0
B18: PC1250-07 | K18: 0.0125 | M18: 0.0069444444 | S18: 0.052083333 | AA18: =SUM(J18:Z18) -> 0.071527778
B19: PC1250-10 | J19: 0.19930556 | S19: 0.052083333 | AA19: =SUM(J19:Z19) -> 0.25138889
B20: CAT395-02 | J20: 0.060416667 | M20: 0.0020833333 | S20: 0.052083333 | AA20: =SUM(J20:Z20) -> 0.11458333
B21: EC750-02 | K21: 0.0027777778 | M21: 0.00069444444 | S21: 0.052083333 | AA21: =SUM(J21:Z21) -> 0.055555556
A22: Total | B22: PC1250-02 | E22: =E8+E15 -> 0 | F22: =F8+F15 -> 0 | J22: =J8+J15 -> 0.76041667 | K22: =K8+K15 -> 0 | L22: =L8+L15 -> 0 | M22: =M8+M15 -> 0 | N22: =N8+N15 -> 0 | O22: =O8+O15 -> 0 | P22: =P8+P15 -> 0 | Q22: =Q8+Q15 -> 0 | ... Z22: =Z8+Z15 -> 0 | AA22: =SUM(J22:Z22) -> 0.8125
B23: PC1250-05 | E23: =E9+E16 -> 0 | F23: =F9+F16 -> 0 | J23: =J9+J16 -> 0.39583333 | K23: =K9+K16 -> 0.0034722222 | L23: =L9+L16 -> 0 | M23: =M9+M16 -> 0.0069444444 | N23: =N9+N16 -> 0 | O23: =O9+O16 -> 0 | P23: =P9+P16 -> 0 | Q23: =Q9+Q16 -> 0 | ... Z23: =Z9+Z16 -> 0 | AA23: =SUM(J23:Z23) -> 0.47569444
B24: PC1250-06 | E24: =E10+E17 -> 0 | F24: =F10+F17 -> 0 | J24: =J10+J17 -> 0 | K24: =K10+K17 -> 0 | L24: =L10+L17 -> 0 | M24: =M10+M17 -> 0 | N24: =N10+N17 -> 0 | O24: =O10+O17 -> 0 | P24: =P10+P17 -> 0 | Q24: =Q10+Q17 -> 0 | ... Z24: =Z10+Z17 -> 0 | AA24: =SUM(J24:Z24) -> 0
B25: PC1250-07 | E25: =E11+E18 -> 0 | F25: =F11+F18 -> 0 | J25: =J11+J18 -> 0 | K25: =K11+K18 -> 0.0125 | L25: =L11+L18 -> 0 | M25: =M11+M18 -> 0.013194444 | N25: =N11+N18 -> 0.010416667 | O25: =O11+O18 -> 0 | P25: =P11+P18 -> 0 | Q25: =Q11+Q18 -> 0 | ... Z25: =Z11+Z18 -> 0 | AA25: =SUM(J25:Z25) -> 0.10208333
B26: PC1250-10 | E26: =E12+E19 -> 0 | F26: =F12+F19 -> 0 | J26: =J12+J19 -> 0.61597222 | K26: =K12+K19 -> 0 | L26: =L12+L19 -> 0 | M26: =M12+M19 -> 0 | N26: =N12+N19 -> 0 | O26: =O12+O19 -> 0 | P26: =P12+P19 -> 0 | Q26: =Q12+Q19 -> 0 | ... Z26: =Z12+Z19 -> 0 | AA26: =SUM(J26:Z26) -> 0.66805556
B27: CAT395-02 | E27: =E13+E20 -> 0 | F27: =F13+F20 -> 0 | J27: =J13+J20 -> 0.090972222 | K27: =K13+K20 -> 0.0027777778 | L27: =L13+L20 -> 0 | M27: =M13+M20 -> 0.0090277778 | N27: =N13+N20 -> 0.0041666667 | O27: =O13+O20 -> 0 | P27: =P13+P20 -> 0 | Q27: =Q13+Q20 -> 0 | ... Z27: =Z13+Z20 -> 0 | AA27: =SUM(J27:Z27) -> 0.15902778
B28: EC750-02 | E28: =E14+E21 -> 0 | F28: =F14+F21 -> 0 | J28: =J14+J21 -> 0 | K28: =K14+K21 -> 0.0083333333 | L28: =L14+L21 -> 0 | M28: =M14+M21 -> 0.0041666667 | N28: =N14+N21 -> 0 | O28: =O14+O21 -> 0 | P28: =P14+P21 -> 0 | Q28: =Q14+Q21 -> 0 | ... Z28: =Z14+Z21 -> 0 | AA28: =SUM(J28:Z28) -> 0.17222222

Sheet 03
A3: LOST TIME EXCAVATOR PIT 55
A4: PERIODE DESEMBER 204
A5: Tanggal : | B5: ='02'!B5+1 -> 45629
A6: Shift | B6: No Unit | C6: HM Awal | D6: HM Akhir | E6: Total HM | F6: EWH | G6: Prodty | H6: PA | I6: UA | J6: DELAY OPERATION
J7: BD | K7: Perbaikan Front | L7: Pindah Front | M7: Stop loading menjelang istirahat | N7: Stop loading akhir shift | O7: Greasing | P7: Travel | Q7: Oli hydrolik & coolant | R7: Blasting | S7: Hujan | T7: Slippery | U7: Pengisian Fuel | V7: General | W7: STB | X7: Perbaikan Jalan | Y7: Washing | Z7: Start loading setealh sholat jumat | AA7: Total Loss Time | AB7: LOSS TIME RM | AG7: LOSS TIME PROD
A8: Pagi | B8: PC1250-02 | J8: 0.38194444 | S8: 0.034722222 | AA8: =SUM(J8:Z8) -> 0.41666667 | AB8: =+J8+O8+Q8+U8 -> 0.38194444 | AC8: =0+(0/60) -> 0 | AD8: 400 | AE8: =+AC8*AD8 -> 0 | AF8: =SUM(AE8:AE14) -> 4100 | AG8: =+K8+L8+M8+N8+R8+S8+T8+V8 -> 0.034722222 | AH8: =4+(3/60) -> 4.05 | AI8: 400 | AJ8: =+AH8*AI8 -> 1620 | AK8: =SUM(AJ8:AJ14) -> 11505.833
B9: PC1250-05 | J9: 0.16666667 | L9: 0.025694444 | M9: 0.0069444444 | AA9: =SUM(J9:Z9) -> 0.19930556 | AB9: =+J9+O9+Q9+U9 -> 0.16666667 | AC9: =0+(0/60) -> 0 | AD9: 400 | AE9: =+AC9*AD9 -> 0 | AG9: =+K9+L9+M9+N9+R9+S9+T9+V9 -> 0.032638889 | AH9: =10+(0/60) -> 10 | AI9: 400 | AJ9: =+AH9*AI9 -> 4000
B10: PC1250-06
B11: PC1250-07 | M11: 0.0020833333 | N11: 0.0055555556 | S11: 0.034722222 | T11: 0.079861111 | AA11: =SUM(J11:Z11) -> 0.12222222 | AB11: =+J11+O11+Q11+U11 -> 0 | AC11: =8+(30/60) -> 8.5 | AD11: 400 | AE11: =+AC11*AD11 -> 3400 | AG11: =+K11+L11+M11+N11+R11+S11+T11+V11 -> 0.12222222 | AH11: =1+(30/60) -> 1.5 | AI11: 400 | AJ11: =+AH11*AI11 -> 600
B12: PC1250-10 | N12: 0.0069444444 | R12: 0.011111111 | S12: 0.034722222 | T12: 0.076388889 | U12: 0.0034722222 | AA12: =SUM(J12:Z12) -> 0.13263889 | AB12: =+J12+O12+Q12+U12 -> 0.0034722222 | AC12: =0+(0/60) -> 0 | AD12: 400 | AE12: =+AC12*AD12 -> 0 | AG12: =+K12+L12+M12+N12+R12+S12+T12+V12 -> 0.12916667 | AH12: =3+(56/60) -> 3.9333333 | AI12: 400 | AJ12: =+AH12*AI12 -> 1573.3333
B13: CAT395-02 | M13: 0.0069444444 | N13: 0.0069444444 | S13: 0.034722222 | T13: 0.076388889 | AA13: =SUM(J13:Z13) -> 0.125 | AB13: =+J13+O13+Q13+U13 -> 0 | AC13: =0+(0/60) -> 0 | AD13: 450 | AE13: =+AC13*AD13 -> 0 | AG13: =+K13+L13+M13+N13+R13+S13+T13+V13 -> 0.125 | AH13: =3+(35/60) -> 3.5833333 | AI13: 450 | AJ13: =+AH13*AI13 -> 1612.5
B14: EC750-02 | K14: 0.010416667 | M14: 0.0069444444 | S14: 0.034722222 | T14: 0.079861111 | V14: 0.25 | AA14: =SUM(J14:Z14) -> 0.38194444 | AB14: =+J14+O14+Q14+U14 -> 0 | AC14: =2+(0/60) -> 2 | AD14: 350 | AE14: =+AC14*AD14 -> 700 | AG14: =+K14+L14+M14+N14+R14+S14+T14+V14 -> 0.38194444 | AH14: =6+(0/60) -> 6 | AI14: 350 | AJ14: =+AH14*AI14 -> 2100
A15: Malam | B15: PC1250-02 | J15: 0.41666667 | AA15: =SUM(J15:Z15) -> 0.41666667 | AB15: =+J15+O15+Q15+U15 -> 0.41666667 | AC15: =0+(40/60) -> 0.66666667 | AD15: 400 | AE15: =+AC15*AD15 -> 266.66667 | AF15: =SUM(AE15:AE21) -> 5626.6667 | AG15: =+K15+L15+M15+N15+R15+S15+T15+V15 -> 0 | AH15: =0+(44/60) -> 0.73333333 | AI15: 400 | AJ15: =+AH15*AI15 -> 293.33333 | AK15: =SUM(AJ15:AJ21) -> 1137.5
B16: PC1250-05 | K16: 0.0013888889 | M16: 0.0048611111 | N16: 0.0069444444 | AA16: =SUM(J16:Z16) -> 0.013194444 | AB16: =+J16+O16+Q16+U16 -> 0 | AC16: =0+(39/60) -> 0.65 | AD16: 400 | AE16: =+AC16*AD16 -> 260 | AG16: =+K16+L16+M16+N16+R16+S16+T16+V16 -> 0.013194444 | AH16: =0+(28/60) -> 0.46666667 | AI16: 400 | AJ16: =+AH16*AI16 -> 186.66667
B17: PC1250-06
B18: PC1250-07 | K18: 0.0034722222 | M18: 0.0069444444 | N18: 0.010416667 | AA18: =SUM(J18:Z18) -> 0.020833333 | AB18: =+J18+O18+Q18+U18 -> 0 | AC18: =10+(0/60) -> 10 | AD18: 400 | AE18: =+AC18*AD18 -> 4000 | AG18: =+K18+L18+M18+N18+R18+S18+T18+V18 -> 0.020833333 | AH18: =0+(0/60) -> 0 | AI18: 400 | AJ18: =+AH18*AI18 -> 0
B19: PC1250-10 | J19: 0.023611111 | K19: 0.0055555556 | L19: 0.0125 | M19: 0.0034722222 | N19: 0.0020833333 | AA19: =SUM(J19:Z19) -> 0.047222222 | AB19: =+J19+O19+Q19+U19 -> 0.023611111 | AC19: =1+(0/60) -> 1 | AD19: 400 | AE19: =+AC19*AD19 -> 400 | AG19: =+K19+L19+M19+N19+R19+S19+T19+V19 -> 0.023611111 | AH19: =0+(23/60) -> 0.38333333 | AI19: 400 | AJ19: =+AH19*AI19 -> 153.33333
B20: CAT395-02 | K20: 0.0083333333 | M20: 0.0055555556 | N20: 0.0069444444 | AA20: =SUM(J20:Z20) -> 0.020833333 | AB20: =+J20+O20+Q20+U20 -> 0 | AC20: =0+(0/60) -> 0 | AD20: 450 | AE20: =+AC20*AD20 -> 0 | AG20: =+K20+L20+M20+N20+R20+S20+T20+V20 -> 0.020833333 | AH20: =0+(47/60) -> 0.78333333 | AI20: 450 | AJ20: =+AH20*AI20 -> 352.5
B21: EC750-02 | K21: 0.026388889 | M21: 0.0027777778 | V21: 0.125 | W21: 0.083333333 | AA21: =SUM(J21:Z21) -> 0.2375 | AB21: =+J21+O21+Q21+U21 -> 0 | AC21: =2+(0/60) -> 2 | AD21: 350 | AE21: =+AC21*AD21 -> 700 | AG21: =+K21+L21+M21+N21+R21+S21+T21+V21 -> 0.15416667 | AH21: =0+(26/60) -> 0.43333333 | AI21: 350 | AJ21: =+AH21*AI21 -> 151.66667
A22: Total | B22: PC1250-02 | E22: =E8+E15 -> 0 | F22: =F8+F15 -> 0 | J22: =J8+J15 -> 0.79861111 | K22: =K8+K15 -> 0 | L22: =L8+L15 -> 0 | M22: =M8+M15 -> 0 | N22: =N8+N15 -> 0 | O22: =O8+O15 -> 0 | P22: =P8+P15 -> 0 | Q22: =Q8+Q15 -> 0 | ... Z22: =Z8+Z15 -> 0 | AA22: =SUM(J22:Z22) -> 0.83333333
B23: PC1250-05 | E23: =E9+E16 -> 0 | F23: =F9+F16 -> 0 | J23: =J9+J16 -> 0.16666667 | K23: =K9+K16 -> 0.0013888889 | L23: =L9+L16 -> 0.025694444 | M23: =M9+M16 -> 0.011805556 | N23: =N9+N16 -> 0.0069444444 | O23: =O9+O16 -> 0 | P23: =P9+P16 -> 0 | Q23: =Q9+Q16 -> 0 | ... Z23: =Z9+Z16 -> 0 | AA23: =SUM(J23:Z23) -> 0.2125
B24: PC1250-06 | E24: =E10+E17 -> 0 | F24: =F10+F17 -> 0 | J24: =J10+J17 -> 0 | K24: =K10+K17 -> 0 | L24: =L10+L17 -> 0 | M24: =M10+M17 -> 0 | N24: =N10+N17 -> 0 | O24: =O10+O17 -> 0 | P24: =P10+P17 -> 0 | Q24: =Q10+Q17 -> 0 | ... Z24: =Z10+Z17 -> 0 | AA24: =SUM(J24:Z24) -> 0
B25: PC1250-07 | E25: =E11+E18 -> 0 | F25: =F11+F18 -> 0 | J25: =J11+J18 -> 0 | K25: =K11+K18 -> 0.0034722222 | L25: =L11+L18 -> 0 | M25: =M11+M18 -> 0.0090277778 | N25: =N11+N18 -> 0.015972222 | O25: =O11+O18 -> 0 | P25: =P11+P18 -> 0 | Q25: =Q11+Q18 -> 0 | ... Z25: =Z11+Z18 -> 0 | AA25: =SUM(J25:Z25) -> 0.14305556
B26: PC1250-10 | E26: =E12+E19 -> 0 | F26: =F12+F19 -> 0 | J26: =J12+J19 -> 0.023611111 | K26: =K12+K19 -> 0.0055555556 | L26: =L12+L19 -> 0.0125 | M26: =M12+M19 -> 0.0034722222 | N26: =N12+N19 -> 0.0090277778 | O26: =O12+O19 -> 0 | P26: =P12+P19 -> 0 | Q26: =Q12+Q19 -> 0 | ... Z26: =Z12+Z19 -> 0 | AA26: =SUM(J26:Z26) -> 0.17986111
B27: CAT395-02 | E27: =E13+E20 -> 0 | F27: =F13+F20 -> 0 | J27: =J13+J20 -> 0 | K27: =K13+K20 -> 0.0083333333 | L27: =L13+L20 -> 0 | M27: =M13+M20 -> 0.0125 | N27: =N13+N20 -> 0.013888889 | O27: =O13+O20 -> 0 | P27: =P13+P20 -> 0 | Q27: =Q13+Q20 -> 0 | ... Z27: =Z13+Z20 -> 0 | AA27: =SUM(J27:Z27) -> 0.14583333
B28: EC750-02 | E28: =E14+E21 -> 0 | F28: =F14+F21 -> 0 | J28: =J14+J21 -> 0 | K28: =K14+K21 -> 0.036805556 | L28: =L14+L21 -> 0 | M28: =M14+M21 -> 0.0097222222 | N28: =N14+N21 -> 0 | O28: =O14+O21 -> 0 | P28: =P14+P21 -> 0 | Q28: =Q14+Q21 -> 0 | ... Z28: =Z14+Z21 -> 0 | AA28: =SUM(J28:Z28) -> 0.61944444

Sheet 04
A3: LOST TIME EXCAVATOR PIT 55
A4: PERIODE DESEMBER 204
A5: Tanggal : | B5: ='03'!B5+1 -> 45630
A6: Shift | B6: No Unit | C6: HM Awal | D6: HM Akhir | E6: Total HM | F6: EWH | G6: Prodty | H6: PA | I6: UA | J6: DELAY OPERATION
J7: BD | K7: Perbaikan Front | L7: Pindah Front | M7: Stop loading menjelang istirahat | N7: Stop loading akhir shift | O7: Greasing | P7: Travel | Q7: Oli hydrolik & coolant | R7: Blasting | S7: Hujan | T7: Slippery | U7: Pengisian Fuel | V7: General | W7: STB | X7: Perbaikan Jalan | Y7: Washing | Z7: Start loading setelah sholat jumat | AA7: Total Loss Time | AB7: LOSS TIME RM | AG7: LOSS TIME PROD
A8: Pagi | B8: PC1250-02 | J8: 0.41666667 | AA8: =SUM(J8:Z8) -> 0.41666667 | AB8: =+J8+O8+Q8+U8 -> 0.41666667 | AC8: =2+(20/60) -> 2.3333333 | AD8: 400 | AE8: =+AC8*AD8 -> 933.33333 | AF8: =SUM(AE8:AE14) -> 7716.6667 | AG8: =+K8+L8+M8+N8+R8+S8+T8+V8 -> 0 | AH8: =0+(9/60) -> 0.15 | AI8: 400 | AJ8: =+AH8*AI8 -> 60 | AK8: =SUM(AJ8:AJ14) -> 883.33333
B9: PC1250-05 | J9: 0.0020833333 | K9: 0.0097222222 | N9: 0.0069444444 | O9: 0.01875 | R9: 0.011805556 | AA9: =SUM(J9:Z9) -> 0.049305556 | AB9: =+J9+O9+Q9+U9 -> 0.020833333 | AC9: =0+(0/60) -> 0 | AD9: 400 | AE9: =+AC9*AD9 -> 0 | AG9: =+K9+L9+M9+N9+R9+S9+T9+V9 -> 0.028472222 | AH9: =0+(45/60) -> 0.75 | AI9: 400 | AJ9: =+AH9*AI9 -> 300
B10: PC1250-06 | AA10: =SUM(J10:Z10) -> 0
B11: PC1250-07 | J11: 0.11388889 | M11: 0.0069444444 | N11: 0.0069444444 | AA11: =SUM(J11:Z11) -> 0.12777778 | AB11: =+J11+O11+Q11+U11 -> 0.11388889 | AC11: =10+(0/60) -> 10 | AD11: 400 | AE11: =+AC11*AD11 -> 4000 | AG11: =+K11+L11+M11+N11+R11+S11+T11+V11 -> 0.013888889 | AH11: =0+(0/60) -> 0 | AI11: 400 | AJ11: =+AH11*AI11 -> 0
B12: PC1250-10 | J12: 0.1 | K12: 0.011111111 | M12: 0.0055555556 | N12: 0.0069444444 | O12: 0.011111111 | AA12: =SUM(J12:Z12) -> 0.13472222 | AB12: =+J12+O12+Q12+U12 -> 0.11111111 | AC12: =4+(20/60) -> 4.3333333 | AD12: 400 | AE12: =+AC12*AD12 -> 1733.3333 | AG12: =+K12+L12+M12+N12+R12+S12+T12+V12 -> 0.023611111 | AH12: =0+(37/60) -> 0.61666667 | AI12: 400 | AJ12: =+AH12*AI12 -> 246.66667
B13: CAT395-02 | K13: 0.0027777778 | L13: 0.0041666667 | M13: 0.0069444444 | N13: 0.0013888889 | AA13: =SUM(J13:Z13) -> 0.015277778 | AB13: =+J13+O13+Q13+U13 -> 0 | AC13: =0+(0/60) -> 0 | AD13: 450 | AE13: =+AC13*AD13 -> 0 | AG13: =+K13+L13+M13+N13+R13+S13+T13+V13 -> 0.015277778 | AH13: =0+(33/60) -> 0.55 | AI13: 450 | AJ13: =+AH13*AI13 -> 247.5
B14: EC750-02 | K14: 0.0013888889 | M14: 0.0069444444 | W14: 0.029861111 | AA14: =SUM(J14:Z14) -> 0.038194444 | AB14: =+J14+O14+Q14+U14 -> 0 | AC14: =3+(0/60) -> 3 | AD14: 350 | AE14: =+AC14*AD14 -> 1050 | AG14: =+K14+L14+M14+N14+R14+S14+T14+V14 -> 0.0083333333 | AH14: =0+(5/60) -> 0.083333333 | AI14: 350 | AJ14: =+AH14*AI14 -> 29.166667
A15: Malam | B15: PC1250-02 | J15: 0.26041667 | S15: 0.15625 | AA15: =SUM(J15:Z15) -> 0.41666667 | AB15: =+J15+O15+Q15+U15 -> 0.26041667 | AC15: =0+(0/60) -> 0 | AD15: 400 | AE15: =+AC15*AD15 -> 0 | AF15: =SUM(AE15:AE21) -> 4046.6667 | AG15: =+K15+L15+M15+N15+R15+S15+T15+V15 -> 0.15625 | AH15: =0+(19/60) -> 0.31666667 | AI15: 400 | AJ15: =+AH15*AI15 -> 126.66667 | AK15: =SUM(AJ15:AJ21) -> 1105.8333
B16: PC1250-05 | K16: 0.0034722222 | M16: 0.0069444444 | S16: 0.15625 | AA16: =SUM(J16:Z16) -> 0.16666667 | AB16: =+J16+O16+Q16+U16 -> 0 | AC16: =0+(0/60) -> 0 | AD16: 400 | AE16: =+AC16*AD16 -> 0 | AG16: =+K16+L16+M16+N16+R16+S16+T16+V16 -> 0.16666667 | AH16: =0+(34/60) -> 0.56666667 | AI16: 400 | AJ16: =+AH16*AI16 -> 226.66667
B17: PC1250-06 | AA17: =SUM(J17:Z17) -> 0 | AB17: =+J17+O17+Q17+U17 -> 0
B18: PC1250-07 | M18: 0.0069444444 | S18: 0.15625 | AA18: =SUM(J18:Z18) -> 0.16319444 | AB18: =+J18+O18+Q18+U18 -> 0 | AC18: =10+(0/60) -> 10 | AD18: 400 | AE18: =+AC18*AD18 -> 4000 | AG18: =+K18+L18+M18+N18+R18+S18+T18+V18 -> 0.16319444 | AH18: =0+(0/60) -> 0 | AI18: 400 | AJ18: =+AH18*AI18 -> 0
B19: PC1250-10 | M19: 0.0041666667 | S19: 0.15625 | AA19: =SUM(J19:Z19) -> 0.16041667 | AB19: =+J19+O19+Q19+U19 -> 0 | AC19: =0+(7/60) -> 0.11666667 | AD19: 400 | AE19: =+AC19*AD19 -> 46.666667 | AG19: =+K19+L19+M19+N19+R19+S19+T19+V19 -> 0.16041667 | AH19: =0+(41/60) -> 0.68333333 | AI19: 400 | AJ19: =+AH19*AI19 -> 273.33333
B20: CAT395-02 | K20: 0.0020833333 | M20: 0.0069444444 | S20: 0.15625 | AA20: =SUM(J20:Z20) -> 0.16527778 | AB20: =+J20+O20+Q20+U20 -> 0 | AC20: =0+(0/60) -> 0 | AD20: 450 | AE20: =+AC20*AD20 -> 0 | AG20: =+K20+L20+M20+N20+R20+S20+T20+V20 -> 0.16527778 | AH20: =0+(32/60) -> 0.53333333 | AI20: 450 | AJ20: =+AH20*AI20 -> 240
B21: EC750-02 | AA21: =SUM(J21:Z21) -> 0 | AB21: =+J21+O21+Q21+U21 -> 0 | AC21: =0+(0/60) -> 0 | AD21: 350 | AE21: =+AC21*AD21 -> 0 | AG21: =+K21+L21+M21+N21+R21+S21+T21+V21 -> 0 | AH21: =0+(41/60) -> 0.68333333 | AI21: 350 | AJ21: =+AH21*AI21 -> 239.16667
A22: Total | B22: PC1250-02 | E22: =E8+E15 -> 0 | F22: =F8+F15 -> 0 | J22: =J8+J15 -> 0.67708333 | K22: =K8+K15 -> 0 | L22: =L8+L15 -> 0 | M22: =M8+M15 -> 0 | N22: =N8+N15 -> 0 | O22: =O8+O15 -> 0 | P22: =P8+P15 -> 0 | Q22: =Q8+Q15 -> 0 | ... Z22: =Z8+Z15 -> 0 | AA22: =SUM(J22:Z22) -> 0.83333333 | AB22: Total loss time RM | AF22: =+AF15+AF8 -> 11763.333 | AG22: Total loss time Produksi | AK22: =+AK15+AK8 -> 1989.1667
B23: PC1250-05 | E23: =E9+E16 -> 0 | F23: =F9+F16 -> 0 | J23: =J9+J16 -> 0.0020833333 | K23: =K9+K16 -> 0.013194444 | L23: =L9+L16 -> 0 | M23: =M9+M16 -> 0.0069444444 | N23: =N9+N16 -> 0.0069444444 | O23: =O9+O16 -> 0.01875 | P23: =P9+P16 -> 0 | Q23: =Q9+Q16 -> 0 | ... Z23: =Z9+Z16 -> 0 | AA23: =SUM(J23:Z23) -> 0.21597222
B24: PC1250-06 | E24: =E10+E17 -> 0 | F24: =F10+F17 -> 0 | J24: =J10+J17 -> 0 | K24: =K10+K17 -> 0 | L24: =L10+L17 -> 0 | M24: =M10+M17 -> 0 | N24: =N10+N17 -> 0 | O24: =O10+O17 -> 0 | P24: =P10+P17 -> 0 | Q24: =Q10+Q17 -> 0 | ... Z24: =Z10+Z17 -> 0 | AA24: =SUM(J24:Z24) -> 0
B25: PC1250-07 | E25: =E11+E18 -> 0 | F25: =F11+F18 -> 0 | J25: =J11+J18 -> 0.11388889 | K25: =K11+K18 -> 0 | L25: =L11+L18 -> 0 | M25: =M11+M18 -> 0.013888889 | N25: =N11+N18 -> 0.0069444444 | O25: =O11+O18 -> 0 | P25: =P11+P18 -> 0 | Q25: =Q11+Q18 -> 0 | ... Z25: =Z11+Z18 -> 0 | AA25: =SUM(J25:Z25) -> 0.29097222
B26: PC1250-10 | E26: =E12+E19 -> 0 | F26: =F12+F19 -> 0 | J26: =J12+J19 -> 0.1 | K26: =K12+K19 -> 0.011111111 | L26: =L12+L19 -> 0 | M26: =M12+M19 -> 0.0097222222 | N26: =N12+N19 -> 0.0069444444 | O26: =O12+O19 -> 0.011111111 | P26: =P12+P19 -> 0 | Q26: =Q12+Q19 -> 0 | ... Z26: =Z12+Z19 -> 0 | AA26: =SUM(J26:Z26) -> 0.29513889
B27: CAT395-02 | E27: =E13+E20 -> 0 | F27: =F13+F20 -> 0 | J27: =J13+J20 -> 0 | K27: =K13+K20 -> 0.0048611111 | L27: =L13+L20 -> 0.0041666667 | M27: =M13+M20 -> 0.013888889 | N27: =N13+N20 -> 0.0013888889 | O27: =O13+O20 -> 0 | P27: =P13+P20 -> 0 | Q27: =Q13+Q20 -> 0 | ... Z27: =Z13+Z20 -> 0 | AA27: =SUM(J27:Z27) -> 0.18055556
B28: EC750-02 | E28: =E14+E21 -> 0 | F28: =F14+F21 -> 0 | J28: =J14+J21 -> 0 | K28: =K14+K21 -> 0.0013888889 | L28: =L14+L21 -> 0 | M28: =M14+M21 -> 0.0069444444 | N28: =N14+N21 -> 0 | O28: =O14+O21 -> 0 | P28: =P14+P21 -> 0 | Q28: =Q14+Q21 -> 0 | ... Z28: =Z14+Z21 -> 0 | AA28: =SUM(J28:Z28) -> 0.038194444

Sheet 05
A3: LOST TIME EXCAVATOR PIT 55
A4: PERIODE DESEMBER 204
A5: Tanggal : | B5: ='04'!B5+1 -> 45631
A6: Shift | B6: No Unit | C6: HM Awal | D6: HM Akhir | E6: Total HM | F6: EWH | G6: Prodty | H6: PA | I6: UA | J6: DELAY OPERATION
J7: BD | K7: Perbaikan Front | L7: Pindah Front | M7: Stop loading menjelang istirahat | N7: Stop loading akhir shift | O7: Greasing | P7: Travel | Q7: Oli hydrolik & coolant | R7: Blasting | S7: Hujan | T7: Slippery | U7: Pengisian Fuel | V7: General | W7: STB | X7: Perbaikan Jalan | Y7: Washing | AA7: Total Loss Time | AB7: LOSS TIME RM | AG7: LOSS TIME PROD
A8: Pagi | B8: PC1250-02 | J8: 0.30555556 | S8: 0.11111111 | AA8: =SUM(J8:Z8) -> 0.41666667 | AB8: =+J8+O8+Q8+U8 -> 0.30555556 | AC8: =0+(24/60) -> 0.4 | AD8: 400 | AE8: =+AC8*AD8 -> 160 | AF8: =SUM(AE8:AE14) -> 2486.6667 | AG8: =+K8+L8+M8+N8+R8+S8+T8+V8+W8+X8+Y8+Z8 -> 0.11111111 | AH8: =0+(5/60) -> 0.083333333 | AI8: 400 | AJ8: =+AH8*AI8 -> 33.333333 | AK8: =SUM(AJ8:AJ14) -> 1760.8333
B9: PC1250-05 | J9: 0.16111111 | M9: 0.00069444444 | N9: 0.0069444444 | R9: 0.024305556 | S9: 0.11111111 | T9: 0.023611111 | AA9: =SUM(J9:Z9) -> 0.32777778 | AB9: =+J9+O9+Q9+U9 -> 0.16111111 | AC9: =1+(45/60) -> 1.75 | AD9: 400 | AE9: =+AC9*AD9 -> 700 | AG9: =+K9+L9+M9+N9+R9+S9+T9+V9+W9+X9+Y9+Z9 -> 0.16666667 | AH9: =0+(12/60) -> 0.2 | AI9: 400 | AJ9: =+AH9*AI9 -> 80
B10: PC1250-06 | AA10: =SUM(J10:Z10) -> 0
B11: PC1250-07 | M11: 0.0027777778 | N11: 0.0055555556 | R11: 0.03125 | V11: 0.13263889 | AA11: =SUM(J11:Z11) -> 0.17222222 | AB11: =+J11+O11+Q11+U11 -> 0 | AC11: =0+(0/60) -> 0 | AD11: 400 | AE11: =+AC11*AD11 -> 0 | AG11: =+K11+L11+M11+N11+R11+S11+T11+V11+W11+X11+Y11+Z11 -> 0.17222222 | AH11: =0+(0/60) -> 0 | AI11: 400 | AJ11: =+AH11*AI11 -> 0
B12: PC1250-10 | J12: 0.072916667 | M12: 0.0041666667 | N12: 0.0034722222 | R12: 0.040277778 | S12: 0.041666667 | T12: 0.041666667 | V12: 0.0625 | AA12: =SUM(J12:Z12) -> 0.26666667 | AB12: =+J12+O12+Q12+U12 -> 0.072916667 | AC12: =1+(44/60) -> 1.7333333 | AD12: 400 | AE12: =+AC12*AD12 -> 693.33333 | AG12: =+K12+L12+M12+N12+R12+S12+T12+V12+W12+X12+Y12+Z12 -> 0.19375 | AH12: =0+(6/60) -> 0.1 | AI12: 400 | AJ12: =+AH12*AI12 -> 40
B13: CAT395-02 | M13: 0.0041666667 | N13: 0.0055555556 | R13: 0.017361111 | V13: 0.10277778 | AA13: =SUM(J13:Z13) -> 0.12986111 | AB13: =+J13+O13+Q13+U13 -> 0 | AC13: =0+(0/60) -> 0 | AD13: 450 | AE13: =+AC13*AD13 -> 0 | AG13: =+K13+L13+M13+N13+R13+S13+T13+V13+W13+X13+Y13+Z13 -> 0.12986111 | AH13: =0+(30/60) -> 0.5 | AI13: 450 | AJ13: =+AH13*AI13 -> 225
B14: EC750-02 | K14: 0.0069444444 | M14: 0.0034722222 | N14: 0.013888889 | R14: 0.028472222 | V14: 0.13958333 | AA14: =SUM(J14:Z14) -> 0.19236111 | AB14: =+J14+O14+Q14+U14 -> 0 | AC14: =2+(40/60) -> 2.6666667 | AD14: 350 | AE14: =+AC14*AD14 -> 933.33333 | AG14: =+K14+L14+M14+N14+R14+S14+T14+V14+W14+X14+Y14+Z14 -> 0.19236111 | AH14: =3+(57/60) -> 3.95 | AI14: 350 | AJ14: =+AH14*AI14 -> 1382.5
A15: Malam | B15: PC1250-02 | J15: 0.41666667 | AA15: =SUM(J15:Z15) -> 0.41666667 | AB15: =+J15+O15+Q15+U15 -> 0.41666667 | AC15: =0+(0/60) -> 0 | AD15: 400 | AE15: =+AC15*AD15 -> 0 | AF15: =SUM(AE15:AE21) -> 2626.6667 | AG15: =+K15+L15+M15+N15+R15+S15+T15+V15+W15+X15+Y15+Z15 -> 0 | AH15: =0+(0/60) -> 0 | AI15: 400 | AJ15: =+AH15*AI15 -> 0 | AK15: =SUM(AJ15:AJ21) -> 5913.3333
B16: PC1250-05 | J16: 0.095138889 | M16: 0.00625 | AA16: =SUM(J16:Z16) -> 0.10138889 | AB16: =+J16+O16+Q16+U16 -> 0.095138889 | AC16: =3+(0/60) -> 3 | AD16: 400 | AE16: =+AC16*AD16 -> 1200 | AG16: =+K16+L16+M16+N16+R16+S16+T16+V16+W16+X16+Y16+Z16 -> 0.00625 | AH16: =7+(9/60) -> 7.15 | AI16: 400 | AJ16: =+AH16*AI16 -> 2860
B17: PC1250-06 | AA17: =SUM(J17:Z17) -> 0 | AG17: =+K17+L17+M17+N17+R17+S17+T17+V17+W17+X17+Y17+Z17 -> 0
B18: PC1250-07 | M18: 0.0048611111 | N18: 0.0034722222 | AA18: =SUM(J18:Z18) -> 0.0083333333 | AB18: =+J18+O18+Q18+U18 -> 0 | AC18: =0+(0/60) -> 0 | AD18: 400 | AE18: =+AC18*AD18 -> 0 | AG18: =+K18+L18+M18+N18+R18+S18+T18+V18+W18+X18+Y18+Z18 -> 0.0083333333 | AH18: =0+(0/60) -> 0 | AI18: 400 | AJ18: =+AH18*AI18 -> 0
B19: PC1250-10 | K19: 0.0125 | M19: 0.00069444444 | N19: 0.015277778 | AA19: =SUM(J19:Z19) -> 0.028472222 | AB19: =+J19+O19+Q19+U19 -> 0 | AC19: =3+(34/60) -> 3.5666667 | AD19: 400 | AE19: =+AC19*AD19 -> 1426.6667 | AG19: =+K19+L19+M19+N19+R19+S19+T19+V19+W19+X19+Y19+Z19 -> 0.028472222 | AH19: =7+(38/60) -> 7.6333333 | AI19: 400 | AJ19: =+AH19*AI19 -> 3053.3333
B20: CAT395-02 | K20: 0.0069444444 | M20: 0.0069444444 | N20: 0.0034722222 | AA20: =SUM(J20:Z20) -> 0.017361111 | AB20: =+J20+O20+Q20+U20 -> 0 | AC20: =0+(0/60) -> 0 | AD20: 450 | AE20: =+AC20*AD20 -> 0 | AG20: =+K20+L20+M20+N20+R20+S20+T20+V20+W20+X20+Y20+Z20 -> 0.017361111 | AH20: =0+(0/60) -> 0 | AI20: 450 | AJ20: =+AH20*AI20 -> 0
B21: EC750-02 | AA21: =SUM(J21:Z21) -> 0 | AB21: =+J21+O21+Q21+U21 -> 0 | AC21: =0+(0/60) -> 0 | AD21: 350 | AE21: =+AC21*AD21 -> 0 | AG21: =+K21+L21+M21+N21+R21+S21+T21+V21+W21+X21+Y21+Z21 -> 0 | AH21: =0+(0/60) -> 0 | AI21: 350 | AJ21: =+AH21*AI21 -> 0
A22: Total | B22: PC1250-02 | E22: =E8+E15 -> 0 | F22: =F8+F15 -> 0 | J22: =J8+J15 -> 0.72222222 | K22: =K8+K15 -> 0 | L22: =L8+L15 -> 0 | M22: =M8+M15 -> 0 | N22: =N8+N15 -> 0 | O22: =O8+O15 -> 0 | P22: =P8+P15 -> 0 | Q22: =Q8+Q15 -> 0 | ... Z22: =Z8+Z15 -> 0 | AA22: =SUM(J22:Z22) -> 0.83333333 | AB22: Total loss time RM | AF22: =+AF15+AF8 -> 5113.3333 | AG22: Total loss time Produksi | AK22: =+AK15+AK8 -> 7674.1667
B23: PC1250-05 | E23: =E9+E16 -> 0 | F23: =F9+F16 -> 0 | J23: =J9+J16 -> 0.25625 | K23: =K9+K16 -> 0 | L23: =L9+L16 -> 0 | M23: =M9+M16 -> 0.0069444444 | N23: =N9+N16 -> 0.0069444444 | O23: =O9+O16 -> 0 | P23: =P9+P16 -> 0 | Q23: =Q9+Q16 -> 0 | ... Z23: =Z9+Z16 -> 0 | AA23: =SUM(J23:Z23) -> 0.42916667
B24: PC1250-06 | E24: =E10+E17 -> 0 | F24: =F10+F17 -> 0 | J24: =J10+J17 -> 0 | K24: =K10+K17 -> 0 | L24: =L10+L17 -> 0 | M24: =M10+M17 -> 0 | N24: =N10+N17 -> 0 | O24: =O10+O17 -> 0 | P24: =P10+P17 -> 0 | Q24: =Q10+Q17 -> 0 | ... Z24: =Z10+Z17 -> 0 | AA24: =SUM(J24:Z24) -> 0
B25: PC1250-07 | E25: =E11+E18 -> 0 | F25: =F11+F18 -> 0 | J25: =J11+J18 -> 0 | K25: =K11+K18 -> 0 | L25: =L11+L18 -> 0 | M25: =M11+M18 -> 0.0076388889 | N25: =N11+N18 -> 0.0090277778 | O25: =O11+O18 -> 0 | P25: =P11+P18 -> 0 | Q25: =Q11+Q18 -> 0 | ... Z25: =Z11+Z18 -> 0 | AA25: =SUM(J25:Z25) -> 0.18055556
B26: PC1250-10 | E26: =E12+E19 -> 0 | F26: =F12+F19 -> 0 | J26: =J12+J19 -> 0.072916667 | K26: =K12+K19 -> 0.0125 | L26: =L12+L19 -> 0 | M26: =M12+M19 -> 0.0048611111 | N26: =N12+N19 -> 0.01875 | O26: =O12+O19 -> 0 | P26: =P12+P19 -> 0 | Q26: =Q12+Q19 -> 0 | ... Z26: =Z12+Z19 -> 0 | AA26: =SUM(J26:Z26) -> 0.29513889
B27: CAT395-02 | E27: =E13+E20 -> 0 | F27: =F13+F20 -> 0 | J27: =J13+J20 -> 0 | K27: =K13+K20 -> 0.0069444444 | L27: =L13+L20 -> 0 | M27: =M13+M20 -> 0.011111111 | N27: =N13+N20 -> 0.0090277778 | O27: =O13+O20 -> 0 | P27: =P13+P20 -> 0 | Q27: =Q13+Q20 -> 0 | ... Z27: =Z13+Z20 -> 0 | AA27: =SUM(J27:Z27) -> 0.14722222
B28: EC750-02 | E28: =E14+E21 -> 0 | F28: =F14+F21 -> 0 | J28: =J14+J21 -> 0 | K28: =K14+K21 -> 0.0069444444 | L28: =L14+L21 -> 0 | M28: =M14+M21 -> 0.0034722222 | N28: =N14+N21 -> 0.013888889 | O28: =O14+O21 -> 0 | P28: =P14+P21 -> 0 | Q28: =Q14+Q21 -> 0 | ... Z28: =Z14+Z21 -> 0 | AA28: =SUM(J28:Z28) -> 0.19236111

Sheet 06
A3: LOST TIME EXCAVATOR PIT 55
A4: PERIODE DESEMBER 204
A5: Tanggal : | B5: ='05'!B5+1 -> 45632
A6: Shift | B6: No Unit | C6: HM Awal | D6: HM Akhir | E6: Total HM | F6: EWH | G6: Prodty | H6: PA | I6: UA | J6: DELAY OPERATION
J7: BD | K7: Perbaikan Front | L7: Pindah Front | M7: Stop loading menjelang istirahat | N7: Stop loading akhir shift | O7: Greasing | P7: Travel | Q7: Oli hydrolik & coolant | R7: Blasting | S7: Hujan | T7: Slippery | U7: Pengisian Fuel | V7: General | W7: STB | X7: Perbaikan Jalan | Y7: Washing | Z7: loading kembali setelah sholat jumat | AA7: Total Loss Time | AB7: LOSS TIME RM | AG7: LOSS TIME PROD
A8: Pagi | B8: PC1250-02 | J8: 0.29305556 | S8: 0.12361111 | AA8: =SUM(J8:Z8) -> 0.41666667 | AB8: =+J8+O8+Q8+U8 -> 0.29305556 | AC8: =0+(0/60) -> 0 | AD8: 400 | AE8: =+AC8*AD8 -> 0 | AF8: =SUM(AE8:AE14) -> 0 | AG8: =+K8+L8+M8+N8+R8+S8+T8+V8+W8+X8+Y8+Z8 -> 0.12361111 | AH8: =0+(0/60) -> 0 | AI8: 400 | AJ8: =+AH8*AI8 -> 0 | AK8: =SUM(AJ8:AJ14) -> 390
B9: PC1250-05 | J9: 0.125 | K9: 0.020833333 | L9: 0.041666667 | M9: 0.020833333 | S9: 0.10486111 | T9: 0.0083333333 | AA9: =SUM(J9:Z9) -> 0.32152778 | AB9: =+J9+O9+Q9+U9 -> 0.125 | AC9: =0+(0/60) -> 0 | AD9: 400 | AE9: =+AC9*AD9 -> 0 | AG9: =+K9+L9+M9+N9+R9+S9+T9+V9+W9+X9+Y9+Z9 -> 0.19652778 | AH9: =0+(0/60) -> 0 | AI9: 400 | AJ9: =+AH9*AI9 -> 0
B10: PC1250-06
B11: PC1250-07 | J11: 0.030555556 | K11: 0.0083333333 | M11: 0.020138889 | O11: 0.0055555556 | S11: 0.12361111 | T11: 0.084027778 | Z11: 0.021527778 | AA11: =SUM(J11:Z11) -> 0.29375 | AB11: =+J11+O11+Q11+U11 -> 0.036111111 | AC11: =0+(0/60) -> 0 | AD11: 400 | AE11: =+AC11*AD11 -> 0 | AG11: =+K11+L11+M11+N11+R11+S11+T11+V11+W11+X11+Y11+Z11 -> 0.25763889 | AH11: =0+(0/60) -> 0 | AI11: 400 | AJ11: =+AH11*AI11 -> 0
B12: PC1250-10 | K12: 0.0048611111 | M12: 0.020833333 | S12: 0.10486111 | Z12: 0.018055556 | AA12: =SUM(J12:Z12) -> 0.14861111 | AB12: =+J12+O12+Q12+U12 -> 0 | AC12: =0+(0/60) -> 0 | AD12: 400 | AE12: =+AC12*AD12 -> 0 | AG12: =+K12+L12+M12+N12+R12+S12+T12+V12+W12+X12+Y12+Z12 -> 0.14861111 | AH12: =0+(0/60) -> 0 | AI12: 400 | AJ12: =+AH12*AI12 -> 0
B13: CAT395-02 | K13: 0.0048611111 | M13: 0.0090277778 | S13: 0.12361111 | T13: 0.084027778 | Z13: 0.0069444444 | AA13: =SUM(J13:Z13) -> 0.22847222 | AB13: =+J13+O13+Q13+U13 -> 0 | AC13: =0+(0/60) -> 0 | AD13: 450 | AE13: =+AC13*AD13 -> 0 | AG13: =+K13+L13+M13+N13+R13+S13+T13+V13+W13+X13+Y13+Z13 -> 0.22847222 | AH13: =0+(52/60) -> 0.86666667 | AI13: 450 | AJ13: =+AH13*AI13 -> 390
B14: EC750-02 | M14: 0.018055556 | S14: 0.036111111 | V14: 0.19930556 | AA14: =SUM(J14:Z14) -> 0.25347222 | AB14: =+J14+O14+Q14+U14 -> 0 | AC14: =0+(0/60) -> 0 | AD14: 350 | AE14: =+AC14*AD14 -> 0 | AG14: =+K14+L14+M14+N14+R14+S14+T14+V14+W14+X14+Y14+Z14 -> 0.25347222 | AH14: =0+(0/60) -> 0 | AI14: 350 | AJ14: =+AH14*AI14 -> 0
A15: Malam | B15: PC1250-02 | AA15: =SUM(J15:Z15) -> 0 | AB15: =+J15+O15+Q15+U15 -> 0 | AC15: =0+(0/60) -> 0 | AD15: 400 | AE15: =+AC15*AD15 -> 0 | AF15: =SUM(AE15:AE21) -> 700 | AG15: =+K15+L15+M15+N15+R15+S15+T15+V15+W15+X15+Y15+Z15 -> 0 | AH15: =0+(0/60) -> 0 | AI15: 400 | AJ15: =+AH15*AI15 -> 0 | AK15: =SUM(AJ15:AJ21) -> 1970
B16: PC1250-05 | J16: 0.10416667 | S16: 0.14375 | T16: 0.10138889 | AA16: =SUM(J16:Z16) -> 0.34930556 | AB16: =+J16+O16+Q16+U16 -> 0.10416667 | AC16: =0+(0/60) -> 0 | AD16: 400 | AE16: =+AC16*AD16 -> 0 | AG16: =+K16+L16+M16+N16+R16+S16+T16+V16+W16+X16+Y16+Z16 -> 0.24513889 | AH16: =0+(0/60) -> 0 | AI16: 400 | AJ16: =+AH16*AI16 -> 0
B17: PC1250-06 | AA17: =SUM(J17:Z17) -> 0 | AB17: =+J17+O17+Q17+U17 -> 0
B18: PC1250-07 | J18: 0.010416667 | L18: 0.0125 | M18: 0.0055555556 | S18: 0.15069444 | T18: 0.19305556 | U18: 0.010416667 | AA18: =SUM(J18:Z18) -> 0.38263889 | AB18: =+J18+O18+Q18+U18 -> 0.020833333 | AC18: =0+(0/60) -> 0 | AD18: 400 | AE18: =+AC18*AD18 -> 0 | AG18: =+K18+L18+M18+N18+R18+S18+T18+V18+W18+X18+Y18+Z18 -> 0.36180556 | AH18: =0+(0/60) -> 0 | AI18: 400 | AJ18: =+AH18*AI18 -> 0
B19: PC1250-10 | M19: 0.0034722222 | S19: 0.14375 | T19: 0.10416667 | V19: 0.018055556 | AA19: =SUM(J19:Z19) -> 0.26944444 | AB19: =+J19+O19+Q19+U19 -> 0 | AC19: =0+(0/60) -> 0 | AD19: 400 | AE19: =+AC19*AD19 -> 0 | AG19: =+K19+L19+M19+N19+R19+S19+T19+V19+W19+X19+Y19+Z19 -> 0.26944444 | AH19: =2+(41/60) -> 2.6833333 | AI19: 400 | AJ19: =+AH19*AI19 -> 1073.3333
B20: CAT395-02 | K20: 0.0013888889 | M20: 0.0048611111 | O20: 0.013194444 | S20: 0.15069444 | T20: 0.15138889 | U20: 0.010416667 | AA20: =SUM(J20:Z20) -> 0.33194444 | AB20: =+J20+O20+Q20+U20 -> 0.023611111 | AC20: =0+(0/60) -> 0 | AD20: 450 | AE20: =+AC20*AD20 -> 0 | AG20: =+K20+L20+M20+N20+R20+S20+T20+V20+W20+X20+Y20+Z20 -> 0.30833333 | AH20: =0+(20/60) -> 0.33333333 | AI20: 450 | AJ20: =+AH20*AI20 -> 150
B21: EC750-02 | K21: 0.0055555556 | M21: 0.00069444444 | T21: 0.1 | W21: 0.21875 | AA21: =SUM(J21:Z21) -> 0.325 | AB21: =+J21+O21+Q21+U21 -> 0 | AC21: =2+(0/60) -> 2 | AD21: 350 | AE21: =+AC21*AD21 -> 700 | AG21: =+K21+L21+M21+N21+R21+S21+T21+V21+W21+X21+Y21+Z21 -> 0.325 | AH21: =2+(8/60) -> 2.1333333 | AI21: 350 | AJ21: =+AH21*AI21 -> 746.66667
A22: Total | B22: PC1250-02 | E22: =E8+E15 -> 0 | F22: =F8+F15 -> 0 | J22: =J8+J15 -> 0.29305556 | K22: =K8+K15 -> 0 | L22: =L8+L15 -> 0 | M22: =M8+M15 -> 0 | N22: =N8+N15 -> 0 | O22: =O8+O15 -> 0 | P22: =P8+P15 -> 0 | Q22: =Q8+Q15 -> 0 | ... Z22: =Z8+Z15 -> 0 | AA22: =SUM(J22:Z22) -> 0.41666667 | AB22: Total loss time RM | AF22: =+AF15+AF8 -> 700 | AG22: Total loss time Produksi | AK22: =+AK15+AK8 -> 2360
B23: PC1250-05 | E23: =E9+E16 -> 0 | F23: =F9+F16 -> 0 | J23: =J9+J16 -> 0.22916667 | K23: =K9+K16 -> 0.020833333 | L23: =L9+L16 -> 0.041666667 | M23: =M9+M16 -> 0.020833333 | N23: =N9+N16 -> 0 | O23: =O9+O16 -> 0 | P23: =P9+P16 -> 0 | Q23: =Q9+Q16 -> 0 | ... Z23: =Z9+Z16 -> 0 | AA23: =SUM(J23:Z23) -> 0.67083333
B24: PC1250-06 | E24: =E10+E17 -> 0 | F24: =F10+F17 -> 0 | J24: =J10+J17 -> 0 | K24: =K10+K17 -> 0 | L24: =L10+L17 -> 0 | M24: =M10+M17 -> 0 | N24: =N10+N17 -> 0 | O24: =O10+O17 -> 0 | P24: =P10+P17 -> 0 | Q24: =Q10+Q17 -> 0 | ... Z24: =Z10+Z17 -> 0 | AA24: =SUM(J24:Z24) -> 0
B25: PC1250-07 | E25: =E11+E18 -> 0 | F25: =F11+F18 -> 0 | J25: =J11+J18 -> 0.040972222 | K25: =K11+K18 -> 0.0083333333 | L25: =L11+L18 -> 0.0125 | M25: =M11+M18 -> 0.025694444 | N25: =N11+N18 -> 0 | O25: =O11+O18 -> 0.0055555556 | P25: =P11+P18 -> 0 | Q25: =Q11+Q18 -> 0 | ... Z25: =Z11+Z18 -> 0.021527778 | AA25: =SUM(J25:Z25) -> 0.67638889
B26: PC1250-10 | E26: =E12+E19 -> 0 | F26: =F12+F19 -> 0 | J26: =J12+J19 -> 0 | K26: =K12+K19 -> 0.0048611111 | L26: =L12+L19 -> 0 | M26: =M12+M19 -> 0.024305556 | N26: =N12+N19 -> 0 | O26: =O12+O19 -> 0 | P26: =P12+P19 -> 0 | Q26: =Q12+Q19 -> 0 | ... Z26: =Z12+Z19 -> 0.018055556 | AA26: =SUM(J26:Z26) -> 0.41805556
B27: CAT395-02 | E27: =E13+E20 -> 0 | F27: =F13+F20 -> 0 | J27: =J13+J20 -> 0 | K27: =K13+K20 -> 0.00625 | L27: =L13+L20 -> 0 | M27: =M13+M20 -> 0.013888889 | N27: =N13+N20 -> 0 | O27: =O13+O20 -> 0.013194444 | P27: =P13+P20 -> 0 | Q27: =Q13+Q20 -> 0 | ... Z27: =Z13+Z20 -> 0.0069444444 | AA27: =SUM(J27:Z27) -> 0.56041667
B28: EC750-02 | E28: =E14+E21 -> 0 | F28: =F14+F21 -> 0 | J28: =J14+J21 -> 0 | K28: =K14+K21 -> 0.0055555556 | L28: =L14+L21 -> 0 | M28: =M14+M21 -> 0.01875 | N28: =N14+N21 -> 0 | O28: =O14+O21 -> 0 | P28: =P14+P21 -> 0 | Q28: =Q14+Q21 -> 0 | ... Z28: =Z14+Z21 -> 0 | AA28: =SUM(J28:Z28) -> 0.57847222

Sheet 07
A3: LOST TIME EXCAVATOR PIT 55
A4: PERIODE DESEMBER 204
A5: Tanggal : | B5: ='06'!B5+1 -> 45633
A6: Shift | B6: No Unit | C6: HM Awal | D6: HM Akhir | E6: Total HM | F6: EWH | G6: Prodty | H6: PA | I6: UA | J6: DELAY OPERATION
J7: BD | K7: Perbaikan Front | L7: Pindah Front | M7: Stop loading menjelang istirahat | N7: Stop loading akhir shift | O7: Greasing | P7: Travel | Q7: Oli hydrolik & coolant | R7: Blasting | S7: Hujan | T7: Slippery | U7: Pengisian Fuel | V7: General | W7: STB | X7: Perbaikan Jalan | Y7: Washing | AA7: Total Loss Time | AB7: LOSS TIME RM | AG7: LOSS TIME PROD
A8: Pagi | B8: PC1250-02 | J8: 0.36805556 | S8: 0.048611111 | AA8: =SUM(J8:Z8) -> 0.41666667 | AB8: =+J8+O8+Q8+U8 -> 0.36805556 | AC8: =3+(43/60) -> 3.7166667 | AD8: 400 | AE8: =+AC8*AD8 -> 1486.6667 | AF8: =SUM(AE8:AE14) -> 1886.6667 | AG8: =+K8+L8+M8+N8+R8+S8+T8+V8+W8+X8+Y8+Z8 -> 0.048611111 | AH8: =0+(12/60) -> 0.2 | AI8: 400 | AJ8: =+AH8*AI8 -> 80 | AK8: =SUM(AJ8:AJ14) -> 3529.1667
B9: PC1250-05 | J9: 0.13402778 | M9: 0.0027777778 | N9: 0.0069444444 | R9: 0.027083333 | S9: 0.048611111 | AA9: =SUM(J9:Z9) -> 0.21944444 | AB9: =+J9+O9+Q9+U9 -> 0.13402778 | AC9: =1+(0/60) -> 1 | AD9: 400 | AE9: =+AC9*AD9 -> 400 | AG9: =+K9+L9+M9+N9+R9+S9+T9+V9+W9+X9+Y9+Z9 -> 0.085416667 | AH9: =0+(28/60) -> 0.46666667 | AI9: 400 | AJ9: =+AH9*AI9 -> 186.66667
B10: PC1250-06 | AA10: =SUM(J10:Z10) -> 0
B11: PC1250-07 | J11: 0.011111111 | M11: 0.010416667 | N11: 0.0069444444 | R11: 0.01875 | S11: 0.048611111 | T11: 0.013888889 | AA11: =SUM(J11:Z11) -> 0.10972222 | AB11: =+J11+O11+Q11+U11 -> 0.011111111 | AC11: =0+(0/60) -> 0 | AD11: 400 | AE11: =+AC11*AD11 -> 0 | AG11: =+K11+L11+M11+N11+R11+S11+T11+V11+W11+X11+Y11+Z11 -> 0.098611111 | AH11: =0+(0/60) -> 0 | AI11: 400 | AJ11: =+AH11*AI11 -> 0
B12: PC1250-10 | K12: 0.0027777778 | M12: 0.0055555556 | N12: 0.010416667 | R12: 0.016666667 | S12: 0.048611111 | T12: 0.038888889 | AA12: =SUM(J12:Z12) -> 0.12291667 | AB12: =+J12+O12+Q12+U12 -> 0 | AC12: =0+(0/60) -> 0 | AD12: 400 | AE12: =+AC12*AD12 -> 0 | AG12: =+K12+L12+M12+N12+R12+S12+T12+V12+W12+X12+Y12+Z12 -> 0.12291667 | AH12: =0+(52/60) -> 0.86666667 | AI12: 400 | AJ12: =+AH12*AI12 -> 346.66667
B13: CAT395-02 | K13: 0.00625 | L13: 0.011111111 | M13: 0.0020833333 | N13: 0.0069444444 | R13: 0.01875 | S13: 0.048611111 | T13: 0.038888889 | V13: 0.083333333 | AA13: =SUM(J13:Z13) -> 0.21597222 | AB13: =+J13+O13+Q13+U13 -> 0 | AC13: =0+(0/60) -> 0 | AD13: 450 | AE13: =+AC13*AD13 -> 0 | AG13: =+K13+L13+M13+N13+R13+S13+T13+V13+W13+X13+Y13+Z13 -> 0.21597222 | AH13: =0+(52/60) -> 0.86666667 | AI13: 450 | AJ13: =+AH13*AI13 -> 390
B14: EC750-02 | J14: 0.06875 | N14: 0.0097222222 | V14: 0.24722222 | AA14: =SUM(J14:Z14) -> 0.32569444 | AB14: =+J14+O14+Q14+U14 -> 0.06875 | AC14: =0+(0/60) -> 0 | AD14: 350 | AE14: =+AC14*AD14 -> 0 | AG14: =+K14+L14+M14+N14+R14+S14+T14+V14+W14+X14+Y14+Z14 -> 0.25694444 | AH14: =7+(13/60) -> 7.2166667 | AI14: 350 | AJ14: =+AH14*AI14 -> 2525.8333
A15: Malam | B15: PC1250-02 | J15: 0.41666667 | AA15: =SUM(J15:Z15) -> 0.41666667 | AB15: =+J15+O15+Q15+U15 -> 0.41666667 | AC15: =0+(0/60) -> 0 | AD15: 400 | AE15: =+AC15*AD15 -> 0 | AF15: =SUM(AE15:AE21) -> 3225 | AG15: =+K15+L15+M15+N15+R15+S15+T15+V15+W15+X15+Y15+Z15 -> 0 | AH15: =0+(21/60) -> 0.35 | AI15: 400 | AJ15: =+AH15*AI15 -> 140 | AK15: =SUM(AJ15:AJ21) -> 900
B16: PC1250-05 | M16: 0.0013888889 | N16: 0.0069444444 | AA16: =SUM(J16:Z16) -> 0.0083333333 | AB16: =+J16+O16+Q16+U16 -> 0 | AC16: =0+(0/60) -> 0 | AD16: 400 | AE16: =+AC16*AD16 -> 0 | AG16: =+K16+L16+M16+N16+R16+S16+T16+V16+W16+X16+Y16+Z16 -> 0.0083333333 | AH16: =0+(33/60) -> 0.55 | AI16: 400 | AJ16: =+AH16*AI16 -> 220
B17: PC1250-06
B18: PC1250-07 | J18: 0.038888889 | M18: 0.0069444444 | N18: 0.0069444444 | AA18: =SUM(J18:Z18) -> 0.052777778 | AB18: =+J18+O18+Q18+U18 -> 0.038888889 | AC18: =0+(0/60) -> 0 | AD18: 400 | AE18: =+AC18*AD18 -> 0 | AG18: =+K18+L18+M18+N18+R18+S18+T18+V18+W18+X18+Y18+Z18 -> 0.013888889 | AH18: =0+(0/60) -> 0 | AI18: 400 | AJ18: =+AH18*AI18 -> 0
B19: PC1250-10 | K19: 0.0125 | L19: 0.0069444444 | M19: 0.0069444444 | N19: 0.0069444444 | AA19: =SUM(J19:Z19) -> 0.033333333 | AB19: =+J19+O19+Q19+U19 -> 0 | AC19: =0+(0/60) -> 0 | AD19: 400 | AE19: =+AC19*AD19 -> 0 | AG19: =+K19+L19+M19+N19+R19+S19+T19+V19+W19+X19+Y19+Z19 -> 0.033333333 | AH19: =0+(48/60) -> 0.8 | AI19: 400 | AJ19: =+AH19*AI19 -> 320
B20: CAT395-02 | M20: 0.0055555556 | N20: 0.0069444444 | AA20: =SUM(J20:Z20) -> 0.0125 | AB20: =+J20+O20+Q20+U20 -> 0 | AC20: =7+(10/60) -> 7.1666667 | AD20: 450 | AE20: =+AC20*AD20 -> 3225 | AG20: =+K20+L20+M20+N20+R20+S20+T20+V20+W20+X20+Y20+Z20 -> 0.0125 | AH20: =0+(20/60) -> 0.33333333 | AI20: 450 | AJ20: =+AH20*AI20 -> 150
B21: EC750-02 | AA21: =SUM(J21:Z21) -> 0 | AB21: =+J21+O21+Q21+U21 -> 0 | AC21: =0+(0/60) -> 0 | AD21: 350 | AE21: =+AC21*AD21 -> 0 | AG21: =+K21+L21+M21+N21+R21+S21+T21+V21+W21+X21+Y21+Z21 -> 0 | AH21: =0+(12/60) -> 0.2 | AI21: 350 | AJ21: =+AH21*AI21 -> 70
A22: Total | B22: PC1250-02 | E22: =E8+E15 -> 0 | F22: =F8+F15 -> 0 | J22: =J8+J15 -> 0.78472222 | K22: =K8+K15 -> 0 | L22: =L8+L15 -> 0 | M22: =M8+M15 -> 0 | N22: =N8+N15 -> 0 | O22: =O8+O15 -> 0 | P22: =P8+P15 -> 0 | Q22: =Q8+Q15 -> 0 | ... Z22: =Z8+Z15 -> 0 | AA22: =SUM(J22:Z22) -> 0.83333333 | AB22: Total loss time RM | AF22: =+AF15+AF8 -> 5111.6667 | AG22: Total loss time Produksi | AK22: =+AK15+AK8 -> 4429.1667
B23: PC1250-05 | E23: =E9+E16 -> 0 | F23: =F9+F16 -> 0 | J23: =J9+J16 -> 0.13402778 | K23: =K9+K16 -> 0 | L23: =L9+L16 -> 0 | M23: =M9+M16 -> 0.0041666667 | N23: =N9+N16 -> 0.013888889 | O23: =O9+O16 -> 0 | P23: =P9+P16 -> 0 | Q23: =Q9+Q16 -> 0 | ... Z23: =Z9+Z16 -> 0 | AA23: =SUM(J23:Z23) -> 0.22777778
B24: PC1250-06 | E24: =E10+E17 -> 0 | F24: =F10+F17 -> 0 | J24: =J10+J17 -> 0 | K24: =K10+K17 -> 0 | L24: =L10+L17 -> 0 | M24: =M10+M17 -> 0 | N24: =N10+N17 -> 0 | O24: =O10+O17 -> 0 | P24: =P10+P17 -> 0 | Q24: =Q10+Q17 -> 0 | ... Z24: =Z10+Z17 -> 0 | AA24: =SUM(J24:Z24) -> 0
B25: PC1250-07 | E25: =E11+E18 -> 0 | F25: =F11+F18 -> 0 | J25: =J11+J18 -> 0.05 | K25: =K11+K18 -> 0 | L25: =L11+L18 -> 0 | M25: =M11+M18 -> 0.017361111 | N25: =N11+N18 -> 0.013888889 | O25: =O11+O18 -> 0 | P25: =P11+P18 -> 0 | Q25: =Q11+Q18 -> 0 | ... Z25: =Z11+Z18 -> 0 | AA25: =SUM(J25:Z25) -> 0.1625
B26: PC1250-10 | E26: =E12+E19 -> 0 | F26: =F12+F19 -> 0 | J26: =J12+J19 -> 0 | K26: =K12+K19 -> 0.015277778 | L26: =L12+L19 -> 0.0069444444 | M26: =M12+M19 -> 0.0125 | N26: =N12+N19 -> 0.017361111 | O26: =O12+O19 -> 0 | P26: =P12+P19 -> 0 | Q26: =Q12+Q19 -> 0 | ... Z26: =Z12+Z19 -> 0 | AA26: =SUM(J26:Z26) -> 0.15625
B27: CAT395-02 | E27: =E13+E20 -> 0 | F27: =F13+F20 -> 0 | J27: =J13+J20 -> 0 | K27: =K13+K20 -> 0.00625 | L27: =L13+L20 -> 0.011111111 | M27: =M13+M20 -> 0.0076388889 | N27: =N13+N20 -> 0.013888889 | O27: =O13+O20 -> 0 | P27: =P13+P20 -> 0 | Q27: =Q13+Q20 -> 0 | ... Z27: =Z13+Z20 -> 0 | AA27: =SUM(J27:Z27) -> 0.22847222
B28: EC750-02 | E28: =E14+E21 -> 0 | F28: =F14+F21 -> 0 | J28: =J14+J21 -> 0.06875 | K28: =K14+K21 -> 0 | L28: =L14+L21 -> 0 | M28: =M14+M21 -> 0 | N28: =N14+N21 -> 0.0097222222 | O28: =O14+O21 -> 0 | P28: =P14+P21 -> 0 | Q28: =Q14+Q21 -> 0 | ... Z28: =Z14+Z21 -> 0 | AA28: =SUM(J28:Z28) -> 0.32569444

Sheet 08
A3: LOST TIME EXCAVATOR PIT 55
A4: PERIODE DESEMBER 204
A5: Tanggal : | B5: 45604
A6: Shift | B6: No Unit | C6: HM Awal | D6: HM Akhir | E6: Total HM | F6: EWH | G6: Prodty | H6: PA | I6: UA | J6: DELAY OPERATION
J7: BD | K7: Perbaikan Front | L7: Pindah Front | M7: Stop loading menjelang istirahat | N7: Stop loading akhir shift | O7: Greasing | P7: Travel | Q7: Oli hydrolik & coolant | R7: Blasting | S7: Hujan | T7: Slippery | U7: Pengisian Fuel | V7: General | W7: STB | X7: Perbaikan Jalan | Y7: Washing | Z7: Start loading setelah sholat jumat | AA7: Total Loss Time | AB7: LOSS TIME RM | AG7: LOSS TIME PROD
A8: Pagi | B8: PC1250-02 | J8: 0.41666667 | AA8: =SUM(J8:Z8) -> 0.41666667 | AB8: =+J8+O8+Q8+U8 -> 0.41666667 | AC8: =1+(14/60) -> 1.2333333 | AD8: 400 | AE8: =+AC8*AD8 -> 493.33333 | AF8: =SUM(AE8:AE14) -> 2981.6667 | AG8: =+K8+L8+M8+N8+R8+S8+T8+V8+W8+X8+Y8+Z8 -> 0 | AH8: =1+(26/60) -> 1.4333333 | AI8: 400 | AJ8: =+AH8*AI8 -> 573.33333 | AK8: =SUM(AJ8:AJ14) -> 4980
B9: PC1250-05 | W9: 0.41666667 | AA9: =SUM(J9:Z9) -> 0.41666667 | AB9: =+J9+O9+Q9+U9 -> 0 | AC9: =0+(0/60) -> 0 | AD9: 400 | AE9: =+AC9*AD9 -> 0 | AG9: =+K9+L9+M9+N9+R9+S9+T9+V9+W9+X9+Y9+Z9 -> 0.41666667 | AH9: =2+(32/60) -> 2.5333333 | AI9: 400 | AJ9: =+AH9*AI9 -> 1013.3333
B10: PC1250-06 | AA10: =SUM(J10:Z10) -> 0
B11: PC1250-07 | W11: 0.375 | AA11: =SUM(J11:Z11) -> 0.375 | AB11: =+J11+O11+Q11+U11 -> 0 | AC11: =0+(0/60) -> 0 | AD11: 400 | AE11: =+AC11*AD11 -> 0 | AG11: =+K11+L11+M11+N11+R11+S11+T11+V11+W11+X11+Y11+Z11 -> 0.375 | AH11: =1+(0/60) -> 1 | AI11: 400 | AJ11: =+AH11*AI11 -> 400
B12: PC1250-10 | W12: 0.041666667 | AA12: =SUM(J12:Z12) -> 0.041666667 | AB12: =+J12+O12+Q12+U12 -> 0 | AC12: =4+(59/60) -> 4.9833333 | AD12: 400 | AE12: =+AC12*AD12 -> 1993.3333 | AG12: =+K12+L12+M12+N12+R12+S12+T12+V12+W12+X12+Y12+Z12 -> 0.041666667 | AH12: =1+(10/60) -> 1.1666667 | AI12: 400 | AJ12: =+AH12*AI12 -> 466.66667
B13: CAT395-02 | K13: 0.020138889 | N13: 0.0069444444 | W13: 0.18125 | AA13: =SUM(J13:Z13) -> 0.20833333 | AB13: =+J13+O13+Q13+U13 -> 0 | AC13: =1+(6/60) -> 1.1 | AD13: 450 | AE13: =+AC13*AD13 -> 495 | AG13: =+K13+L13+M13+N13+R13+S13+T13+V13+W13+X13+Y13+Z13 -> 0.20833333 | AH13: =3+(6/60) -> 3.1 | AI13: 450 | AJ13: =+AH13*AI13 -> 1395
B14: EC750-02 | W14: 0.41666667 | AA14: =SUM(J14:Z14) -> 0.41666667 | AB14: =+J14+O14+Q14+U14 -> 0 | AC14: =0+(0/60) -> 0 | AD14: 350 | AE14: =+AC14*AD14 -> 0 | AG14: =+K14+L14+M14+N14+R14+S14+T14+V14+W14+X14+Y14+Z14 -> 0.41666667 | AH14: =3+(14/60) -> 3.2333333 | AI14: 350 | AJ14: =+AH14*AI14 -> 1131.6667
A15: Malam | B15: PC1250-02 | J15: 0.41666667 | AA15: =SUM(J15:Z15) -> 0.41666667 | AB15: =+J15+O15+Q15+U15 -> 0.41666667 | AC15: =4+(17/60) -> 4.2833333 | AD15: 400 | AE15: =+AC15*AD15 -> 1713.3333 | AF15: =SUM(AE15:AE21) -> 4220.8333 | AG15: =+K15+L15+M15+N15+R15+S15+T15+V15+W15+X15+Y15+Z15 -> 0 | AH15: =0+(17/60) -> 0.28333333 | AI15: 400 | AJ15: =+AH15*AI15 -> 113.33333 | AK15: =SUM(AJ15:AJ21) -> 3565.8333
B16: PC1250-05 | K16: 0.0034722222 | M16: 0.00069444444 | N16: 0.0069444444 | AA16: =SUM(J16:Z16) -> 0.011111111 | AB16: =+J16+O16+Q16+U16 -> 0 | AC16: =1+(36/60) -> 1.6 | AD16: 400 | AE16: =+AC16*AD16 -> 640 | AG16: =+K16+L16+M16+N16+R16+S16+T16+V16+W16+X16+Y16+Z16 -> 0.011111111 | AH16: =1+(5/60) -> 1.0833333 | AI16: 400 | AJ16: =+AH16*AI16 -> 433.33333
B17: PC1250-06 | AA17: =SUM(J17:Z17) -> 0 | AB17: =+J17+O17+Q17+U17 -> 0
B18: PC1250-07 | J18: 0.045138889 | K18: 0.0013888889 | M18: 0.0048611111 | N18: 0.0097222222 | AA18: =SUM(J18:Z18) -> 0.061111111 | AB18: =+J18+O18+Q18+U18 -> 0.045138889 | AC18: =0+(0/60) -> 0 | AD18: 400 | AE18: =+AC18*AD18 -> 0 | AG18: =+K18+L18+M18+N18+R18+S18+T18+V18+W18+X18+Y18+Z18 -> 0.015972222 | AH18: =0+(0/60) -> 0 | AI18: 400 | AJ18: =+AH18*AI18 -> 0
B19: PC1250-10 | J19: 0.099305556 | K19: 0.013888889 | M19: 0.0069444444 | N19: 0.0034722222 | AA19: =SUM(J19:Z19) -> 0.12361111 | AB19: =+J19+O19+Q19+U19 -> 0.099305556 | AC19: =0+(0/60) -> 0 | AD19: 400 | AE19: =+AC19*AD19 -> 0 | AG19: =+K19+L19+M19+N19+R19+S19+T19+V19+W19+X19+Y19+Z19 -> 0.024305556 | AH19: =5+(12/60) -> 5.2 | AI19: 400 | AJ19: =+AH19*AI19 -> 2080
B20: CAT395-02 | K20: 0.0027777778 | M20: 0.0069444444 | N20: 0.0069444444 | AA20: =SUM(J20:Z20) -> 0.016666667 | AB20: =+J20+O20+Q20+U20 -> 0 | AC20: =4+(9/60) -> 4.15 | AD20: 450 | AE20: =+AC20*AD20 -> 1867.5 | AG20: =+K20+L20+M20+N20+R20+S20+T20+V20+W20+X20+Y20+Z20 -> 0.016666667 | AH20: =0+(0/60) -> 0 | AI20: 450 | AJ20: =+AH20*AI20 -> 0
B21: EC750-02 | K21: 0.015972222 | N21: 0.0069444444 | V21: 0.20416667 | AA21: =SUM(J21:Z21) -> 0.22708333 | AB21: =+J21+O21+Q21+U21 -> 0 | AC21: =0+(0/60) -> 0 | AD21: 350 | AE21: =+AC21*AD21 -> 0 | AG21: =+K21+L21+M21+N21+R21+S21+T21+V21+W21+X21+Y21+Z21 -> 0.22708333 | AH21: =2+(41/60) -> 2.6833333 | AI21: 350 | AJ21: =+AH21*AI21 -> 939.16667
A22: Total | B22: PC1250-02 | E22: =E8+E15 -> 0 | F22: =F8+F15 -> 0 | J22: =J8+J15 -> 0.83333333 | K22: =K8+K15 -> 0 | L22: =L8+L15 -> 0 | M22: =M8+M15 -> 0 | N22: =N8+N15 -> 0 | O22: =O8+O15 -> 0 | P22: =P8+P15 -> 0 | Q22: =Q8+Q15 -> 0 | ... Z22: =Z8+Z15 -> 0 | AA22: =SUM(J22:Z22) -> 0.83333333 | AB22: Total loss time RM | AF22: =+AF15+AF8 -> 7202.5 | AG22: Total loss time Produksi | AK22: =+AK15+AK8 -> 8545.8333
B23: PC1250-05 | E23: =E9+E16 -> 0 | F23: =F9+F16 -> 0 | J23: =J9+J16 -> 0 | K23: =K9+K16 -> 0.0034722222 | L23: =L9+L16 -> 0 | M23: =M9+M16 -> 0.00069444444 | N23: =N9+N16 -> 0.0069444444 | O23: =O9+O16 -> 0 | P23: =P9+P16 -> 0 | Q23: =Q9+Q16 -> 0 | ... Z23: =Z9+Z16 -> 0 | AA23: =SUM(J23:Z23) -> 0.42777778
B24: PC1250-06 | E24: =E10+E17 -> 0 | F24: =F10+F17 -> 0 | J24: =J10+J17 -> 0 | K24: =K10+K17 -> 0 | L24: =L10+L17 -> 0 | M24: =M10+M17 -> 0 | N24: =N10+N17 -> 0 | O24: =O10+O17 -> 0 | P24: =P10+P17 -> 0 | Q24: =Q10+Q17 -> 0 | ... Z24: =Z10+Z17 -> 0 | AA24: =SUM(J24:Z24) -> 0
B25: PC1250-07 | E25: =E11+E18 -> 0 | F25: =F11+F18 -> 0 | J25: =J11+J18 -> 0.045138889 | K25: =K11+K18 -> 0.0013888889 | L25: =L11+L18 -> 0 | M25: =M11+M18 -> 0.0048611111 | N25: =N11+N18 -> 0.0097222222 | O25: =O11+O18 -> 0 | P25: =P11+P18 -> 0 | Q25: =Q11+Q18 -> 0 | ... Z25: =Z11+Z18 -> 0 | AA25: =SUM(J25:Z25) -> 0.43611111
B26: PC1250-10 | E26: =E12+E19 -> 0 | F26: =F12+F19 -> 0 | J26: =J12+J19 -> 0.099305556 | K26: =K12+K19 -> 0.013888889 | L26: =L12+L19 -> 0 | M26: =M12+M19 -> 0.0069444444 | N26: =N12+N19 -> 0.0034722222 | O26: =O12+O19 -> 0 | P26: =P12+P19 -> 0 | Q26: =Q12+Q19 -> 0 | ... Z26: =Z12+Z19 -> 0 | AA26: =SUM(J26:Z26) -> 0.16527778
B27: CAT395-02 | E27: =E13+E20 -> 0 | F27: =F13+F20 -> 0 | J27: =J13+J20 -> 0 | K27: =K13+K20 -> 0.022916667 | L27: =L13+L20 -> 0 | M27: =M13+M20 -> 0.0069444444 | N27: =N13+N20 -> 0.013888889 | O27: =O13+O20 -> 0 | P27: =P13+P20 -> 0 | Q27: =Q13+Q20 -> 0 | ... Z27: =Z13+Z20 -> 0 | AA27: =SUM(J27:Z27) -> 0.225
B28: EC750-02 | E28: =E14+E21 -> 0 | F28: =F14+F21 -> 0 | J28: =J14+J21 -> 0 | K28: =K14+K21 -> 0.015972222 | L28: =L14+L21 -> 0 | M28: =M14+M21 -> 0 | N28: =N14+N21 -> 0.0069444444 | O28: =O14+O21 -> 0 | P28: =P14+P21 -> 0 | Q28: =Q14+Q21 -> 0 | ... Z28: =Z14+Z21 -> 0 | AA28: =SUM(J28:Z28) -> 0.64375

Sheet 09
A3: LOST TIME EXCAVATOR PIT 55
A4: PERIODE DESEMBER 204
A5: Tanggal : | B5: 45635
A6: Shift | B6: No Unit | C6: HM Awal | D6: HM Akhir | E6: Total HM | F6: EWH | G6: Prodty | H6: PA | I6: UA | J6: DELAY OPERATION
J7: BD | K7: Perbaikan Front | L7: Pindah Front | M7: Stop loading menjelang istirahat | N7: Stop loading akhir shift | O7: Greasing | P7: Travel | Q7: Oli hydrolik & coolant | R7: Blasting | S7: Hujan | T7: Slippery | U7: Pengisian Fuel | V7: General | W7: STB | X7: Perbaikan Jalan | Y7: Washing | AA7: Total Loss Time | AB7: LOSS TIME RM | AG7: LOSS TIME PROD
A8: Pagi | B8: PC1250-02 | AA8: =SUM(J8:Z8) -> 0 | AB8: =+J8+O8+Q8+U8 -> 0 | AC8: =0+(14/60) -> 0.23333333 | AD8: 400 | AE8: =+AC8*AD8 -> 93.333333 | AF8: =SUM(AE8:AE14) -> 453.33333 | AG8: =+K8+L8+M8+N8+R8+S8+T8+V8+W8+X8+Y8+Z8 -> 0 | AH8: =0+(12/60) -> 0.2 | AI8: 400 | AJ8: =+AH8*AI8 -> 80 | AK8: =SUM(AJ8:AJ14) -> 5498.3333
B9: PC1250-05 | J9: 0.09375 | K9: 0.013888889 | M9: 0.0034722222 | N9: 0.0090277778 | R9: 0.020138889 | AA9: =SUM(J9:Z9) -> 0.14027778 | AB9: =+J9+O9+Q9+U9 -> 0.09375 | AC9: =0+(39/60) -> 0.65 | AD9: 400 | AE9: =+AC9*AD9 -> 260 | AG9: =+K9+L9+M9+N9+R9+S9+T9+V9+W9+X9+Y9+Z9 -> 0.046527778 | AH9: =3+(17/60) -> 3.2833333 | AI9: 400 | AJ9: =+AH9*AI9 -> 1313.3333
B10: PC1250-06
B11: PC1250-07 | M11: 0.0076388889 | N11: 0.0083333333 | R11: 0.015277778 | AA11: =SUM(J11:Z11) -> 0.03125 | AB11: =+J11+O11+Q11+U11 -> 0 | AC11: =0+(0/60) -> 0 | AD11: 400 | AE11: =+AC11*AD11 -> 0 | AG11: =+K11+L11+M11+N11+R11+S11+T11+V11+W11+X11+Y11+Z11 -> 0.03125 | AH11: =1+(24/60) -> 1.4 | AI11: 400 | AJ11: =+AH11*AI11 -> 560
B12: PC1250-10 | K12: 0.0076388889 | M12: 0.00069444444 | N12: 0.0097222222 | R12: 0.020138889 | AA12: =SUM(J12:Z12) -> 0.038194444 | AB12: =+J12+O12+Q12+U12 -> 0 | AC12: =0+(15/60) -> 0.25 | AD12: 400 | AE12: =+AC12*AD12 -> 100 | AG12: =+K12+L12+M12+N12+R12+S12+T12+V12+W12+X12+Y12+Z12 -> 0.038194444 | AH12: =3+(17/60) -> 3.2833333 | AI12: 400 | AJ12: =+AH12*AI12 -> 1313.3333
B13: CAT395-02 | K13: 0.0013888889 | M13: 0.0069444444 | N13: 0.0048611111 | R13: 0.010416667 | AA13: =SUM(J13:Z13) -> 0.023611111 | AB13: =+J13+O13+Q13+U13 -> 0 | AC13: =0+(0/60) -> 0 | AD13: 450 | AE13: =+AC13*AD13 -> 0 | AG13: =+K13+L13+M13+N13+R13+S13+T13+V13+W13+X13+Y13+Z13 -> 0.023611111 | AH13: =3+(18/60) -> 3.3 | AI13: 450 | AJ13: =+AH13*AI13 -> 1485
B14: EC750-02 | J14: 0.082638889 | K14: 0.0034722222 | M14: 0.010416667 | N14: 0.014583333 | R14: 0.020833333 | AA14: =SUM(J14:Z14) -> 0.13194444 | AB14: =+J14+O14+Q14+U14 -> 0.082638889 | AC14: =0+(0/60) -> 0 | AD14: 350 | AE14: =+AC14*AD14 -> 0 | AG14: =+K14+L14+M14+N14+R14+S14+T14+V14+W14+X14+Y14+Z14 -> 0.049305556 | AH14: =2+(8/60) -> 2.1333333 | AI14: 350 | AJ14: =+AH14*AI14 -> 746.66667
A15: Malam | B15: PC1250-02 | J15: 0.24652778 | K15: 0.0027777778 | P15: 0.060416667 | S15: 0.017361111 | AA15: =SUM(J15:Z15) -> 0.32708333 | AB15: =+J15+O15+Q15+U15 -> 0.24652778 | AC15: =0+(0/60) -> 0 | AD15: 400 | AE15: =+AC15*AD15 -> 0 | AF15: =SUM(AE15:AE21) -> 476.66667 | AG15: =+K15+L15+M15+N15+R15+S15+T15+V15+W15+X15+Y15+Z15 -> 0.020138889 | AH15: =1+(42/60) -> 1.7 | AI15: 400 | AJ15: =+AH15*AI15 -> 680 | AK15: =SUM(AJ15:AJ21) -> 3400
B16: PC1250-05 | J16: 0.37847222 | AA16: =SUM(J16:Z16) -> 0.37847222 | AB16: =+J16+O16+Q16+U16 -> 0.37847222 | AC16: =1+(1/60) -> 1.0166667 | AD16: 400 | AE16: =+AC16*AD16 -> 406.66667 | AG16: =+K16+L16+M16+N16+R16+S16+T16+V16+W16+X16+Y16+Z16 -> 0 | AH16: =1+(55/60) -> 1.9166667 | AI16: 400 | AJ16: =+AH16*AI16 -> 766.66667
B17: PC1250-06
B18: PC1250-07 | K18: 0.014583333 | N18: 0.0069444444 | S18: 0.017361111 | AA18: =SUM(J18:Z18) -> 0.038888889 | AB18: =+J18+O18+Q18+U18 -> 0 | AC18: =0+(0/60) -> 0 | AD18: 400 | AE18: =+AC18*AD18 -> 0 | AG18: =+K18+L18+M18+N18+R18+S18+T18+V18+W18+X18+Y18+Z18 -> 0.038888889 | AH18: =0+(0/60) -> 0 | AI18: 400 | AJ18: =+AH18*AI18 -> 0
B19: PC1250-10 | K19: 0.0076388889 | N19: 0.0076388889 | S19: 0.017361111 | AA19: =SUM(J19:Z19) -> 0.032638889 | AB19: =+J19+O19+Q19+U19 -> 0 | AC19: =0+(0/60) -> 0 | AD19: 400 | AE19: =+AC19*AD19 -> 0 | AG19: =+K19+L19+M19+N19+R19+S19+T19+V19+W19+X19+Y19+Z19 -> 0.032638889 | AH19: =1+(47/60) -> 1.7833333 | AI19: 400 | AJ19: =+AH19*AI19 -> 713.33333
B20: CAT395-02 | K20: 0.01875 | N20: 0.0020833333 | O20: 0.0083333333 | S20: 0.017361111 | AA20: =SUM(J20:Z20) -> 0.046527778 | AB20: =+J20+O20+Q20+U20 -> 0.0083333333 | AC20: =0+(0/60) -> 0 | AD20: 450 | AE20: =+AC20*AD20 -> 0 | AG20: =+K20+L20+M20+N20+R20+S20+T20+V20+W20+X20+Y20+Z20 -> 0.038194444 | AH20: =2+(22/60) -> 2.3666667 | AI20: 450 | AJ20: =+AH20*AI20 -> 1065
B21: EC750-02 | K21: 0.024305556 | N21: 0.0069444444 | S21: 0.017361111 | AA21: =SUM(J21:Z21) -> 0.048611111 | AB21: =+J21+O21+Q21+U21 -> 0 | AC21: =0+(12/60) -> 0.2 | AD21: 350 | AE21: =+AC21*AD21 -> 70 | AG21: =+K21+L21+M21+N21+R21+S21+T21+V21+W21+X21+Y21+Z21 -> 0.048611111 | AH21: =0+(30/60) -> 0.5 | AI21: 350 | AJ21: =+AH21*AI21 -> 175
A22: Total | B22: PC1250-02 | E22: =E8+E15 -> 0 | F22: =F8+F15 -> 0 | J22: =J8+J15 -> 0.24652778 | K22: =K8+K15 -> 0.0027777778 | L22: =L8+L15 -> 0 | M22: =M8+M15 -> 0 | N22: =N8+N15 -> 0 | O22: =O8+O15 -> 0 | P22: =P8+P15 -> 0.060416667 | Q22: =Q8+Q15 -> 0 | ... Z22: =Z8+Z15 -> 0 | AA22: =SUM(J22:Z22) -> 0.32708333 | AB22: Total loss time RM | AF22: =+AF15+AF8 -> 930 | AG22: Total loss time Produksi | AK22: =+AK15+AK8 -> 8898.3333
B23: PC1250-05 | E23: =E9+E16 -> 0 | F23: =F9+F16 -> 0 | J23: =J9+J16 -> 0.47222222 | K23: =K9+K16 -> 0.013888889 | L23: =L9+L16 -> 0 | M23: =M9+M16 -> 0.0034722222 | N23: =N9+N16 -> 0.0090277778 | O23: =O9+O16 -> 0 | P23: =P9+P16 -> 0 | Q23: =Q9+Q16 -> 0 | ... Z23: =Z9+Z16 -> 0 | AA23: =SUM(J23:Z23) -> 0.51875
B24: PC1250-06 | E24: =E10+E17 -> 0 | F24: =F10+F17 -> 0 | J24: =J10+J17 -> 0 | K24: =K10+K17 -> 0 | L24: =L10+L17 -> 0 | M24: =M10+M17 -> 0 | N24: =N10+N17 -> 0 | O24: =O10+O17 -> 0 | P24: =P10+P17 -> 0 | Q24: =Q10+Q17 -> 0 | ... Z24: =Z10+Z17 -> 0 | AA24: =SUM(J24:Z24) -> 0
B25: PC1250-07 | E25: =E11+E18 -> 0 | F25: =F11+F18 -> 0 | J25: =J11+J18 -> 0 | K25: =K11+K18 -> 0.014583333 | L25: =L11+L18 -> 0 | M25: =M11+M18 -> 0.0076388889 | N25: =N11+N18 -> 0.015277778 | O25: =O11+O18 -> 0 | P25: =P11+P18 -> 0 | Q25: =Q11+Q18 -> 0 | ... Z25: =Z11+Z18 -> 0 | AA25: =SUM(J25:Z25) -> 0.070138889
B26: PC1250-10 | E26: =E12+E19 -> 0 | F26: =F12+F19 -> 0 | J26: =J12+J19 -> 0 | K26: =K12+K19 -> 0.015277778 | L26: =L12+L19 -> 0 | M26: =M12+M19 -> 0.00069444444 | N26: =N12+N19 -> 0.017361111 | O26: =O12+O19 -> 0 | P26: =P12+P19 -> 0 | Q26: =Q12+Q19 -> 0 | ... Z26: =Z12+Z19 -> 0 | AA26: =SUM(J26:Z26) -> 0.070833333
B27: CAT395-02 | E27: =E13+E20 -> 0 | F27: =F13+F20 -> 0 | J27: =J13+J20 -> 0 | K27: =K13+K20 -> 0.020138889 | L27: =L13+L20 -> 0 | M27: =M13+M20 -> 0.0069444444 | N27: =N13+N20 -> 0.0069444444 | O27: =O13+O20 -> 0.0083333333 | P27: =P13+P20 -> 0 | Q27: =Q13+Q20 -> 0 | ... Z27: =Z13+Z20 -> 0 | AA27: =SUM(J27:Z27) -> 0.070138889
B28: EC750-02 | E28: =E14+E21 -> 0 | F28: =F14+F21 -> 0 | J28: =J14+J21 -> 0.082638889 | K28: =K14+K21 -> 0.027777778 | L28: =L14+L21 -> 0 | M28: =M14+M21 -> 0.010416667 | N28: =N14+N21 -> 0.021527778 | O28: =O14+O21 -> 0 | P28: =P14+P21 -> 0 | Q28: =Q14+Q21 -> 0 | ... Z28: =Z14+Z21 -> 0 | AA28: =SUM(J28:Z28) -> 0.18055556

Sheet 10
A3: LOST TIME EXCAVATOR PIT 55
A4: PERIODE DESEMBER 204
A5: Tanggal : | B5: 45606
A6: Shift | B6: No Unit | C6: HM Awal | D6: HM Akhir | E6: Total HM | F6: EWH | G6: Prodty | H6: PA | I6: UA | J6: DELAY OPERATION
J7: BD | K7: Perbaikan Front | L7: Pindah Front | M7: Stop loading menjelang istirahat | N7: Stop loading akhir shift | O7: Greasing | P7: Travel | Q7: Oli hydrolik & coolant | R7: Blasting | S7: Hujan | T7: Slippery | U7: Pengisian Fuel | V7: General | W7: STB | X7: Perbaikan Jalan | Y7: Washing | AA7: Total Loss Time | AB7: LOSS TIME RM | AG7: LOSS TIME PROD
A8: Pagi | B8: PC1250-02 | J8: 0.22361111 | K8: 0.014583333 | M8: 0.0069444444 | N8: 0.018055556 | AA8: =SUM(J8:Z8) -> 0.26319444 | AB8: =+J8+O8+Q8+U8 -> 0.22361111 | AC8: =0+(0/60) -> 0 | AD8: 400 | AE8: =+AC8*AD8 -> 0 | AF8: =SUM(AE8:AE14) -> 2965 | AG8: =+K8+L8+M8+N8+R8+S8+T8+V8+W8+X8+Y8+Z8 -> 0.039583333 | AH8: =0+(48/60) -> 0.8 | AI8: 400 | AJ8: =+AH8*AI8 -> 320 | AK8: =SUM(AJ8:AJ14) -> 2076.6667
B9: PC1250-05 | J9: 0.35416667 | V9: 0.025 | AA9: =SUM(J9:Z9) -> 0.37916667 | AB9: =+J9+O9+Q9+U9 -> 0.35416667 | AC9: =4+(10/60) -> 4.1666667 | AD9: 400 | AE9: =+AC9*AD9 -> 1666.6667 | AG9: =+K9+L9+M9+N9+R9+S9+T9+V9+W9+X9+Y9+Z9 -> 0.025 | AH9: =0+(28/60) -> 0.46666667 | AI9: 400 | AJ9: =+AH9*AI9 -> 186.66667
B10: PC1250-06
B11: PC1250-07 | J11: 0.17152778 | K11: 0.010416667 | M11: 0.0055555556 | N11: 0.0090277778 | R11: 0.013888889 | AA11: =SUM(J11:Z11) -> 0.21041667 | AB11: =+J11+O11+Q11+U11 -> 0.17152778 | AC11: =0+(0/60) -> 0 | AD11: 400 | AE11: =+AC11*AD11 -> 0 | AG11: =+K11+L11+M11+N11+R11+S11+T11+V11+W11+X11+Y11+Z11 -> 0.038888889 | AH11: =0+(0/60) -> 0 | AI11: 400 | AJ11: =+AH11*AI11 -> 0
