Workbook

Sheet Daily All PIT
B2: PT. SUMBER MITRA JAYA | AE2: SMJ(B)-S-MA-PR-V-01 | AJ2: =12891+17157+10856+4825+10248+4903 -> 60880
B3: REKAP DAILY REPORT APRIL 2024
B4: PIT 55 GAR & PIT 50 GAR | AK4: U/FUEL
B5: TGL | C5: OVERBURDEN (BCM) | M5: BATUBARA (TON) | T5: TOTAL MATERIAL (BCM) | U5: NON VOLUME (BCM) | X5: Solar Pagi | Y5: Solar malam | Z5: PEMAKAIAN SOLAR (LTR) | AA5: SR | AD5: FR PAGI | AE5: FR MALAM | AF5: FR | AG5: RAIN | AH5: SLIPERY | AI5: PEMAKAIAN SOLAR (LTR) (Jetty) | AK5: TOTAL MATERIAL (BCM) | AL5: Total Material Pagi | AM5: Total Material Malam
C6: PLAN | K6: % | M6: PLAN | N6: ACTUAL | Q6: % | R6: ACTUAL
D7: PAGI | G7: MALAM | H7: Fleet | J7: TOTAL | L7: % | N7: PAGI | O7: MALAM | P7: TOTAL | R7: RIT | S7: (BCM) | U7: PAGI | V7: MALAM | W7: TOTAL | AA7: PLAN | AB7: ACT | AC7: %ACH
B8: 45383 | C8: ='55 REV-'!D9+'50 REV'!D8 -> 90000 | D8: ='55 REV-'!M9+'50 REV'!L8 -> 70028 | E8: ='55 REV-'!H9+'50 REV'!G8 -> 11 | F8: fleet | G8: ='55 REV-'!J9+'50 REV'!I8 -> 36720 | H8: ='55 REV-'!K9+'50 REV'!J8 -> 11 | I8: fleet | J8: =+G8+D8 -> 106748 | K8: =IFERROR(+J8/C8,"") -> 1.1860889 | L8: =IFERROR(J8/C8,"") -> 1.1860889 | M8: ='55 REV-'!R9+'50 REV'!O8 -> 6300 | N8: ='55 REV-'!T9+'50 REV'!Q8 -> 2966.04 | O8: ='55 REV-'!U9+'50 REV'!R8 -> 1744.13 | P8: =+O8+N8 -> 4710.17 | Q8: =IFERROR(+P8/M8,"") -> 0.74764603 | R8: =+'[1]Daily All PIT'!$O$8 -> 76 | S8: =+P8/1.27 -> 3708.7953 | T8: =J8+S8 -> 110456.8 | U8: =+'PIT GAR 42'!R8+#REF! -> #REF! | V8: =+'PIT GAR 42'!S8+#REF! -> #REF! | W8: =U8+V8 -> #REF! | X8: ='55 REV-'!Z9+'50 REV'!W8 -> 38914 | Y8: ='55 REV-'!AA9+'50 REV'!X8 -> 33182 | Z8: =+X8+Y8 -> 72096 | AA8: =+IFERROR(C8/M8,0) -> 14.285714 | AB8: =+IFERROR(J8/P8,0) -> 22.663301 | AC8: =IFERROR(+AB8/AA8,"") -> 1.5864311 | AD8: =+X8/(D8+(N8/1.27)) -> 0.53775756 | AE8: =+Y8/(G8+(O8/1.27)) -> 0.87107111 | AF8: =+Z8/(J8+(P8/1.27)) -> 0.65270769 | AJ8: =AI8+Z8 -> 72096 | AK8: =+AL8+AM8 -> 110456.8 | AL8: =+AN8+D8 -> 72363.465 | AM8: =+AO8+G8 -> 38093.331 | AN8: =+N8/1.27 -> 2335.4646 | AO8: =+O8/1.27 -> 1373.3307 | AP8: =+AO8+AN8 -> 3708.7953 | AQ8: =+AP8-S8 -> 0 | AR8: =+AP8+J8 -> 110456.8
B9: 45384 | C9: ='55 REV-'!D10+'50 REV'!D9 -> 90000 | D9: ='55 REV-'!M10+'50 REV'!L9 -> 65666 | E9: ='55 REV-'!H10+'50 REV'!G9 -> 11 | F9: fleet | G9: ='55 REV-'!J10+'50 REV'!I9 -> 34974 | H9: ='55 REV-'!K10+'50 REV'!J9 -> 11 | I9: fleet | J9: =+G9+D9 -> 100640 | K9: =IFERROR(+J9/C9,"") -> 1.1182222 | L9: =IFERROR(J9/C9,"") -> 1.1182222 | M9: ='55 REV-'!R10+'50 REV'!O9 -> 6300 | N9: ='55 REV-'!T10+'50 REV'!Q9 -> 2665.37 | O9: ='55 REV-'!U10+'50 REV'!R9 -> 2427.59 | P9: =+O9+N9 -> 5092.96 | Q9: =IFERROR(+P9/M9,"") -> 0.80840635 | R9: =+'[1]Daily All PIT'!O9 -> 34 | S9: =+P9/1.27 -> 4010.2047 | T9: =J9+S9 -> 104650.2 | U9: =+'PIT GAR 42'!R9+#REF! -> #REF! | V9: =+'PIT GAR 42'!S9+#REF! -> #REF! | W9: =U9+V9 -> #REF! | X9: ='55 REV-'!Z10+'50 REV'!W9 -> 37956.5 | Y9: ='55 REV-'!AA10+'50 REV'!X9 -> 32231 | Z9: =+X9+Y9 -> 70187.5 | AA9: =+IFERROR(C9/M9,0) -> 14.285714 | AB9: =+IFERROR(J9/P9,0) -> 19.760611 | AC9: =IFERROR(+AB9/AA9,"") -> 1.3832428 | AD9: =+X9/(D9+(N9/1.27)) -> 0.56012187 | AE9: =+Y9/(G9+(O9/1.27)) -> 0.87381248 | AF9: =+Z9/(J9+(P9/1.27)) -> 0.6706867 | AJ9: =AI9+Z9 -> 70187.5 | AK9: =+AL9+AM9 -> 104650.2 | AL9: =+AN9+D9 -> 67764.717 | AM9: =+AO9+G9 -> 36885.488 | AN9: =+N9/1.27 -> 2098.7165 | AO9: =+O9/1.27 -> 1911.4882 | AP9: =+AO9+AN9 -> 4010.2047 | AQ9: =+AP9-S9 -> 0 | AR9: =+AP9+J9 -> 104650.2
B10: 45385 | C10: ='55 REV-'!D11+'50 REV'!D10 -> 90000 | D10: ='55 REV-'!M11+'50 REV'!L10 -> 68548 | E10: ='55 REV-'!H11+'50 REV'!G10 -> 11 | F10: fleet | G10: ='55 REV-'!J11+'50 REV'!I10 -> 33816 | H10: ='55 REV-'!K11+'50 REV'!J10 -> 10 | I10: fleet | J10: =+G10+D10 -> 102364 | K10: =IFERROR(+J10/C10,"") -> 1.1373778 | L10: =IFERROR(J10/C10,"") -> 1.1373778 | M10: ='55 REV-'!R11+'50 REV'!O10 -> 6300 | N10: ='55 REV-'!T11+'50 REV'!Q10 -> 2861.04 | O10: ='55 REV-'!U11+'50 REV'!R10 -> 2293.04 | P10: =+O10+N10 -> 5154.08 | Q10: =IFERROR(+P10/M10,"") -> 0.81810794 | R10: =+'[1]Daily All PIT'!O10 -> 85 | S10: =+P10/1.27 -> 4058.3307 | T10: =J10+S10 -> 106422.33 | U10: =+'PIT GAR 42'!R10+#REF! -> #REF! | V10: =+'PIT GAR 42'!S10+#REF! -> #REF! | W10: =U10+V10 -> #REF! | X10: ='55 REV-'!Z11+'50 REV'!W10 -> 37828.5 | Y10: ='55 REV-'!AA11+'50 REV'!X10 -> 35114.5 | Z10: =+X10+Y10 -> 72943 | AA10: =+IFERROR(C10/M10,0) -> 14.285714 | AB10: =+IFERROR(J10/P10,0) -> 19.86077 | AC10: =IFERROR(+AB10/AA10,"") -> 1.3902539 | AD10: =+X10/(D10+(N10/1.27)) -> 0.53429491 | AE10: =+Y10/(G10+(O10/1.27)) -> 0.98576582 | AF10: =+Z10/(J10+(P10/1.27)) -> 0.68541066 | AJ10: =AI10+Z10 -> 72943 | AK10: =+AL10+AM10 -> 106422.33 | AL10: =+AN10+D10 -> 70800.787 | AM10: =+AO10+G10 -> 35621.543 | AN10: =+N10/1.27 -> 2252.7874 | AO10: =+O10/1.27 -> 1805.5433 | AP10: =+AO10+AN10 -> 4058.3307 | AQ10: =+AP10-S10 -> 0 | AR10: =+AP10+J10 -> 106422.33
B11: 45386 | C11: ='55 REV-'!D12+'50 REV'!D11 -> 45000 | D11: ='55 REV-'!M12+'50 REV'!L11 -> 39908 | E11: ='55 REV-'!H12+'50 REV'!G11 -> 2 | F11: fleet | G11: ='55 REV-'!J12+'50 REV'!I11 -> 32824 | H11: ='55 REV-'!K12+'50 REV'!J11 -> 11 | I11: fleet | J11: =+G11+D11 -> 72732 | K11: =IFERROR(+J11/C11,"") -> 1.6162667 | L11: =IFERROR(J11/C11,"") -> 1.6162667 | M11: ='55 REV-'!R12+'50 REV'!O11 -> 3775 | N11: ='55 REV-'!T12+'50 REV'!Q11 -> 884.08 | O11: ='55 REV-'!U12+'50 REV'!R11 -> 2759.35 | P11: =+O11+N11 -> 3643.43 | Q11: =IFERROR(+P11/M11,"") -> 0.96514702 | R11: =+'[1]Daily All PIT'!O11 -> 77 | S11: =+P11/1.27 -> 2868.8425 | T11: =J11+S11 -> 75600.843 | U11: =+'PIT GAR 42'!R11+#REF! -> #REF! | V11: =+'PIT GAR 42'!S11+#REF! -> #REF! | W11: =U11+V11 -> #REF! | X11: ='55 REV-'!Z12+'50 REV'!W11 -> 11337 | Y11: ='55 REV-'!AA12+'50 REV'!X11 -> 32148 | Z11: =+X11+Y11 -> 43485 | AA11: =+IFERROR(C11/M11,0) -> 11.92053 | AB11: =+IFERROR(J11/P11,0) -> 19.962508 | AC11: =IFERROR(+AB11/AA11,"") -> 1.6746326 | AD11: =+X11/(D11+(N11/1.27)) -> 0.27920808 | AE11: =+Y11/(G11+(O11/1.27)) -> 0.91860046 | AF11: =+Z11/(J11+(P11/1.27)) -> 0.575192 | AJ11: =AI11+Z11 -> 43485 | AK11: =+AL11+AM11 -> 75600.843 | AL11: =+AN11+D11 -> 40604.126 | AM11: =+AO11+G11 -> 34996.717 | AN11: =+N11/1.27 -> 696.12598 | AO11: =+O11/1.27 -> 2172.7165 | AP11: =+AO11+AN11 -> 2868.8425 | AQ11: =+AP11-S11 -> 0 | AR11: =+AP11+J11 -> 75600.843
B12: 45387 | C12: ='55 REV-'!D13+'50 REV'!D12 -> 90000 | D12: ='55 REV-'!M13+'50 REV'!L12 -> 78462 | E12: ='55 REV-'!H13+'50 REV'!G12 -> 11 | F12: fleet | G12: ='55 REV-'!J13+'50 REV'!I12 -> 37758 | H12: ='55 REV-'!K13+'50 REV'!J12 -> 10 | I12: fleet | J12: =+G12+D12 -> 116220 | K12: =IFERROR(+J12/C12,"") -> 1.2913333 | L12: =IFERROR(J12/C12,"") -> 1.2913333 | M12: ='55 REV-'!R13+'50 REV'!O12 -> 6300 | N12: ='55 REV-'!T13+'50 REV'!Q12 -> 2560.3 | O12: ='55 REV-'!U13+'50 REV'!R12 -> 2667.64 | P12: =+O12+N12 -> 5227.94 | Q12: =IFERROR(+P12/M12,"") -> 0.82983175 | R12: =+'[1]Daily All PIT'!O12 -> 35 | S12: =+P12/1.27 -> 4116.4882 | T12: =J12+S12 -> 120336.49 | U12: =+'PIT GAR 42'!R12+#REF! -> #REF! | V12: =+'PIT GAR 42'!S12+#REF! -> #REF! | W12: =U12+V12 -> #REF! | X12: ='55 REV-'!Z13+'50 REV'!W12 -> 36696 | Y12: ='55 REV-'!AA13+'50 REV'!X12 -> 38829 | Z12: =+X12+Y12 -> 75525 | AA12: =+IFERROR(C12/M12,0) -> 14.285714 | AB12: =+IFERROR(J12/P12,0) -> 22.230554 | AC12: =IFERROR(+AB12/AA12,"") -> 1.5561387 | AD12: =+X12/(D12+(N12/1.27)) -> 0.45597564 | AE12: =+Y12/(G12+(O12/1.27)) -> 0.97417103 | AF12: =+Z12/(J12+(P12/1.27)) -> 0.62761512 | AJ12: =AI12+Z12 -> 75525 | AK12: =+AL12+AM12 -> 120336.49 | AL12: =+AN12+D12 -> 80477.984 | AM12: =+AO12+G12 -> 39858.504 | AN12: =+N12/1.27 -> 2015.9843 | AO12: =+O12/1.27 -> 2100.5039 | AP12: =+AO12+AN12 -> 4116.4882 | AQ12: =+AP12-S12 -> 0 | AR12: =+AP12+J12 -> 120336.49
B13: 45388 | C13: ='55 REV-'!D14+'50 REV'!D13 -> 90000 | D13: ='55 REV-'!M14+'50 REV'!L13 -> 69988 | E13: ='55 REV-'!H14+'50 REV'!G13 -> 11 | F13: fleet | G13: ='55 REV-'!J14+'50 REV'!I13 -> 32526 | H13: ='55 REV-'!K14+'50 REV'!J13 -> 11 | I13: fleet | J13: =+G13+D13 -> 102514 | K13: =IFERROR(+J13/C13,"") -> 1.1390444 | L13: =IFERROR(J13/C13,"") -> 1.1390444 | M13: ='55 REV-'!R14+'50 REV'!O13 -> 6300 | N13: ='55 REV-'!T14+'50 REV'!Q13 -> 3446.83 | O13: ='55 REV-'!U14+'50 REV'!R13 -> 3341.47 | P13: =+O13+N13 -> 6788.3 | Q13: =IFERROR(+P13/M13,"") -> 1.0775079 | R13: =+'[1]Daily All PIT'!O13 -> 83 | S13: =+P13/1.27 -> 5345.1181 | T13: =J13+S13 -> 107859.12 | U13: =+'PIT GAR 42'!R13+#REF! -> #REF! | V13: =+'PIT GAR 42'!S13+#REF! -> #REF! | W13: =U13+V13 -> #REF! | X13: ='55 REV-'!Z14+'50 REV'!W13 -> 35817 | Y13: ='55 REV-'!AA14+'50 REV'!X13 -> 36960 | Z13: =+X13+Y13 -> 72777 | AA13: =+IFERROR(C13/M13,0) -> 14.285714 | AB13: =+IFERROR(J13/P13,0) -> 15.101572 | AC13: =IFERROR(+AB13/AA13,"") -> 1.05711 | AD13: =+X13/(D13+(N13/1.27)) -> 0.49265468 | AE13: =+Y13/(G13+(O13/1.27)) -> 1.0512819 | AF13: =+Z13/(J13+(P13/1.27)) -> 0.67474129 | AJ13: =AI13+Z13 -> 72777 | AK13: =+AL13+AM13 -> 107859.12 | AL13: =+AN13+D13 -> 72702.039 | AM13: =+AO13+G13 -> 35157.079 | AN13: =+N13/1.27 -> 2714.0394 | AO13: =+O13/1.27 -> 2631.0787 | AP13: =+AO13+AN13 -> 5345.1181 | AQ13: =+AP13-S13 -> 0 | AR13: =+AP13+J13 -> 107859.12
B14: 45389 | C14: ='55 REV-'!D15+'50 REV'!D14 -> 90000 | D14: ='55 REV-'!M15+'50 REV'!L14 -> 60698 | E14: ='55 REV-'!H15+'50 REV'!G14 -> 10 | F14: fleet | G14: ='55 REV-'!J15+'50 REV'!I14 -> 24264 | H14: ='55 REV-'!K15+'50 REV'!J14 -> 10 | I14: fleet | J14: =+G14+D14 -> 84962 | K14: =IFERROR(+J14/C14,"") -> 0.94402222 | L14: =IFERROR(J14/C14,"") -> 0.94402222 | M14: ='55 REV-'!R15+'50 REV'!O14 -> 6300 | N14: ='55 REV-'!T15+'50 REV'!Q14 -> 2728.04 | O14: ='55 REV-'!U15+'50 REV'!R14 -> 1832.59 | P14: =+O14+N14 -> 4560.63 | Q14: =IFERROR(+P14/M14,"") -> 0.72390952 | R14: =+'[1]Daily All PIT'!O14 -> 40 | S14: =+P14/1.27 -> 3591.0472 | T14: =J14+S14 -> 88553.047 | U14: =+'PIT GAR 42'!R14+#REF! -> #REF! | V14: =+'PIT GAR 42'!S14+#REF! -> #REF! | W14: =U14+V14 -> #REF! | X14: ='55 REV-'!Z15+'50 REV'!W14 -> 34825 | Y14: ='55 REV-'!AA15+'50 REV'!X14 -> 37362 | Z14: =+X14+Y14 -> 72187 | AA14: =+IFERROR(C14/M14,0) -> 14.285714 | AB14: =+IFERROR(J14/P14,0) -> 18.629444 | AC14: =IFERROR(+AB14/AA14,"") -> 1.3040611 | AD14: =+X14/(D14+(N14/1.27)) -> 0.55413177 | AE14: =+Y14/(G14+(O14/1.27)) -> 1.4533793 | AF14: =+Z14/(J14+(P14/1.27)) -> 0.81518369 | AJ14: =AI14+Z14 -> 72187 | AK14: =+AL14+AM14 -> 88553.047 | AL14: =+AN14+D14 -> 62846.063 | AM14: =+AO14+G14 -> 25706.984 | AN14: =+N14/1.27 -> 2148.063 | AO14: =+O14/1.27 -> 1442.9843 | AP14: =+AO14+AN14 -> 3591.0472 | AQ14: =+AP14-S14 -> 0 | AR14: =+AP14+J14 -> 88553.047
B15: 45390 | C15: ='55 REV-'!D16+'50 REV'!D15 -> 90000 | D15: ='55 REV-'!M16+'50 REV'!L15 -> 38880 | E15: ='55 REV-'!H16+'50 REV'!G15 -> 10 | F15: fleet | G15: ='55 REV-'!J16+'50 REV'!I15 -> 10250 | H15: ='55 REV-'!K16+'50 REV'!J15 -> 11 | I15: fleet | J15: =+G15+D15 -> 49130 | K15: =IFERROR(+J15/C15,"") -> 0.54588889 | L15: =IFERROR(J15/C15,"") -> 0.54588889 | M15: ='55 REV-'!R16+'50 REV'!O15 -> 6300 | N15: ='55 REV-'!T16+'50 REV'!Q15 -> 1884.3 | O15: ='55 REV-'!U16+'50 REV'!R15 -> 1001.74 | P15: =+O15+N15 -> 2886.04 | Q15: =IFERROR(+P15/M15,"") -> 0.45810159 | R15: =+'[1]Daily All PIT'!O15 -> 66 | S15: =+P15/1.27 -> 2272.4724 | T15: =J15+S15 -> 51402.472 | U15: =+'PIT GAR 42'!R15+#REF! -> #REF! | V15: =+'PIT GAR 42'!S15+#REF! -> #REF! | W15: =U15+V15 -> #REF! | X15: ='55 REV-'!Z16+'50 REV'!W15 -> 30667 | Y15: ='55 REV-'!AA16+'50 REV'!X15 -> 26609 | Z15: =+X15+Y15 -> 57276 | AA15: =+IFERROR(C15/M15,0) -> 14.285714 | AB15: =+IFERROR(J15/P15,0) -> 17.023326 | AC15: =IFERROR(+AB15/AA15,"") -> 1.1916328 | AD15: =+X15/(D15+(N15/1.27)) -> 0.75976681 | AE15: =+Y15/(G15+(O15/1.27)) -> 2.4105037 | AF15: =+Z15/(J15+(P15/1.27)) -> 1.1142655 | AJ15: =AI15+Z15 -> 57276 | AK15: =+AL15+AM15 -> 51402.472 | AL15: =+AN15+D15 -> 40363.701 | AM15: =+AO15+G15 -> 11038.772 | AN15: =+N15/1.27 -> 1483.7008 | AO15: =+O15/1.27 -> 788.77165 | AP15: =+AO15+AN15 -> 2272.4724 | AQ15: =+AP15-S15 -> 0 | AR15: =+AP15+J15 -> 51402.472
B16: 45391 | C16: ='55 REV-'!D17+'50 REV'!D16 -> 90000 | D16: ='55 REV-'!M17+'50 REV'!L16 -> 61242 | E16: ='55 REV-'!H17+'50 REV'!G16 -> 10 | F16: fleet | G16: ='55 REV-'!J17+'50 REV'!I16 -> 37380 | H16: ='55 REV-'!K17+'50 REV'!J16 -> 10 | I16: fleet | J16: =+G16+D16 -> 98622 | K16: =IFERROR(+J16/C16,"") -> 1.0958 | L16: =IFERROR(J16/C16,"") -> 1.0958 | M16: ='55 REV-'!R17+'50 REV'!O16 -> 6300 | N16: ='55 REV-'!T17+'50 REV'!Q16 -> 1570.72 | O16: ='55 REV-'!U17+'50 REV'!R16 -> 1663.48 | P16: =+O16+N16 -> 3234.2 | Q16: =IFERROR(+P16/M16,"") -> 0.51336508 | R16: =+'[1]Daily All PIT'!O16 -> 0 | S16: =+P16/1.27 -> 2546.6142 | T16: =J16+S16 -> 101168.61 | U16: =+'PIT GAR 42'!R16+#REF! -> #REF! | V16: =+'PIT GAR 42'!S16+#REF! -> #REF! | W16: =U16+V16 -> #REF! | X16: ='55 REV-'!Z17+'50 REV'!W16 -> 15147 | Y16: ='55 REV-'!AA17+'50 REV'!X16 -> 29363 | Z16: =+X16+Y16 -> 44510 | AA16: =+IFERROR(C16/M16,0) -> 14.285714 | AB16: =+IFERROR(J16/P16,0) -> 30.493476 | AC16: =IFERROR(+AB16/AA16,"") -> 2.1345433 | AD16: =+X16/(D16+(N16/1.27)) -> 0.24243428 | AE16: =+Y16/(G16+(O16/1.27)) -> 0.75893335 | AF16: =+Z16/(J16+(P16/1.27)) -> 0.43995858 | AJ16: =AI16+Z16 -> 44510 | AK16: =+AL16+AM16 -> 101168.61 | AL16: =+AN16+D16 -> 62478.787 | AM16: =+AO16+G16 -> 38689.827 | AN16: =+N16/1.27 -> 1236.7874 | AO16: =+O16/1.27 -> 1309.8268 | AP16: =+AO16+AN16 -> 2546.6142 | AQ16: =+AP16-S16 -> 0 | AR16: =+AP16+J16 -> 101168.61
B17: 45392 | C17: ='55 REV-'!D18+'50 REV'!D17 -> 90000 | D17: ='55 REV-'!M18+'50 REV'!L17 -> 69692 | E17: ='55 REV-'!H18+'50 REV'!G17 -> 11 | F17: fleet | G17: ='55 REV-'!J18+'50 REV'!I17 -> 33246 | H17: ='55 REV-'!K18+'50 REV'!J17 -> 10 | I17: fleet | J17: =+G17+D17 -> 102938 | K17: =IFERROR(+J17/C17,"") -> 1.1437556 | L17: =IFERROR(J17/C17,"") -> 1.1437556 | M17: ='55 REV-'!R18+'50 REV'!O17 -> 6300 | N17: ='55 REV-'!T18+'50 REV'!Q17 -> 2125.72 | O17: ='55 REV-'!U18+'50 REV'!R17 -> 1892.57 | P17: =+O17+N17 -> 4018.29 | Q17: =IFERROR(+P17/M17,"") -> 0.63782381 | R17: =+'[1]Daily All PIT'!O17 -> 61 | S17: =+P17/1.27 -> 3164.0079 | T17: =J17+S17 -> 106102.01 | U17: =+'PIT GAR 42'!R17+#REF! -> #REF! | V17: =+'PIT GAR 42'!S17+#REF! -> #REF! | W17: =U17+V17 -> #REF! | X17: ='55 REV-'!Z18+'50 REV'!W17 -> 34120 | Y17: ='55 REV-'!AA18+'50 REV'!X17 -> 31331 | Z17: =+X17+Y17 -> 65451 | AA17: =+IFERROR(C17/M17,0) -> 14.285714 | AB17: =+IFERROR(J17/P17,0) -> 25.617365 | AC17: =IFERROR(+AB17/AA17,"") -> 1.7932155 | AD17: =+X17/(D17+(N17/1.27)) -> 0.47810019 | AE17: =+Y17/(G17+(O17/1.27)) -> 0.90196938 | AF17: =+Z17/(J17+(P17/1.27)) -> 0.61686863 | AJ17: =AI17+Z17 -> 65451 | AK17: =+AL17+AM17 -> 106102.01 | AL17: =+AN17+D17 -> 71365.795 | AM17: =+AO17+G17 -> 34736.213 | AN17: =+N17/1.27 -> 1673.7953 | AO17: =+O17/1.27 -> 1490.2126 | AP17: =+AO17+AN17 -> 3164.0079 | AQ17: =+AP17-S17 -> 0 | AR17: =+AP17+J17 -> 106102.01
B18: 45393 | C18: ='55 REV-'!D19+'50 REV'!D18 -> 45000 | D18: ='55 REV-'!M19+'50 REV'!L18 -> 40132 | E18: ='55 REV-'!H19+'50 REV'!G18 -> 2 | F18: fleet | G18: ='55 REV-'!J19+'50 REV'!I18 -> 31288 | H18: ='55 REV-'!K19+'50 REV'!J18 -> 10 | I18: fleet | J18: =+G18+D18 -> 71420 | K18: =IFERROR(+J18/C18,"") -> 1.5871111 | L18: =IFERROR(J18/C18,"") -> 1.5871111 | M18: ='55 REV-'!R19+'50 REV'!O18 -> 3775 | N18: ='55 REV-'!T19+'50 REV'!Q18 -> 557.18 | O18: ='55 REV-'!U19+'50 REV'!R18 -> 2379.49 | P18: =O18+N18 -> 2936.67 | Q18: =IFERROR(+P18/M18,"") -> 0.77792583 | R18: =+'[1]Daily All PIT'!O18 -> 34 | S18: =+P18/1.27 -> 2312.3386 | T18: =J18+S18 -> 73732.339 | U18: =+'PIT GAR 42'!R18+#REF! -> #REF! | V18: =+'PIT GAR 42'!S18+#REF! -> #REF! | W18: =U18+V18 -> #REF! | X18: ='55 REV-'!Z19+'50 REV'!W18 -> 10998 | Y18: ='55 REV-'!AA19+'50 REV'!X18 -> 29584 | Z18: =+X18+Y18 -> 40582 | AA18: =+IFERROR(C18/M18,0) -> 11.92053 | AB18: =+IFERROR(J18/P18,0) -> 24.320063 | AC18: =IFERROR(+AB18/AA18,"") -> 2.0401831 | AD18: =+X18/(D18+(N18/1.27)) -> 0.27108217 | AE18: =+Y18/(G18+(O18/1.27)) -> 0.8921158 | AF18: =+Z18/(J18+(P18/1.27)) -> 0.55039621 | AJ18: =AI18+Z18 -> 40582 | AK18: =+AL18+AM18 -> 73732.339 | AL18: =+AN18+D18 -> 40570.724 | AM18: =+AO18+G18 -> 33161.614 | AN18: =+N18/1.27 -> 438.72441 | AO18: =+O18/1.27 -> 1873.6142 | AP18: =+AO18+AN18 -> 2312.3386 | AQ18: =+AP18-S18 -> 0 | AR18: =+AP18+J18 -> 73732.339 | AT18: 20.1
B19: 45394 | C19: ='55 REV-'!D20+'50 REV'!D19 -> 90000 | D19: ='55 REV-'!M20+'50 REV'!L19 -> 70236 | E19: ='55 REV-'!H20+'50 REV'!G19 -> 10 | F19: fleet | G19: ='55 REV-'!J20+'50 REV'!I19 -> 35100 | H19: ='55 REV-'!K20+'50 REV'!J19 -> 10 | I19: fleet | J19: =+G19+D19 -> 105336 | K19: =IFERROR(+J19/C19,"") -> 1.1704 | L19: =IFERROR(J19/C19,"") -> 1.1704 | M19: ='55 REV-'!R20+'50 REV'!O19 -> 6300 | N19: ='55 REV-'!T20+'50 REV'!Q19 -> 2374.15 | O19: ='55 REV-'!U20+'50 REV'!R19 -> 2618.25 | P19: =+O19+N19 -> 4992.4 | Q19: =IFERROR(+P19/M19,"") -> 0.79244444 | R19: =+'[1]Daily All PIT'!O19 -> 63 | S19: =+P19/1.27 -> 3931.0236 | T19: =J19+S19 -> 109267.02 | U19: =+'PIT GAR 42'!R19+#REF! -> #REF! | V19: =+'PIT GAR 42'!S19+#REF! -> #REF! | W19: =U19+V19 -> #REF! | X19: ='55 REV-'!Z20+'50 REV'!W19 -> 36398 | Y19: ='55 REV-'!AA20+'50 REV'!X19 -> 29261 | Z19: =+X19+Y19 -> 65659 | AA19: =+IFERROR(C19/M19,0) -> 14.285714 | AB19: =+IFERROR(J19/P19,0) -> 21.099271 | AC19: =IFERROR(+AB19/AA19,"") -> 1.476949 | AD19: =+X19/(D19+(N19/1.27)) -> 0.50478876 | AE19: =+Y19/(G19+(O19/1.27)) -> 0.78739852 | AF19: =+Z19/(J19+(P19/1.27)) -> 0.60090408 | AJ19: =AI19+Z19 -> 65659 | AK19: =+AL19+AM19 -> 109267.02 | AL19: =+AN19+D19 -> 72105.409 | AM19: =+AO19+G19 -> 37161.614 | AN19: =+N19/1.27 -> 1869.4094 | AO19: =+O19/1.27 -> 2061.6142 | AP19: =+AO19+AN19 -> 3931.0236 | AQ19: =+AP19-S19 -> 0 | AR19: =+AP19+J19 -> 109267.02 | AT19: 19.76
B20: 45395 | C20: ='55 REV-'!D21+'50 REV'!D20 -> 90000 | D20: ='55 REV-'!M21+'50 REV'!L20 -> 0 | E20: ='55 REV-'!H21+'50 REV'!G20 -> 0 | F20: fleet | G20: ='55 REV-'!J21+'50 REV'!I20 -> 0 | H20: ='55 REV-'!K21+'50 REV'!J20 -> 0 | I20: fleet | J20: =+G20+D20 -> 0 | K20: =IFERROR(+J20/C20,"") -> 0 | L20: =IFERROR(J20/C20,"") -> 0 | M20: ='55 REV-'!R21+'50 REV'!O20 -> 6300 | N20: ='55 REV-'!T21+'50 REV'!Q20 -> 0 | O20: ='55 REV-'!U21+'50 REV'!R20 -> 0 | P20: =O20+N20 -> 0 | Q20: =IFERROR(+P20/M20,"") -> 0 | R20: =+'[1]Daily All PIT'!O20 -> 80 | S20: =+P20/1.27 -> 0 | T20: =J20+S20 -> 0 | U20: =+'PIT GAR 42'!R20+#REF! -> #REF! | V20: =+'PIT GAR 42'!S20+#REF! -> #REF! | W20: =U20+V20 -> #REF! | X20: ='55 REV-'!Z21+'50 REV'!W20 -> 0 | Y20: ='55 REV-'!AA21+'50 REV'!X20 -> 0 | Z20: =+X20+Y20 -> 0 | AA20: =+IFERROR(C20/M20,0) -> 14.285714 | AB20: =+IFERROR(J20/P20,0) -> 0 | AC20: =IFERROR(+AB20/AA20,"") -> 0 | AD20: =+X20/(D20+(N20/1.27)) -> #DIV/0! | AE20: =+Y20/(G20+(O20/1.27)) -> #DIV/0! | AF20: =+Z20/(J20+(P20/1.27)) -> #DIV/0! | AJ20: =AI20+Z20 -> 0 | AK20: =+AL20+AM20 -> 0 | AL20: =+AN20+D20 -> 0 | AM20: =+AO20+G20 -> 0 | AN20: =+N20/1.27 -> 0 | AO20: =+O20/1.27 -> 0 | AP20: =+AO20+AN20 -> 0 | AQ20: =+AP20-S20 -> 0 | AR20: =+AP20+J20 -> 0 | AT20: 20.06
B21: 45396 | C21: ='55 REV-'!D22+'50 REV'!D21 -> 90000 | D21: ='55 REV-'!M22+'50 REV'!L21 -> 0 | E21: ='55 REV-'!H22+'50 REV'!G21 -> 0 | F21: fleet | G21: ='55 REV-'!J22+'50 REV'!I21 -> 0 | H21: ='55 REV-'!K22+'50 REV'!J21 -> 0 | I21: fleet | J21: =+G21+D21 -> 0 | K21: =IFERROR(+J21/C21,"") -> 0 | L21: =IFERROR(J21/C21,"") -> 0 | M21: ='55 REV-'!R22+'50 REV'!O21 -> 6300 | N21: ='55 REV-'!T22+'50 REV'!Q21 -> 0 | O21: ='55 REV-'!U22+'50 REV'!R21 -> 0 | P21: =O21+N21 -> 0 | Q21: =IFERROR(+P21/M21,"") -> 0 | R21: =+'[1]Daily All PIT'!O21 -> 61 | S21: =+P21/1.27 -> 0 | T21: =J21+S21 -> 0 | U21: =+'PIT GAR 42'!R21+#REF! -> #REF! | V21: =+'PIT GAR 42'!S21+#REF! -> #REF! | W21: =U21+V21 -> #REF! | X21: ='55 REV-'!Z22+'50 REV'!W21 -> 0 | Y21: ='55 REV-'!AA22+'50 REV'!X21 -> 0 | Z21: =+X21+Y21 -> 0 | AA21: =+IFERROR(C21/M21,0) -> 14.285714 | AB21: =+IFERROR(J21/P21,0) -> 0 | AC21: =IFERROR(+AB21/AA21,"") -> 0 | AD21: =+X21/(D21+(N21/1.27)) -> #DIV/0! | AE21: =+Y21/(G21+(O21/1.27)) -> #DIV/0! | AF21: =+Z21/(J21+(P21/1.27)) -> #DIV/0! | AJ21: =AI21+Z21 -> 0 | AK21: =+AL21+AM21 -> 0 | AL21: =+AN21+D21 -> 0 | AM21: =+AO21+G21 -> 0 | AN21: =+N21/1.27 -> 0 | AO21: =+O21/1.27 -> 0 | AP21: =+AO21+AN21 -> 0 | AQ21: =+AP21-S21 -> 0 | AR21: =+AP21+J21 -> 0 | AT21: 20.97
B22: 45397 | C22: ='55 REV-'!D23+'50 REV'!D22 -> 90000 | D22: ='55 REV-'!M23+'50 REV'!L22 -> 0 | E22: ='55 REV-'!H23+'50 REV'!G22 -> 0 | F22: fleet | G22: ='55 REV-'!J23+'50 REV'!I22 -> 0 | H22: ='55 REV-'!K23+'50 REV'!J22 -> 0 | I22: fleet | J22: =+G22+D22 -> 0 | K22: =IFERROR(+J22/C22,"") -> 0 | L22: =IFERROR(J22/C22,"") -> 0 | M22: ='55 REV-'!R23+'50 REV'!O22 -> 6300 | N22: ='55 REV-'!T23+'50 REV'!Q22 -> 0 | O22: ='55 REV-'!U23+'50 REV'!R22 -> 0 | P22: =+O22+N22 -> 0 | Q22: =IFERROR(+P22/M22,"") -> 0 | R22: 112 | S22: 2015.5197 | T22: 40751.52 | U22: 0 | V22: 0 | W22: 0 | X22: ='55 REV-'!Z23+'50 REV'!W22 -> 0 | Y22: ='55 REV-'!AA23+'50 REV'!X22 -> 0 | Z22: =+X22+Y22 -> 0 | AA22: =+IFERROR(C22/M22,0) -> 14.285714 | AB22: =+IFERROR(J22/P22,0) -> 0 | AC22: =IFERROR(+AB22/AA22,"") -> 0 | AD22: =+X22/(D22+(N22/1.27)) -> #DIV/0! | AE22: =+Y22/(G22+(O22/1.27)) -> #DIV/0! | AF22: =+Z22/(J22+(P22/1.27)) -> #DIV/0! | AJ22: =AI22+Z22 -> 0 | AK22: =+AL22+AM22 -> 0 | AL22: =+AN22+D22 -> 0 | AM22: =+AO22+G22 -> 0 | AN22: =+N22/1.27 -> 0 | AO22: =+O22/1.27 -> 0 | AP22: =+AO22+AN22 -> 0 | AQ22: =+AP22-S22 -> -2015.5197 | AR22: =+AP22+J22 -> 0 | AT22: 19.56
B23: 45398 | C23: ='55 REV-'!D24+'50 REV'!D23 -> 90000 | D23: ='55 REV-'!M24+'50 REV'!L23 -> 0 | E23: ='55 REV-'!H24+'50 REV'!G23 -> 0 | F23: fleet | G23: ='55 REV-'!J24+'50 REV'!I23 -> 0 | H23: ='55 REV-'!K24+'50 REV'!J23 -> 0 | I23: fleet | J23: =+G23+D23 -> 0 | K23: =IFERROR(+J23/C23,"") -> 0 | L23: =IFERROR(J23/C23,"") -> 0 | M23: ='55 REV-'!R24+'50 REV'!O23 -> 6300 | N23: ='55 REV-'!T24+'50 REV'!Q23 -> 0 | O23: ='55 REV-'!U24+'50 REV'!R23 -> 0 | P23: =+O23+N23 -> 0 | Q23: =IFERROR(+P23/M23,"") -> 0 | R23: 128 | S23: 2405.6378 | T23: 42821.638 | U23: 0 | V23: 0 | W23: 0 | X23: ='55 REV-'!Z24+'50 REV'!W23 -> 0 | Y23: ='55 REV-'!AA24+'50 REV'!X23 -> 0 | Z23: =+X23+Y23 -> 0 | AA23: =+IFERROR(C23/M23,0) -> 14.285714 | AB23: =+IFERROR(J23/P23,0) -> 0 | AC23: =IFERROR(+AB23/AA23,"") -> 0 | AD23: =+X23/(D23+(N23/1.27)) -> #DIV/0! | AE23: =+Y23/(G23+(O23/1.27)) -> #DIV/0! | AF23: =+Z23/(J23+(P23/1.27)) -> #DIV/0! | AJ23: =AI23+Z23 -> 0 | AK23: =+AL23+AM23 -> 0 | AL23: =+AN23+D23 -> 0 | AM23: =+AO23+G23 -> 0 | AN23: =+N23/1.27 -> 0 | AO23: =+O23/1.27 -> 0 | AP23: =+AO23+AN23 -> 0 | AQ23: =+AP23-S23 -> -2405.6378 | AR23: =+AP23+J23 -> 0 | AT23: 22.16
B24: 45399 | C24: ='55 REV-'!D25+'50 REV'!D24 -> 90000 | D24: ='55 REV-'!M25+'50 REV'!L24 -> 0 | E24: ='55 REV-'!H25+'50 REV'!G24 -> 0 | F24: fleet | G24: ='55 REV-'!J25+'50 REV'!I24 -> 0 | H24: ='55 REV-'!K25+'50 REV'!J24 -> 0 | I24: fleet | J24: =+G24+D24 -> 0 | K24: =IFERROR(+J24/C24,"") -> 0 | L24: =IFERROR(J24/C24,"") -> 0 | M24: ='55 REV-'!R25+'50 REV'!O24 -> 6300 | N24: ='55 REV-'!T25+'50 REV'!Q24 -> 0 | O24: ='55 REV-'!U25+'50 REV'!R24 -> 0 | P24: =+O24+N24 -> 0 | Q24: =IFERROR(+P24/M24,"") -> 0 | R24: 64 | S24: 1188.748 | T24: 41940.748 | U24: 0 | V24: 0 | W24: 0 | X24: ='55 REV-'!Z25+'50 REV'!W24 -> 0 | Y24: ='55 REV-'!AA25+'50 REV'!X24 -> 0 | Z24: =+X24+Y24 -> 0 | AA24: =+IFERROR(C24/M24,0) -> 14.285714 | AB24: =+IFERROR(J24/P24,0) -> 0 | AC24: =IFERROR(+AB24/AA24,"") -> 0 | AD24: =+X24/(D24+(N24/1.27)) -> #DIV/0! | AE24: =+Y24/(G24+(O24/1.27)) -> #DIV/0! | AF24: =+Z24/(J24+(P24/1.27)) -> #DIV/0! | AJ24: =AI24+Z24 -> 0 | AK24: =+AL24+AM24 -> 0 | AL24: =+AN24+D24 -> 0 | AM24: =+AO24+G24 -> 0 | AN24: =+N24/1.27 -> 0 | AO24: =+O24/1.27 -> 0 | AP24: =+AO24+AN24 -> 0 | AQ24: =+AP24-S24 -> -1188.748 | AR24: =+AP24+J24 -> 0 | AT24: 21.71
B25: 45400 | C25: ='55 REV-'!D26+'50 REV'!D25 -> 45000 | D25: ='55 REV-'!M26+'50 REV'!L25 -> 0 | E25: ='55 REV-'!H26+'50 REV'!G25 -> 0 | F25: fleet | G25: ='55 REV-'!J26+'50 REV'!I25 -> 0 | H25: ='55 REV-'!K26+'50 REV'!J25 -> 0 | I25: fleet | J25: =+G25+D25 -> 0 | K25: =IFERROR(+J25/C25,"") -> 0 | L25: =IFERROR(J25/C25,"") -> 0 | M25: ='55 REV-'!R26+'50 REV'!O25 -> 3775 | N25: ='55 REV-'!T26+'50 REV'!Q25 -> 0 | O25: ='55 REV-'!U26+'50 REV'!R25 -> 0 | P25: =+O25+N25 -> 0 | Q25: =IFERROR(+P25/M25,"") -> 0 | R25: 80 | S25: 1452.7165 | T25: 32940.717 | U25: 0 | V25: 0 | W25: 0 | X25: ='55 REV-'!Z26+'50 REV'!W25 -> 0 | Y25: ='55 REV-'!AA26+'50 REV'!X25 -> 0 | Z25: =+X25+Y25 -> 0 | AA25: =+IFERROR(C25/M25,0) -> 11.92053 | AB25: =+IFERROR(J25/P25,0) -> 0 | AC25: =IFERROR(+AB25/AA25,"") -> 0 | AD25: =+X25/(D25+(N25/1.27)) -> #DIV/0! | AE25: =+Y25/(G25+(O25/1.27)) -> #DIV/0! | AF25: =+Z25/(J25+(P25/1.27)) -> #DIV/0! | AJ25: =AI25+Z25 -> 0 | AK25: =+AL25+AM25 -> 0 | AL25: =+AN25+D25 -> 0 | AM25: =+AO25+G25 -> 0 | AN25: =+N25/1.27 -> 0 | AO25: =+O25/1.27 -> 0 | AP25: =+AO25+AN25 -> 0 | AQ25: =+AP25-S25 -> -1452.7165 | AR25: =+AP25+J25 -> 0 | AT25: 22.24
A26: P | B26: 45401 | C26: ='55 REV-'!D27+'50 REV'!D26 -> 90000 | D26: ='55 REV-'!M27+'50 REV'!L26 -> 0 | E26: ='55 REV-'!H27+'50 REV'!G26 -> 0 | F26: fleet | G26: ='55 REV-'!J27+'50 REV'!I26 -> 0 | H26: ='55 REV-'!K27+'50 REV'!J26 -> 0 | I26: fleet | J26: =+G26+D26 -> 0 | K26: =IFERROR(+J26/C26,"") -> 0 | L26: =IFERROR(J26/C26,"") -> 0 | M26: ='55 REV-'!R27+'50 REV'!O26 -> 6300 | N26: ='55 REV-'!T27+'50 REV'!Q26 -> 0 | O26: ='55 REV-'!U27+'50 REV'!R26 -> 0 | P26: =+O26+N26 -> 0 | Q26: =IFERROR(+P26/M26,"") -> 0 | R26: =+'[1]Daily All PIT'!O26 -> 80 | S26: =+P26/1.27 -> 0 | T26: =J26+S26 -> 0 | U26: =+'PIT GAR 42'!R26+#REF! -> #REF! | V26: =+'PIT GAR 42'!S26+#REF! -> #REF! | W26: =U26+V26 -> #REF! | X26: ='55 REV-'!Z27+'50 REV'!W26 -> 0 | Y26: ='55 REV-'!AA27+'50 REV'!X26 -> 0 | Z26: =+X26+Y26 -> 0 | AA26: =+IFERROR(C26/M26,0) -> 14.285714 | AB26: =+IFERROR(J26/P26,0) -> 0 | AC26: =IFERROR(+AB26/AA26,"") -> 0 | AD26: =+X26/(D26+(N26/1.27)) -> #DIV/0! | AE26: =+Y26/(G26+(O26/1.27)) -> #DIV/0! | AF26: =+Z26/(J26+(P26/1.27)) -> #DIV/0! | AJ26: =AI26+Z26 -> 0 | AK26: =+AL26+AM26 -> 0 | AL26: =+AN26+D26 -> 0 | AM26: =+AO26+G26 -> 0 | AN26: =+N26/1.27 -> 0 | AO26: =+O26/1.27 -> 0 | AP26: =+AO26+AN26 -> 0 | AQ26: =+AP26-S26 -> 0 | AR26: =+AP26+J26 -> 0 | AT26: 21.9
B27: 45402 | C27: ='55 REV-'!D28+'50 REV'!D27 -> 90000 | D27: ='55 REV-'!M28+'50 REV'!L27 -> 0 | E27: ='55 REV-'!H28+'50 REV'!G27 -> 0 | F27: fleet | G27: ='55 REV-'!J28+'50 REV'!I27 -> 0 | H27: ='55 REV-'!K28+'50 REV'!J27 -> 0 | I27: fleet | J27: =+G27+D27 -> 0 | K27: =IFERROR(+J27/C27,"") -> 0 | L27: =IFERROR(J27/C27,"") -> 0 | M27: ='55 REV-'!R28+'50 REV'!O27 -> 6300 | N27: ='55 REV-'!T28+'50 REV'!Q27 -> 0 | O27: ='55 REV-'!U28+'50 REV'!R27 -> 0 | P27: =+O27+N27 -> 0 | Q27: =IFERROR(+P27/M27,"") -> 0 | R27: =+'[1]Daily All PIT'!O27 -> 87 | S27: =+P27/1.27 -> 0 | T27: =J27+S27 -> 0 | U27: =+'PIT GAR 42'!R27+#REF! -> #REF! | V27: =+'PIT GAR 42'!S27+#REF! -> #REF! | W27: =U27+V27 -> #REF! | X27: ='55 REV-'!Z28+'50 REV'!W27 -> 0 | Y27: ='55 REV-'!AA28+'50 REV'!X27 -> 0 | Z27: =+X27+Y27 -> 0 | AA27: =+IFERROR(C27/M27,0) -> 14.285714 | AB27: =+IFERROR(J27/P27,0) -> 0 | AC27: =IFERROR(+AB27/AA27,"") -> 0 | AD27: =+X27/(D27+(N27/1.27)) -> #DIV/0! | AE27: =+Y27/(G27+(O27/1.27)) -> #DIV/0! | AF27: =+Z27/(J27+(P27/1.27)) -> #DIV/0! | AJ27: =AI27+Z27 -> 0 | AK27: =+AL27+AM27 -> 0 | AL27: =+AN27+D27 -> 0 | AM27: =+AO27+G27 -> 0 | AN27: =+N27/1.27 -> 0 | AO27: =+O27/1.27 -> 0 | AP27: =+AO27+AN27 -> 0 | AQ27: =+AP27-S27 -> 0 | AR27: =+AP27+J27 -> 0 | AT27: =34.75-13.11 -> 21.64
B28: 45403 | C28: ='55 REV-'!D29+'50 REV'!D28 -> 90000 | D28: ='55 REV-'!M29+'50 REV'!L28 -> 0 | E28: ='55 REV-'!H29+'50 REV'!G28 -> 0 | F28: fleet | G28: ='55 REV-'!J29+'50 REV'!I28 -> 0 | H28: ='55 REV-'!K29+'50 REV'!J28 -> 0 | I28: fleet | J28: =+G28+D28 -> 0 | K28: =IFERROR(+J28/C28,"") -> 0 | L28: =IFERROR(J28/C28,"") -> 0 | M28: ='55 REV-'!R29+'50 REV'!O28 -> 6300 | N28: ='55 REV-'!T29+'50 REV'!Q28 -> 0 | O28: ='55 REV-'!U29+'50 REV'!R28 -> 0 | P28: =+O28+N28 -> 0 | Q28: =IFERROR(+P28/M28,"") -> 0 | R28: =+'[1]Daily All PIT'!O28 -> 99 | S28: =+P28/1.27 -> 0 | T28: =J28+S28 -> 0 | U28: =+'PIT GAR 42'!R28+#REF! -> #REF! | V28: =+'PIT GAR 42'!S28+#REF! -> #REF! | W28: =U28+V28 -> #REF! | X28: ='55 REV-'!Z29+'50 REV'!W28 -> 0 | Y28: ='55 REV-'!AA29+'50 REV'!X28 -> 0 | Z28: =+X28+Y28 -> 0 | AA28: =+IFERROR(C28/M28,0) -> 14.285714 | AB28: =+IFERROR(J28/P28,0) -> 0 | AC28: =IFERROR(+AB28/AA28,"") -> 0 | AD28: =+X28/(D28+(N28/1.27)) -> #DIV/0! | AE28: =+Y28/(G28+(O28/1.27)) -> #DIV/0! | AF28: =+Z28/(J28+(P28/1.27)) -> #DIV/0! | AJ28: =AI28+Z28 -> 0 | AK28: =+AL28+AM28 -> 0 | AL28: =+AN28+D28 -> 0 | AM28: =+AO28+G28 -> 0 | AN28: =+N28/1.27 -> 0 | AO28: =+O28/1.27 -> 0 | AP28: =+AO28+AN28 -> 0 | AQ28: =+AP28-S28 -> 0 | AR28: =+AP28+J28 -> 0 | AT28: 21
B29: 45404 | C29: ='55 REV-'!D30+'50 REV'!D29 -> 90000 | D29: ='55 REV-'!M30+'50 REV'!L29 -> 0 | E29: ='55 REV-'!H30+'50 REV'!G29 -> 0 | F29: fleet | G29: ='55 REV-'!J30+'50 REV'!I29 -> 0 | H29: ='55 REV-'!K30+'50 REV'!J29 -> 0 | I29: fleet | J29: =+G29+D29 -> 0 | K29: =IFERROR(+J29/C29,"") -> 0 | L29: =IFERROR(J29/C29,"") -> 0 | M29: ='55 REV-'!R30+'50 REV'!O29 -> 6300 | N29: ='55 REV-'!T30+'50 REV'!Q29 -> 0 | O29: ='55 REV-'!U30+'50 REV'!R29 -> 0 | P29: =O29+N29 -> 0 | Q29: =IFERROR(+P29/M29,"") -> 0 | R29: =+'[1]Daily All PIT'!O29 -> 73 | S29: =+P29/1.27 -> 0 | T29: =J29+S29 -> 0 | U29: =+'PIT GAR 42'!R29+#REF! -> #REF! | V29: =+'PIT GAR 42'!S29+#REF! -> #REF! | W29: =U29+V29 -> #REF! | X29: ='55 REV-'!Z30+'50 REV'!W29 -> 0 | Y29: ='55 REV-'!AA30+'50 REV'!X29 -> 0 | Z29: =+X29+Y29 -> 0 | AA29: =+IFERROR(C29/M29,0) -> 14.285714 | AB29: =+IFERROR(J29/P29,0) -> 0 | AC29: =IFERROR(+AB29/AA29,"") -> 0 | AD29: =+X29/(D29+(N29/1.27)) -> #DIV/0! | AE29: =+Y29/(G29+(O29/1.27)) -> #DIV/0! | AF29: =+Z29/(J29+(P29/1.27)) -> #DIV/0! | AJ29: =AI29+Z29 -> 0 | AK29: =+AL29+AM29 -> 0 | AL29: =+AN29+D29 -> 0 | AM29: =+AO29+G29 -> 0 | AN29: =+N29/1.27 -> 0 | AO29: =+O29/1.27 -> 0 | AP29: =+AO29+AN29 -> 0 | AQ29: =+AP29-S29 -> 0 | AR29: =+AP29+J29 -> 0 | AT29: 19.65
B30: 45405 | C30: ='55 REV-'!D31+'50 REV'!D30 -> 90000 | D30: ='55 REV-'!M31+'50 REV'!L30 -> 0 | E30: ='55 REV-'!H31+'50 REV'!G30 -> 0 | F30: fleet | G30: ='55 REV-'!J31+'50 REV'!I30 -> 0 | H30: ='55 REV-'!K31+'50 REV'!J30 -> 0 | I30: fleet | J30: =+G30+D30 -> 0 | K30: =IFERROR(+J30/C30,"") -> 0 | L30: =IFERROR(J30/C30,"") -> 0 | M30: ='55 REV-'!R31+'50 REV'!O30 -> 6300 | N30: ='55 REV-'!T31+'50 REV'!Q30 -> 0 | O30: ='55 REV-'!U31+'50 REV'!R30 -> 0 | P30: =+O30+N30 -> 0 | Q30: =IFERROR(+P30/M30,"") -> 0 | R30: =+'[1]Daily All PIT'!O30 -> 14 | S30: =+P30/1.27 -> 0 | T30: =J30+S30 -> 0 | U30: =+'PIT GAR 42'!R30+#REF! -> #REF! | V30: =+'PIT GAR 42'!S30+#REF! -> #REF! | W30: =U30+V30 -> #REF! | X30: ='55 REV-'!Z31+'50 REV'!W30 -> 0 | Y30: ='55 REV-'!AA31+'50 REV'!X30 -> 0 | Z30: =+X30+Y30 -> 0 | AA30: =+IFERROR(C30/M30,0) -> 14.285714 | AB30: =+IFERROR(J30/P30,0) -> 0 | AC30: =IFERROR(+AB30/AA30,"") -> 0 | AD30: =+X30/(D30+(N30/1.27)) -> #DIV/0! | AE30: =+Y30/(G30+(O30/1.27)) -> #DIV/0! | AF30: =+Z30/(J30+(P30/1.27)) -> #DIV/0! | AJ30: =AI30+Z30 -> 0 | AK30: =+AL30+AM30 -> 0 | AL30: =+AN30+D30 -> 0 | AM30: =+AO30+G30 -> 0 | AN30: =+N30/1.27 -> 0 | AO30: =+O30/1.27 -> 0 | AP30: =+AO30+AN30 -> 0 | AQ30: =+AP30-S30 -> 0 | AR30: =+AP30+J30 -> 0 | AT30: 20.07
B31: 45406 | C31: ='55 REV-'!D32+'50 REV'!D31 -> 90000 | D31: ='55 REV-'!M32+'50 REV'!L31 -> 0 | E31: ='55 REV-'!H32+'50 REV'!G31 -> 0 | F31: fleet | G31: ='55 REV-'!J32+'50 REV'!I31 -> 0 | H31: ='55 REV-'!K32+'50 REV'!J31 -> 0 | I31: fleet | J31: =+G31+D31 -> 0 | K31: =IFERROR(+J31/C31,"") -> 0 | L31: =IFERROR(J31/C31,"") -> 0 | M31: ='55 REV-'!R32+'50 REV'!O31 -> 6300 | N31: ='55 REV-'!T32+'50 REV'!Q31 -> 0 | O31: ='55 REV-'!U32+'50 REV'!R31 -> 0 | P31: =+O31+N31 -> 0 | Q31: =IFERROR(+P31/M31,"") -> 0 | R31: =+'[1]Daily All PIT'!O31 -> 55 | S31: =+P31/1.27 -> 0 | T31: =J31+S31 -> 0 | U31: =+'PIT GAR 42'!R31+#REF! -> #REF! | V31: =+'PIT GAR 42'!S31+#REF! -> #REF! | W31: =U31+V31 -> #REF! | X31: ='55 REV-'!Z32+'50 REV'!W31 -> 0 | Y31: ='55 REV-'!AA32+'50 REV'!X31 -> 0 | Z31: =+X31+Y31 -> 0 | AA31: =+IFERROR(C31/M31,0) -> 14.285714 | AB31: =+IFERROR(J31/P31,0) -> 0 | AC31: =IFERROR(+AB31/AA31,"") -> 0 | AD31: =+X31/(D31+(N31/1.27)) -> #DIV/0! | AE31: =+Y31/(G31+(O31/1.27)) -> #DIV/0! | AF31: =+Z31/(J31+(P31/1.27)) -> #DIV/0! | AJ31: =AI31+Z31 -> 0 | AK31: =+AL31+AM31 -> 0 | AL31: =+AN31+D31 -> 0 | AM31: =+AO31+G31 -> 0 | AN31: =+N31/1.27 -> 0 | AO31: =+O31/1.27 -> 0 | AP31: =+AO31+AN31 -> 0 | AQ31: =+AP31-S31 -> 0 | AR31: =+AP31+J31 -> 0 | AT31: 20.65
B32: 45407 | C32: ='55 REV-'!D33+'50 REV'!D32 -> 45000 | D32: ='55 REV-'!M33+'50 REV'!L32 -> 0 | E32: ='55 REV-'!H33+'50 REV'!G32 -> 0 | F32: fleet | G32: ='55 REV-'!J33+'50 REV'!I32 -> 0 | H32: ='55 REV-'!K33+'50 REV'!J32 -> 0 | I32: fleet | J32: =+G32+D32 -> 0 | K32: =IFERROR(+J32/C32,"") -> 0 | L32: =IFERROR(J32/C32,"") -> 0 | M32: ='55 REV-'!R33+'50 REV'!O32 -> 3775 | N32: ='55 REV-'!T33+'50 REV'!Q32 -> 0 | O32: ='55 REV-'!U33+'50 REV'!R32 -> 0 | P32: =+O32+N32 -> 0 | Q32: =IFERROR(+P32/M32,"") -> 0 | X32: ='55 REV-'!Z33+'50 REV'!W32 -> 0 | Y32: ='55 REV-'!AA33+'50 REV'!X32 -> 0 | Z32: =+X32+Y32 -> 0 | AA32: =+IFERROR(C32/M32,0) -> 11.92053 | AB32: =+IFERROR(J32/P32,0) -> 0 | AC32: =IFERROR(+AB32/AA32,"") -> 0 | AD32: =+X32/(D32+(N32/1.27)) -> #DIV/0! | AE32: =+Y32/(G32+(O32/1.27)) -> #DIV/0! | AF32: =+Z32/(J32+(P32/1.27)) -> #DIV/0! | AJ32: =AI32+Z32 -> 0
B33: 45408 | C33: ='55 REV-'!D34+'50 REV'!D33 -> 90000 | D33: ='55 REV-'!M34+'50 REV'!L33 -> 0 | E33: ='55 REV-'!H34+'50 REV'!G33 -> 0 | F33: fleet | G33: ='55 REV-'!J34+'50 REV'!I33 -> 0 | H33: ='55 REV-'!K34+'50 REV'!J33 -> 0 | I33: fleet | J33: =+G33+D33 -> 0 | K33: =IFERROR(+J33/C33,"") -> 0 | L33: =IFERROR(J33/C33,"") -> 0 | M33: ='55 REV-'!R34+'50 REV'!O33 -> 6300 | N33: ='55 REV-'!T34+'50 REV'!Q33 -> 0 | O33: ='55 REV-'!U34+'50 REV'!R33 -> 0 | P33: =+O33+N33 -> 0 | Q33: =IFERROR(+P33/M33,"") -> 0 | R33: =+'[1]Daily All PIT'!O33 -> 125 | S33: =+P33/1.27 -> 0 | T33: =J33+S33 -> 0 | U33: =+'PIT GAR 42'!R33+#REF! -> #REF! | V33: =+'PIT GAR 42'!S33+#REF! -> #REF! | W33: =U33+V33 -> #REF! | X33: ='55 REV-'!Z34+'50 REV'!W33 -> 0 | Y33: ='55 REV-'!AA34+'50 REV'!X33 -> 0 | Z33: =+X33+Y33 -> 0 | AA33: =+IFERROR(C33/M33,0) -> 14.285714 | AB33: =+IFERROR(J33/P33,0) -> 0 | AC33: =IFERROR(+AB33/AA33,"") -> 0 | AD33: =+X33/(D33+(N33/1.27)) -> #DIV/0! | AE33: =+Y33/(G33+(O33/1.27)) -> #DIV/0! | AF33: =+Z33/(J33+(P33/1.27)) -> #DIV/0! | AJ33: =AI33+Z33 -> 0 | AK33: =+AL33+AM33 -> 0 | AL33: =+AN33+D33 -> 0 | AM33: =+AO33+G33 -> 0 | AN33: =+N33/1.27 -> 0 | AO33: =+O33/1.27 -> 0 | AP33: =+AO33+AN33 -> 0 | AQ33: =+AP33-S33 -> 0 | AR33: =+AP33+J33 -> 0 | AT33: 21.9
B34: 45409 | C34: ='55 REV-'!D35+'50 REV'!D34 -> 90000 | D34: ='55 REV-'!M35+'50 REV'!L34 -> 0 | E34: ='55 REV-'!H35+'50 REV'!G34 -> 0 | F34: fleet | G34: ='55 REV-'!J35+'50 REV'!I34 -> 0 | H34: ='55 REV-'!K35+'50 REV'!J34 -> 0 | I34: fleet | J34: =+G34+D34 -> 0 | K34: =IFERROR(+J34/C34,"") -> 0 | L34: =IFERROR(J34/C34,"") -> 0 | M34: ='55 REV-'!R35+'50 REV'!O34 -> 6300 | N34: ='55 REV-'!T35+'50 REV'!Q34 -> 0 | O34: ='55 REV-'!U35+'50 REV'!R34 -> 0 | P34: =+O34+N34 -> 0 | Q34: =IFERROR(+P34/M34,"") -> 0 | R34: =+'[1]Daily All PIT'!O34 -> 63 | S34: =+P34/1.27 -> 0 | T34: =J34+S34 -> 0 | U34: =+'PIT GAR 42'!R34+#REF! -> #REF! | V34: =+'PIT GAR 42'!S34+#REF! -> #REF! | W34: =U34+V34 -> #REF! | X34: ='55 REV-'!Z35+'50 REV'!W34 -> 0 | Y34: ='55 REV-'!AA35+'50 REV'!X34 -> 0 | Z34: =+X34+Y34 -> 0 | AA34: =+IFERROR(C34/M34,0) -> 14.285714 | AB34: =+IFERROR(J34/P34,0) -> 0 | AC34: =IFERROR(+AB34/AA34,"") -> 0 | AD34: =+X34/(D34+(N34/1.27)) -> #DIV/0! | AE34: =+Y34/(G34+(O34/1.27)) -> #DIV/0! | AF34: =+Z34/(J34+(P34/1.27)) -> #DIV/0! | AJ34: =AI34+Z34 -> 0 | AK34: =+AL34+AM34 -> 0 | AL34: =+AN34+D34 -> 0 | AM34: =+AO34+G34 -> 0 | AN34: =+N34/1.27 -> 0 | AO34: =+O34/1.27 -> 0 | AP34: =+AO34+AN34 -> 0 | AQ34: =+AP34-S34 -> 0 | AR34: =+AP34+J34 -> 0 | AT34: 20.98
B35: 45410 | C35: ='55 REV-'!D36+'50 REV'!D35 -> 90000 | D35: ='55 REV-'!M36+'50 REV'!L35 -> 0 | E35: ='55 REV-'!H36+'50 REV'!G35 -> 0 | F35: fleet | G35: ='55 REV-'!J36+'50 REV'!I35 -> 0 | H35: ='55 REV-'!K36+'50 REV'!J35 -> 0 | I35: fleet | J35: =+G35+D35 -> 0 | K35: =IFERROR(+J35/C35,"") -> 0 | L35: =IFERROR(J35/C35,"") -> 0 | M35: ='55 REV-'!R36+'50 REV'!O35 -> 6300 | N35: ='55 REV-'!T36+'50 REV'!Q35 -> 0 | O35: ='55 REV-'!U36+'50 REV'!R35 -> 0 | P35: =+O35+N35 -> 0 | Q35: =IFERROR(+P35/M35,"") -> 0 | R35: =+'[1]Daily All PIT'!O35 -> 35 | S35: =+P35/1.27 -> 0 | T35: =J35+S35 -> 0 | U35: =+'PIT GAR 42'!R35+#REF! -> #REF! | V35: =+'PIT GAR 42'!S35+#REF! -> #REF! | W35: =U35+V35 -> #REF! | X35: ='55 REV-'!Z36+'50 REV'!W35 -> 0 | Y35: ='55 REV-'!AA36+'50 REV'!X35 -> 0 | Z35: =+X35+Y35 -> 0 | AA35: =+IFERROR(C35/M35,0) -> 14.285714 | AB35: =+IFERROR(J35/P35,0) -> 0 | AC35: =IFERROR(+AB35/AA35,"") -> 0 | AD35: =+X35/(D35+(N35/1.27)) -> #DIV/0! | AE35: =+Y35/(G35+(O35/1.27)) -> #DIV/0! | AF35: =+Z35/(J35+(P35/1.27)) -> #DIV/0! | AJ35: =AI35+Z35 -> 0 | AK35: =+AL35+AM35 -> 0 | AL35: =+AN35+D35 -> 0 | AM35: =+AO35+G35 -> 0 | AN35: =+N35/1.27 -> 0 | AO35: =+O35/1.27 -> 0 | AP35: =+AO35+AN35 -> 0 | AQ35: =+AP35-S35 -> 0 | AR35: =+AP35+J35 -> 0 | AT35: 21.08
B36: 45411 | C36: ='55 REV-'!D37+'50 REV'!D36 -> 90000 | D36: ='55 REV-'!M37+'50 REV'!L36 -> 0 | E36: ='55 REV-'!H37+'50 REV'!G36 -> 0 | F36: fleet | G36: ='55 REV-'!J37+'50 REV'!I36 -> 0 | H36: ='55 REV-'!K37+'50 REV'!J36 -> 0 | I36: fleet | J36: =+G36+D36 -> 0 | L36: =IFERROR(J36/C36,"") -> 0 | M36: ='55 REV-'!R37+'50 REV'!O36 -> 6300 | N36: ='55 REV-'!T37+'50 REV'!Q36 -> 0 | O36: ='55 REV-'!U37+'50 REV'!R36 -> 0 | P36: =+O36+N36 -> 0 | X36: ='55 REV-'!Z37+'50 REV'!W36 -> 0 | Y36: ='55 REV-'!AA37+'50 REV'!X36 -> 0 | Z36: =+X36+Y36 -> 0 | AA36: =+IFERROR(C36/M36,0) -> 14.285714 | AB36: =+IFERROR(J36/P36,0) -> 0 | AC36: =IFERROR(+AB36/AA36,"") -> 0 | AD36: =+X36/(D36+(N36/1.27)) -> #DIV/0! | AE36: =+Y36/(G36+(O36/1.27)) -> #DIV/0! | AF36: =+Z36/(J36+(P36/1.27)) -> #DIV/0! | AJ36: =AI36+Z36 -> 0
B37: 45412 | C37: ='55 REV-'!D38+'50 REV'!D37 -> 90000 | D37: ='55 REV-'!M38+'50 REV'!L37 -> 0 | E37: ='55 REV-'!H38+'50 REV'!G37 -> 0 | F37: fleet | G37: ='55 REV-'!J38+'50 REV'!I37 -> 0 | H37: ='55 REV-'!K38+'50 REV'!J37 -> 0 | I37: fleet | J37: =+G37+D37 -> 0 | L37: =IFERROR(J37/C37,"") -> 0 | M37: ='55 REV-'!R38+'50 REV'!O37 -> 6300 | N37: ='55 REV-'!T38+'50 REV'!Q37 -> 0 | O37: ='55 REV-'!U38+'50 REV'!R37 -> 0 | P37: =+O37+N37 -> 0 | X37: ='55 REV-'!Z38+'50 REV'!W37 -> 0 | Y37: ='55 REV-'!AA38+'50 REV'!X37 -> 0 | Z37: =+X37+Y37 -> 0 | AA37: =+IFERROR(C37/M37,0) -> 14.285714 | AB37: =+IFERROR(J37/P37,0) -> 0 | AC37: =IFERROR(+AB37/AA37,"") -> 0 | AD37: =+X37/(D37+(N37/1.27)) -> #DIV/0! | AE37: =+Y37/(G37+(O37/1.27)) -> #DIV/0! | AF37: =+Z37/(J37+(P37/1.27)) -> #DIV/0!
B38: 45413 | F38: fleet | I38: fleet | L38: =IFERROR(J38/C38,"")
B39: TOTAL | C39: =SUM(C8:C37) -> 2520000 | D39: =SUM(D8:D37) -> 733480 | F39: Fleet | G39: =SUM(G8:G37) -> 380146 | I39: Fleet | J39: =G39+D39 -> 1113626 | K39: =IFERROR(+J39/C39,"") -> 0.44191508 | L39: =IFERROR(J39/C39,"") -> 0.44191508 | M39: =SUM(M8:M37) -> 178900 | N39: =SUM(N8:N37) -> 26623.77 | O39: =SUM(O8:O37) -> 26621.34 | P39: =O39+N39 -> 53245.11 | Q39: =IFERROR(+P39/M39,"") -> 0.29762499 | R39: =SUM(R8:R36) -> 1810 | S39: =+P39/1.27 -> 41925.283 | T39: =J39+S39 -> 1155551.3 | U39: =SUM(U8:U36) -> #REF! | V39: =SUM(V8:V36) -> #REF! | W39: =SUM(W8:W36) -> #REF! | X39: =SUM(X8:X37) -> 360704 | Y39: =SUM(Y8:Y37) -> 391974.5 | Z39: =+X39+Y39 -> 752678.5 | AA39: =+IFERROR(C39/M39,0) -> 14.086082 | AB39: =+IFERROR(J39/P39,"") -> 20.915085 | AC39: =IFERROR(+AB39/AA39,"") -> 1.484805 | AD39: =+X39/(D39+(N39/1.27)) -> 0.47810599 | AE39: =+Y39/(G39+(O39/1.27)) -> 0.97723009 | AF39: =+Z39/(J39+(P39/1.27)) -> 0.6513588 | AG39: =SUM(AG8:AG36) -> 0 | AH39: =SUM(AH8:AH36) -> 0 | AI39: =SUM(AI8:AI38) -> 0 | AJ39: =SUM(AJ8:AJ36) -> 752678.5 | AK39: =SUM(AK8:AK36) -> 1155551.3 | AL39: =SUM(AL8:AL36) -> 754443.6 | AM39: =SUM(AM8:AM36) -> 401107.69 | AN39: =+N39/1.27 -> 20963.598 | AO39: =+O39/1.27 -> 20961.685 | AP39: =+AO39+AN39 -> 41925.283 | AQ39: =+AP39-S39 -> 0 | AR39: =+AP39+J39 -> 1155551.3 | AT39: 19.71
AT40: 20.07
C41: MTD OB | D41: =J39 -> 1113626 | G41: MTD OB PAGI | K41: =+D39 -> 733480 | M41: =+D39 -> 733480 | O41: Note : | P41: Plan sesuai dengan rencana kerja mingguan | Z41: MTD ACHIEVEMENT | AT41: 20.17
...

Sheet Fleet.1
A1: PT. SUMBER MITRA JAYA | S1: Lampiran
A2: FLEET PERFORMANCE
A4: PAGI
A5: TGL | B5: EXCAVATOR | C5: NAMA OPERATOR | D5: HM AWAL | E5: HM AKHIR | F5: TOTAL HM | G5: PRODUKSI | H5: LOKASI KERJA | J5: PRODUKTIVITAS | M5: JARAK (KM) | N5: JML DT | O5: SUPPORT | P5: HM AWAL | Q5: HM AKHIR | R5: TOTAL HM | S5: KETERANGAN
H6: PIT | I6: SEAM/ BLOK | J6: PLAN | K6: ACTUAL | L6: % | O6: DOZER
A7: 42429 | B7: PC.1250-01 | C7: Amri | D7: 17650 | E7: 17660 | F7: =E7-D7 -> 10 | G7: =(164*24)+(4*24) -> 4032 | H7: Pit GAR 55 | I7: SM1 | J7: 500 | K7: =G7/F7 -> 403.2 | L7: =K7/J7 -> 0.8064 | M7: 3.5 | N7: 7 | O7: DZ375-10 | P7: 13420 | Q7: 13429 | R7: =Q7-P7 -> 9 | S7: Start loading jam 08.12, jam 08.25-09.21 tunggu rippingan, jam 17.10-17.14 pindah front
A8: 42429 | B8: PC.1250-02 | C8: Arifin | D8: 17907 | E8: 17917 | F8: =E8-D8 -> 10 | G8: =195*24 -> 4680 | H8: Pit GAR 55 | I8: SM1 | J8: 500 | K8: =G8/F8 -> 468 | L8: =K8/J8 -> 0.936 | M8: 3.8 | N8: 7 | O8: DZ375-02 | P8: 17159 | Q8: 17166 | R8: =Q8-P8 -> 7 | S8: Start loading jam 07.55, jam 09.40-10.05 pengecekan mekanik
O9: DZ375-01 | P9: 18708 | Q9: 18710 | R9: =Q9-P9 -> 2
A10: 42429 | B10: PC.1250-04 | S10: Stand By
A11: 42429 | B11: PC.1250-05 | C11: Simon H | D11: 14125 | E11: 14131 | F11: =E11-D11 -> 6 | G11: =135*24 -> 3240 | H11: Pit GAR 42 | I11: S-1 | J11: 500 | K11: =IFERROR(G11/F11,0) -> 540 | L11: =K11/J11 -> 1.08 | M11: 0.9 | N11: 4 | O11: DZ375-03 | P11: 15408 | Q11: 15418 | R11: =Q11-P11 -> 10 | S11: Start loading jam 08.03, jam 09.07-09.19 pindah front, jam 14.16-14.31 hujan, jam 14.31-15.19 sekrap jalan, jam 13.00-13.42 perbaikan AC, jam 15.51-18.16 perbaikan mekanik (AC panas), start loading jam 18.16
A12: 42429 | B12: PC.1250-06 | S12: BD - Silinder Arm Bocor
A13: 42429 | B13: PC.1250-07 | C13: Nanang | D13: 12623 | E13: 12632 | F13: =E13-D13 -> 9 | G13: =81*24 -> 1944 | H13: Pit GAR 42 | I13: S-2 | J13: 500 | K13: =IFERROR(G13/F13,0) -> 216 | L13: =K13/J13 -> 0.432 | M13: 1 | N13: 4 | O13: DZ375-07 | P13: 15230 | Q13: 15240 | R13: =Q13-P13 -> 10 | S13: Start loading jam 08.01, jam 08.21-09.15 pengelasan tracklink, jam 09.15-11.59 general batu bara, jam 01.09 loading OB kembali, jam 14.16-14.31 hujan, jam 14.31-15.10 sekrap jalan, jam 16.30-17.19 stand by (bantu dorong pompa)
A14: 42429 | B14: PC.700-02 | S14: General
A15: 42429 | B15: PC.700-03 | S15: General
B16: TOTAL | F16: =SUM(F7:F15) -> 35 | G16: =SUM(G7:G15) -> 13896 | R16: =SUM(R7:R15) -> 38
A18: MALAM
A19: TGL | B19: EXCAVATOR | C19: NAMA OPERATOR | D19: HM AWAL | E19: HM AKHIR | F19: TOTAL HM | G19: PRODUKSI | H19: LOKASI KERJA | J19: PRODUKTIVITAS | M19: JARAK (KM) | N19: JML DT | O19: SUPPORT | P19: HM AWAL | Q19: HM AKHIR | R19: TOTAL HM | S19: KETERANGAN
H20: PIT | I20: SEAM/ BLOK | J20: PLAN | K20: ACTUAL | L20: % | O20: DOZER
A21: 42429 | B21: PC.1250-01 | C21: Ardiansyah | D21: 17660 | E21: 17670 | F21: =+E21-D21 -> 10 | G21: =151*24 -> 3624 | H21: Pit GAR 55 | I21: SM1 | J21: 500 | K21: =G21/F21 -> 362.4 | L21: =K21/J21 -> 0.7248 | M21: 2.6 | N21: 5 | O21: DZ375-10 | P21: 13428 | Q21: 13438 | R21: =Q21-P21 -> 10 | S21: Jam 20.00-20.10 perbaikan front, start loading jam 20.10, jam 21.26-21.32 pindah front, jam 22.22-22.29 perbaikan jalan, jam 03.58-04.05 perbaikan front, jam 04.54-05.06 perbaikan front
A22: 42429 | B22: PC.1250-02 | C22: Setiawan | D22: 17917 | E22: 17927 | F22: =+E22-D22 -> 10 | G22: =226*24 -> 5424 | H22: Pit GAR 55 | I22: SM2 | J22: 500 | K22: =G22/F22 -> 542.4 | L22: =K22/J22 -> 1.0848 | M22: 1.4 | N22: 5 | O22: DZ375-10 | P22: 13428 | Q22: 13438 | R22: =Q22-P22 -> 10 | S22: Start loading jam 20.00, jam 02.11-02.13 perbaikan front, jam 05.55-06.03 pindah front
A23: 42429 | B23: PC.1250-04 | S23: BD - Tidak Bisa Start
A24: 42429 | B24: PC.1250-05 | C24: Royal | D24: 14131 | E24: 14140 | F24: =+E24-D24 -> 9 | G24: =142*24 -> 3408 | H24: Pit GAR 42 | I24: S-1 | J24: 500 | K24: =IFERROR(G24/F24,0) -> 378.66667 | L24: =K24/J24 -> 0.75733333 | M24: 0.6 | N24: 4 | O24: DZ375-07 | P24: 15240 | Q24: 15250 | R24: =Q24-P24 -> 10 | S24: Jam 20.00-20.22 greasing, start loading jam 20.22, jam 21.21-22.06 tunggu rippingan, jam 01.53-02.10 perbaikan front, jam 02.35-03.53 tunggu rippingan, jam 05.44-05.49 perbaikan front
A25: 42429 | B25: PC.1250-06 | S25: BD - Silinder Arm Bocor
A26: 42429 | B26: PC.1250-07 | S26: Loading BB
A27: 42429 | B27: PC.700-02 | S27: Stand By
A28: 42429 | B28: PC.700-03 | S28: Stand By
B29: TOTAL | F29: =SUM(F21:F28) -> 29 | G29: =SUM(G21:G28) -> 12456 | R29: =SUM(R21:R28) -> 30

Sheet PIT GAR 42
B2: PT. SUMBER MITRA JAYA
B3: DAILY REPORT GAR 4200
AG4: U/FUEL
B5: TGL | C5: OVERBURDEN (BCM) | J5: BATUBARA (TON) | Q5: TOTAL MATERIAL (BCM) | R5: NON VOLUME (BCM) | U5: Solar Pagi | V5: Solar Malam | W5: PEMAKAIAN SOLAR (LTR) | X5: SR | AA5: FR PAGI | AB5: FR MALAM | AC5: FR | AD5: RAIN | AE5: SLIPERY | AG5: TOTAL MATERIAL (BCM) | AH5: TOTAL MATERIAL PAGI (BCM | AI5: TOTAL MATERIAL MALAM ( BCM )
C6: PLAN | D6: ACTUAL | I6: % | J6: PLAN | K6: ACTUAL | N6: % | O6: ACTUAL
D7: PAGI | E7: Fleet | F7: MALAM | G7: Fleet | H7: TOTAL | K7: PAGI | L7: MALAM | M7: TOTAL | O7: RIT | P7: (BCM) | R7: PAGI | S7: MALAM | T7: TOTAL | X7: PLAN | Y7: ACT | Z7: %ACH
B8: 43221 | C8: 0 | D8: 0 | E8: 0 | F8: 0 | G8: 0 | H8: 0 | I8: 0 | N8: =IFERROR(+M8/J8,"") | P8: =+M8/1.27 -> 0 | Q8: =H8+P8 -> 0 | R8: 0 | S8: 0 | T8: 0 | W8: =+U8+V8 -> 0 | X8: =IFERROR(C8/J8,"") | Y8: =+IFERROR(H8/M8,0) -> 0 | Z8: =IFERROR(+Y8/X8,0) -> 0 | AA8: =+IFERROR(U8/AH8,0) -> 0 | AB8: =+IFERROR(V8/AI8,0) -> 0 | AC8: =IFERROR(W8/AG8,0) -> 0 | AG8: =(H8+T8)+(M8/1.27) -> 0 | AH8: =(D8+R8)+(K8/1.27) -> 0 | AI8: =(F8+S8)+(L8/1.27) -> 0
B9: 43222 | C9: 0 | D9: 0 | E9: 0 | F9: 0 | G9: 0 | H9: 0 | I9: 0 | N9: =IFERROR(+M9/J9,"") | P9: =+M9/1.27 -> 0 | Q9: =H9+P9 -> 0 | R9: 0 | S9: 0 | T9: 0 | W9: =+U9+V9 -> 0 | X9: =IFERROR(C9/J9,"") | Y9: =+IFERROR(H9/M9,0) -> 0 | Z9: =IFERROR(+Y9/X9,0) -> 0 | AA9: =+IFERROR(U9/AH9,0) -> 0 | AB9: =+IFERROR(V9/AI9,0) -> 0 | AC9: =IFERROR(W9/AG9,0) -> 0 | AG9: =(H9+T9)+(M9/1.27) -> 0 | AH9: =(D9+R9)+(K9/1.27) -> 0 | AI9: =(F9+S9)+(L9/1.27) -> 0
B10: 43223 | C10: 0 | D10: 0 | E10: 0 | F10: 0 | G10: 0 | H10: 0 | I10: 0 | N10: =IFERROR(+M10/J10,"") | P10: =+M10/1.27 -> 0 | Q10: =H10+P10 -> 0 | R10: 0 | S10: 0 | T10: 0 | W10: =+U10+V10 -> 0 | X10: =IFERROR(C10/J10,"") | Y10: =+IFERROR(H10/M10,0) -> 0 | Z10: =IFERROR(+Y10/X10,0) -> 0 | AA10: =+IFERROR(U10/AH10,0) -> 0 | AB10: =+IFERROR(V10/AI10,0) -> 0 | AC10: =IFERROR(W10/AG10,0) -> 0 | AG10: =(H10+T10)+(M10/1.27) -> 0 | AH10: =(D10+R10)+(K10/1.27) -> 0 | AI10: =(F10+S10)+(L10/1.27) -> 0
B11: 43224 | C11: 0 | D11: 0 | E11: 0 | F11: 0 | G11: 0 | H11: 0 | I11: 0 | N11: =IFERROR(+M11/J11,"") | P11: =+M11/1.27 -> 0 | Q11: =H11+P11 -> 0 | R11: 0 | S11: 0 | T11: 0 | W11: =+U11+V11 -> 0 | X11: =IFERROR(C11/J11,"") | Y11: =+IFERROR(H11/M11,0) -> 0 | Z11: =IFERROR(+Y11/X11,0) -> 0 | AA11: =+IFERROR(U11/AH11,0) -> 0 | AB11: =+IFERROR(V11/AI11,0) -> 0 | AC11: =IFERROR(W11/AG11,0) -> 0 | AG11: =(H11+T11)+(M11/1.27) -> 0 | AH11: =(D11+R11)+(K11/1.27) -> 0 | AI11: =(F11+S11)+(L11/1.27) -> 0
B12: 43225 | C12: 0 | D12: 0 | E12: 0 | F12: 0 | G12: 0 | H12: 0 | I12: 0 | N12: =IFERROR(+M12/J12,"") | P12: =+M12/1.27 -> 0 | Q12: =H12+P12 -> 0 | R12: 0 | S12: 0 | T12: 0 | W12: =+U12+V12 -> 0 | X12: =IFERROR(C12/J12,"") | Y12: =+IFERROR(H12/M12,0) -> 0 | Z12: =IFERROR(+Y12/X12,0) -> 0 | AA12: =+IFERROR(U12/AH12,0) -> 0 | AB12: =+IFERROR(V12/AI12,0) -> 0 | AC12: =IFERROR(W12/AG12,0) -> 0 | AG12: =(H12+T12)+(M12/1.27) -> 0 | AH12: =(D12+R12)+(K12/1.27) -> 0 | AI12: =(F12+S12)+(L12/1.27) -> 0
B13: 43226 | C13: 0 | D13: 0 | E13: 0 | F13: 0 | G13: 0 | H13: 0 | I13: 0 | N13: =IFERROR(+M13/J13,"") | P13: =+M13/1.27 -> 0 | Q13: =H13+P13 -> 0 | R13: 0 | S13: 0 | T13: 0 | W13: =+U13+V13 -> 0 | X13: =IFERROR(C13/J13,"") | Y13: =+IFERROR(H13/M13,0) -> 0 | Z13: =IFERROR(+Y13/X13,0) -> 0 | AA13: =+IFERROR(U13/AH13,0) -> 0 | AB13: =+IFERROR(V13/AI13,0) -> 0 | AC13: =IFERROR(W13/AG13,0) -> 0 | AG13: =(H13+T13)+(M13/1.27) -> 0 | AH13: =(D13+R13)+(K13/1.27) -> 0 | AI13: =(F13+S13)+(L13/1.27) -> 0
B14: 43227 | N14: =IFERROR(+M14/J14,"") | P14: =+M14/1.27 -> 0 | Q14: =H14+P14 -> 0 | R14: 0 | S14: 0 | T14: 0 | W14: =+U14+V14 -> 0 | X14: =IFERROR(C14/J14,"") | Y14: =+IFERROR(H14/M14,0) -> 0 | Z14: =IFERROR(+Y14/X14,0) -> 0 | AA14: =+IFERROR(U14/AH14,0) -> 0 | AB14: =+IFERROR(V14/AI14,0) -> 0 | AC14: =IFERROR(W14/AG14,0) -> 0 | AG14: =(H14+T14)+(M14/1.27) -> 0 | AH14: =(D14+R14)+(K14/1.27) -> 0 | AI14: =(F14+S14)+(L14/1.27) -> 0
B15: 43228 | N15: =IFERROR(+M15/J15,"") | P15: 0 | Q15: 0 | R15: 0 | S15: 0 | T15: 0 | W15: =+U15+V15 -> 0 | X15: =IFERROR(C15/J15,"") | Y15: 0 | Z15: 0 | AA15: 0 | AB15: 0 | AC15: 0 | AG15: 0 | AH15: 0 | AI15: 0
B16: 43229 | N16: =IFERROR(+M16/J16,"") | P16: =+M16/1.27 -> 0 | Q16: =H16+P16 -> 0 | R16: 0 | S16: 0 | T16: =R16+S16 -> 0 | W16: =+U16+V16 -> 0 | X16: =IFERROR(C16/J16,"") | Y16: =+IFERROR(H16/M16,0) -> 0 | Z16: =IFERROR(+Y16/X16,0) -> 0 | AA16: =+IFERROR(U16/AH16,0) -> 0 | AB16: =+IFERROR(V16/AI16,0) -> 0 | AC16: =IFERROR(W16/AG16,0) -> 0 | AG16: =(H16+T16)+(M16/1.27) -> 0 | AH16: =(D16+R16)+(K16/1.27) -> 0 | AI16: =(F16+S16)+(L16/1.27) -> 0
B17: 43230 | N17: =IFERROR(+M17/J17,"") | P17: =+M17/1.27 -> 0 | Q17: =H17+P17 -> 0 | R17: 0 | S17: 0 | T17: =R17+S17 -> 0 | W17: =+U17+V17 -> 0 | X17: =IFERROR(C17/J17,"") | Y17: =+IFERROR(H17/M17,0) -> 0 | Z17: =IFERROR(+Y17/X17,0) -> 0 | AA17: =+IFERROR(U17/AH17,0) -> 0 | AB17: =+IFERROR(V17/AI17,0) -> 0 | AC17: =IFERROR(W17/AG17,0) -> 0 | AG17: =(H17+T17)+(M17/1.27) -> 0 | AH17: =(D17+R17)+(K17/1.27) -> 0 | AI17: =(F17+S17)+(L17/1.27) -> 0
B18: 43231 | N18: =IFERROR(+M18/J18,"") | P18: =+M18/1.27 -> 0 | Q18: =H18+P18 -> 0 | R18: 0 | S18: 0 | T18: =R18+S18 -> 0 | W18: =+U18+V18 -> 0 | X18: =IFERROR(C18/J18,"") | Y18: =+IFERROR(H18/M18,0) -> 0 | Z18: =IFERROR(+Y18/X18,0) -> 0 | AA18: =+IFERROR(U18/AH18,0) -> 0 | AB18: =+IFERROR(V18/AI18,0) -> 0 | AC18: =IFERROR(W18/AG18,0) -> 0 | AG18: =(H18+T18)+(M18/1.27) -> 0 | AH18: =(D18+R18)+(K18/1.27) -> 0 | AI18: =(F18+S18)+(L18/1.27) -> 0
B19: 43232 | N19: =IFERROR(+M19/J19,"") | P19: 0 | Q19: 0 | R19: 0 | S19: 0 | T19: 0 | W19: 0 | X19: =IFERROR(C19/J19,"") | Y19: 0 | Z19: 0 | AA19: 0 | AB19: 0 | AC19: 0 | AG19: 0 | AH19: 0 | AI19: 0
B20: 43233 | I20: =IFERROR(+H20/C20,"") | N20: =IFERROR(+M20/J20,"") | P20: =+M20/1.27 -> 0 | Q20: =H20+P20 -> 0 | R20: 0 | S20: 0 | T20: =R20+S20 -> 0 | W20: =+U20+V20 -> 0 | X20: =IFERROR(C20/J20,"") | Y20: =+IFERROR(H20/M20,0) -> 0 | Z20: =IFERROR(+Y20/X20,0) -> 0 | AA20: =+IFERROR(U20/AH20,0) -> 0 | AB20: =+IFERROR(V20/AI20,0) -> 0 | AC20: =IFERROR(W20/AG20,0) -> 0 | AG20: =(H20+T20)+(M20/1.27) -> 0 | AH20: =(D20+R20)+(K20/1.27) -> 0 | AI20: =(F20+S20)+(L20/1.27) -> 0
B21: 43234 | I21: =IFERROR(+H21/C21,"") | N21: =IFERROR(+M21/J21,"") | P21: =+M21/1.27 -> 0 | Q21: =H21+P21 -> 0 | R21: 0 | S21: 0 | T21: =R21+S21 -> 0 | W21: =+U21+V21 -> 0 | X21: =IFERROR(C21/J21,"") | Y21: =+IFERROR(H21/M21,0) -> 0 | Z21: =IFERROR(+Y21/X21,0) -> 0 | AA21: =+IFERROR(U21/AH21,0) -> 0 | AB21: =+IFERROR(V21/AI21,0) -> 0 | AC21: =IFERROR(W21/AG21,0) -> 0 | AG21: =(H21+T21)+(M21/1.27) -> 0 | AH21: =(D21+R21)+(K21/1.27) -> 0 | AI21: =(F21+S21)+(L21/1.27) -> 0
B22: 43235 | I22: =IFERROR(+H22/C22,"") | N22: =IFERROR(+M22/J22,"") | P22: =+M22/1.27 -> 0 | Q22: =H22+P22 -> 0 | R22: 0 | S22: 0 | T22: =R22+S22 -> 0 | W22: =+U22+V22 -> 0 | X22: =IFERROR(C22/J22,"") | Y22: =+IFERROR(H22/M22,0) -> 0 | Z22: =IFERROR(+Y22/X22,0) -> 0 | AA22: =+IFERROR(U22/AH22,0) -> 0 | AB22: =+IFERROR(V22/AI22,0) -> 0 | AC22: =IFERROR(W22/AG22,0) -> 0 | AG22: =(H22+T22)+(M22/1.27) -> 0 | AH22: =(D22+R22)+(K22/1.27) -> 0 | AI22: =(F22+S22)+(L22/1.27) -> 0
B23: 43236 | I23: =IFERROR(+H23/C23,"") | N23: =IFERROR(+M23/J23,"") | P23: =+M23/1.27 -> 0 | Q23: =H23+P23 -> 0 | R23: 0 | S23: 0 | T23: =R23+S23 -> 0 | W23: =+U23+V23 -> 0 | X23: =IFERROR(C23/J23,"") | Y23: =+IFERROR(H23/M23,0) -> 0 | Z23: =IFERROR(+Y23/X23,0) -> 0 | AA23: =+IFERROR(U23/AH23,0) -> 0 | AB23: =+IFERROR(V23/AI23,0) -> 0 | AC23: =IFERROR(W23/AG23,0) -> 0 | AG23: =(H23+T23)+(M23/1.27) -> 0 | AH23: =(D23+R23)+(K23/1.27) -> 0 | AI23: =(F23+S23)+(L23/1.27) -> 0
B24: 43237 | I24: =IFERROR(+H24/C24,"") | N24: =IFERROR(+M24/J24,"") | P24: =+M24/1.27 -> 0 | Q24: =H24+P24 -> 0 | R24: 0 | S24: 0 | T24: =R24+S24 -> 0 | W24: =+U24+V24 -> 0 | X24: =IFERROR(C24/J24,"") | Y24: =+IFERROR(H24/M24,0) -> 0 | Z24: =IFERROR(+Y24/X24,0) -> 0 | AA24: =+IFERROR(U24/AH24,0) -> 0 | AB24: =+IFERROR(V24/AI24,0) -> 0 | AC24: =IFERROR(W24/AG24,0) -> 0 | AG24: =(H24+T24)+(M24/1.27) -> 0 | AH24: =(D24+R24)+(K24/1.27) -> 0 | AI24: =(F24+S24)+(L24/1.27) -> 0
B25: 43238 | I25: =IFERROR(+H25/C25,"") | N25: =IFERROR(+M25/J25,"") | P25: =+M25/1.27 -> 0 | Q25: =H25+P25 -> 0 | R25: 0 | S25: 0 | T25: =R25+S25 -> 0 | W25: =+U25+V25 -> 0 | X25: =IFERROR(C25/J25,"") | Y25: =+IFERROR(H25/M25,0) -> 0 | Z25: =IFERROR(+Y25/X25,0) -> 0 | AA25: =+IFERROR(U25/AH25,0) -> 0 | AB25: =+IFERROR(V25/AI25,0) -> 0 | AC25: =IFERROR(W25/AG25,0) -> 0 | AG25: =(H25+T25)+(M25/1.27) -> 0 | AH25: =(D25+R25)+(K25/1.27) -> 0 | AI25: =(F25+S25)+(L25/1.27) -> 0
B26: 43239 | I26: =IFERROR(+H26/C26,"") | N26: =IFERROR(+M26/J26,"") | P26: =+M26/1.27 -> 0 | Q26: =H26+P26 -> 0 | R26: 0 | S26: 0 | T26: =R26+S26 -> 0 | W26: =+U26+V26 -> 0 | X26: =IFERROR(C26/J26,"") | Y26: =+IFERROR(H26/M26,0) -> 0 | Z26: =IFERROR(+Y26/X26,0) -> 0 | AA26: =+IFERROR(U26/AH26,0) -> 0 | AB26: =+IFERROR(V26/AI26,0) -> 0 | AC26: =IFERROR(W26/AG26,0) -> 0 | AG26: =(H26+T26)+(M26/1.27) -> 0 | AH26: =(D26+R26)+(K26/1.27) -> 0 | AI26: =(F26+S26)+(L26/1.27) -> 0
B27: 43240 | I27: =IFERROR(+H27/C27,"") | N27: =IFERROR(+M27/J27,"") | P27: =+M27/1.27 -> 0 | Q27: =H27+P27 -> 0 | R27: 0 | S27: 0 | T27: =R27+S27 -> 0 | W27: =+U27+V27 -> 0 | X27: =IFERROR(C27/J27,"") | Y27: =+IFERROR(H27/M27,0) -> 0 | Z27: =IFERROR(+Y27/X27,0) -> 0 | AA27: =+IFERROR(U27/AH27,0) -> 0 | AB27: =+IFERROR(V27/AI27,0) -> 0 | AC27: =IFERROR(W27/AG27,0) -> 0 | AG27: =(H27+T27)+(M27/1.27) -> 0 | AH27: =(D27+R27)+(K27/1.27) -> 0 | AI27: =(F27+S27)+(L27/1.27) -> 0
B28: 43241 | I28: =IFERROR(+H28/C28,"") | N28: =IFERROR(+M28/J28,"") | P28: =+M28/1.27 -> 0 | Q28: =H28+P28 -> 0 | R28: 0 | S28: 0 | T28: =R28+S28 -> 0 | W28: =+U28+V28 -> 0 | X28: =IFERROR(C28/J28,"") | Y28: =+IFERROR(H28/M28,0) -> 0 | Z28: =IFERROR(+Y28/X28,0) -> 0 | AA28: =+IFERROR(U28/AH28,0) -> 0 | AB28: =+IFERROR(V28/AI28,0) -> 0 | AC28: =IFERROR(W28/AG28,0) -> 0 | AG28: =(H28+T28)+(M28/1.27) -> 0 | AH28: =(D28+R28)+(K28/1.27) -> 0 | AI28: =(F28+S28)+(L28/1.27) -> 0
B29: 43242 | I29: =IFERROR(+H29/C29,"") | N29: =IFERROR(+M29/J29,"") | P29: =+M29/1.27 -> 0 | Q29: =H29+P29 -> 0 | R29: 0 | S29: 0 | T29: =R29+S29 -> 0 | W29: =+U29+V29 -> 0 | X29: =IFERROR(C29/J29,"") | Y29: =+IFERROR(H29/M29,0) -> 0 | Z29: =IFERROR(+Y29/X29,0) -> 0 | AA29: =+IFERROR(U29/AH29,0) -> 0 | AB29: =+IFERROR(V29/AI29,0) -> 0 | AC29: =IFERROR(W29/AG29,0) -> 0 | AG29: =(H29+T29)+(M29/1.27) -> 0 | AH29: =(D29+R29)+(K29/1.27) -> 0 | AI29: =(F29+S29)+(L29/1.27) -> 0
B30: 43243 | I30: =IFERROR(+H30/C30,"") | N30: =IFERROR(+M30/J30,"") | P30: =+M30/1.27 -> 0 | Q30: =H30+P30 -> 0 | R30: 0 | S30: 0 | T30: =R30+S30 -> 0 | W30: =+U30+V30 -> 0 | X30: =IFERROR(C30/J30,"") | Y30: =+IFERROR(H30/M30,0) -> 0 | Z30: =IFERROR(+Y30/X30,0) -> 0 | AA30: =+IFERROR(U30/AH30,0) -> 0 | AB30: =+IFERROR(V30/AI30,0) -> 0 | AC30: =IFERROR(W30/AG30,0) -> 0 | AG30: =(H30+T30)+(M30/1.27) -> 0 | AH30: =(D30+R30)+(K30/1.27) -> 0 | AI30: =(F30+S30)+(L30/1.27) -> 0
B31: 43244 | I31: =IFERROR(+H31/C31,"") | N31: =IFERROR(+M31/J31,"") | P31: =+M31/1.27 -> 0 | Q31: =H31+P31 -> 0 | R31: 0 | S31: 0 | T31: =R31+S31 -> 0 | W31: =+U31+V31 -> 0 | X31: =IFERROR(C31/J31,"") | Y31: =+IFERROR(H31/M31,0) -> 0 | Z31: =IFERROR(+Y31/X31,0) -> 0 | AA31: =+IFERROR(U31/AH31,0) -> 0 | AB31: =+IFERROR(V31/AI31,0) -> 0 | AC31: =IFERROR(W31/AG31,0) -> 0 | AG31: =(H31+T31)+(M31/1.27) -> 0 | AH31: =(D31+R31)+(K31/1.27) -> 0 | AI31: =(F31+S31)+(L31/1.27) -> 0
... B38: 43251 | I38: =IFERROR(+H38/C38,"") | N38: =IFERROR(+M38/J38,"") | P38: =+M38/1.27 -> 0 | Q38: =H38+P38 -> 0 | R38: 0 | S38: 0 | T38: =R38+S38 -> 0 | W38: =+U38+V38 -> 0 | X38: =IFERROR(C38/J38,"") | Y38: =+IFERROR(H38/M38,0) -> 0 | Z38: =IFERROR(+Y38/X38,0) -> 0 | AA38: =+IFERROR(U38/AH38,0) -> 0 | AB38: =+IFERROR(V38/AI38,0) -> 0 | AC38: =IFERROR(W38/AG38,0) -> 0 | AG38: =(H38+T38)+(M38/1.27) -> 0 | AH38: =(D38+R38)+(K38/1.27) -> 0 | AI38: =(F38+S38)+(L38/1.27) -> 0
B39: TOTAL | C39: =SUM(C8:C38) -> 0 | D39: =SUM(D8:D38) -> 0 | F39: =SUM(F8:F38) -> 0 | H39: =SUM(H8:H38) -> 0 | I39: =IFERROR(+H39/C39,"") | J39: =SUM(J8:J38) -> 0 | K39: =SUM(K8:K38) -> 0 | L39: =SUM(L8:L38) -> 0 | M39: =SUM(M8:M38) -> 0 | N39: =IFERROR(M39/J39,"") | O39: =SUM(O8:O38) -> 0 | P39: =SUM(P8:P38) -> 0 | Q39: =SUM(Q8:Q38) -> 0 | R39: =SUM(R8:R38) -> 0 | S39: =SUM(S8:S38) -> 0 | T39: =SUM(T8:T38) -> 0 | U39: =SUM(U8:U38) -> 0 | V39: =SUM(V8:V38) -> 0 | W39: =SUM(W8:W38) -> 0 | X39: =IFERROR(C39/J39,"") | Y39: =+IFERROR(H39/M39,0) -> 0 | Z39: =IFERROR(+Y39/X39,"") | AA39: =+IFERROR(U39/AH39,0) -> 0 | AB39: =+IFERROR(V39/AI39,0) -> 0 | AC39: =IFERROR(W39/AG39,0) -> 0 | AD39: =+SUM(AD8:AD38) -> 0 | AE39: =+SUM(AE8:AE38) -> 0 | AG39: =SUM(AG8:AG38) -> 0 | AH39: =SUM(AH8:AH38) -> 0 | AI39: =SUM(AI8:AI38) -> 0
C42: MTD OB | D42: =H39 -> 0 | F42: MTD OB PAGI | I42: =+D39 -> 0 | J42: RAIN | K42: =+AD39 -> 0 | M42: Note : | N42: Plan sesuai dengan rencana kerja mingguan | W42: MTD ACHIEVEMENT
C43: MTD COAL | D43: =M39 -> 0 | F43: MTD OB MALAM | I43: =+F39 -> 0 | J43: SLIPERY | K43: =+AE39 -> 0 | M43: PLAN OB | N43: =+C39 -> 0 | P43: =IFERROR(+D42/N43,0) -> 0 | W43: UNIT | X43: PLAN | Z43: ACTUAL | AD43: ACHV | AE43: VARIANCE | AG43: WORKING DAYS IN MONTH | AH43: REMAINING DAYS
C44: FR HARIAN | D44: =+AC19 -> 0 | F44: MTD BB PAGI | I44: =+K39 -> 0 | M44: PLAN BB | N44: =+J39 -> 0 | P44: =IFERROR(+D43/N44,0) -> 0 | W44: OB | X44: =SUM(C8:C20) -> 0 | Z44: =+D42 -> 0 | AD44: =+IFERROR(Z44/X44,0) -> 0 | AE44: =+IFERROR(Z44-X44,0) -> 0 | AG44: 27.5 | AH44: =AG44-11 -> 16.5
C45: FR BULANAN | D45: =+AC39 -> 0 | F45: MTD BB MALAM | I45: =+L39 -> 0 | M45: SR | N45: =+X39 | P45: =IFERROR(+Y39/N45,0) -> 0 | W45: COAL | X45: =SUM(J8:J20) -> 0 | Z45: =+D43 -> 0 | AD45: =+IFERROR(Z45/X45,0) -> 0 | AE45: =+IFERROR(Z45-X45,0) -> 0 | AG45: TARGET PER DAY TO GET TARGET
C46: SR HARIAN | D46: =+Y19 -> 0 | M46: FR | N46: 0.8 | P46: =IFERROR(+D45/N46,0) -> 0 | W46: SR | X46: =+IFERROR(X44/X45,0) -> 0 | Z46: =+IFERROR(Z44/Z45,0) -> 0 | AD46: =+IFERROR(Z46/X46,0) -> 0 | AE46: =+IFERROR(Z46-X46,0) -> 0 | AG46: OB | AH46: =IFERROR((C39-Z44)/AH44,"") -> 0
C47: SR BULANAN | D47: =+Y39 -> 0 | AG47: COAL | AH47: =IFERROR((J39-Z45)/AH44,"") -> 0

Sheet Sheet1
G20: =1274/4 -> 318.5

Sheet Sheet2
H19: =3+8 -> 11
H20: =11*24 -> 264 | I20: =36+38+33+1+1+30+2+3 -> 144
I21: =17+25+20+21+20+17+13 -> 133
H22: =144-11 -> 133 | M22: =4+7+9+8+7+8+8+5+4 -> 60
H23: =+H22*24 -> 3192
H24: =+H23+H20 -> 3456
H25: =20+15 -> 35
H26: =+H25*24 -> 840
H27: =10+21+6+6 -> 43 | J27: =10+21 -> 31
H28: =+H27*24 -> 1032 | J28: =+J27*24 -> 744
H29: =13+11 -> 24 | J29: =24+6+6 -> 36
H30: =+H29*24 -> 576 | J30: =+J29*24 -> 864
H31: =35+43+24 -> 102 | J31: =+J30+744+840 -> 2448
H32: =576+840+1032 -> 2448

Sheet Sheet4
A1: 27 | C1: 26.26 | E1: SL3 | F1: =+C1+C2+C7+C8+C13+C14+C17+C18+C24+C25+C30 -> 293.39
A2: 27 | C2: 27.58 | E2: SL4 | F2: =+C3+C4+C5+C9+C10+C11+C15+C19+C20+C21+C26+C27+C31+C32 -> 386.89
A3: 27 | C3: 27.62 | F3: =+F2+F1 -> 680.28
