Workbook

Sheet Sheet1
N4: =IF($D13="","",IF($D13>$C13,$D13-$C13,H9-$C13+$D13)/H8)
B5: 0.12152778 | C5: 0.24166667 | D5: =C5-B5 -> 0.12013889 | N5: =HOUR(D11-C11+24)+MINUTE(D11-C11+60)/60
F7: No | G7: Losstime | H7: Start | I7: Stop | J7: Time (Hour) | M7: Base Time Calculation
F8: 1 | G8: Tunggu Alat Angkut | J8: =HOUR(I8-H8+24)+MINUTE(I8-H8+60)/60 -> 0 | M8: 0.29166667
F9: =F8+1 -> 2 | G9: Tunggu Rippingan | J9: =HOUR(I9-H9+24)+MINUTE(I9-H9+60)/60 -> 0 | M9: 0.33333333
F10: =F9+1 -> 3 | G10: Traveling/ Pindah Front Loading | J10: =HOUR(I10-H10+24)+MINUTE(I10-H10+60)/60 -> 0 | M10: =IFERROR(M9-M8,0) -> 0.041666667
F11: =F10+1 -> 4 | G11: Mulai Operasi Awal Shift | J11: =HOUR(I11-H11+24)+MINUTE(I11-H11+60)/60 -> 0 | M11: 1
F12: =F11+1 -> 5 | G12: Stop Operasi menjelang istirahat | J12: =HOUR(I12-H12+24)+MINUTE(I12-H12+60)/60 -> 0
F13: =F12+1 -> 6 | G13: isi BBM Solar | J13: =HOUR(I13-H13+24)+MINUTE(I13-H13+60)/60 -> 0
F14: =F13+1 -> 7 | G14: Lubrikasi | J14: =HOUR(I14-H14+24)+MINUTE(I14-H14+60)/60 -> 0
F15: =F14+1 -> 8 | G15: Greasing | J15: =IF($D15="","",IF($D15>$C15,$D15-$C15,M11-$C15+$D15)/M10)
F16: =F15+1 -> 9 | G16: Isi Air Radiator | J16: =IF($D16="","",IF($D16>$C16,$D16-$C16,M12-$C16+$D16)/M11)
F17: =F16+1 -> 10 | G17: Mulai Operasi setelah istirahat | J17: =HOUR(I17-H17+24)+MINUTE(I17-H17+60)/60 -> 0
F18: =F17+1 -> 11 | G18: Stop Operasi Akhir Shift | J18: =HOUR(I18-H18+24)+MINUTE(I18-H18+60)/60 -> 0
F19: =F18+1 -> 12 | G19: Standby kurang alat angkut (HD) | J19: =HOUR(I19-H19+24)+MINUTE(I19-H19+60)/60 -> 0
F20: =F19+1 -> 13 | G20: Standby tidak ada operator | J20: =HOUR(I20-H20+24)+MINUTE(I20-H20+60)/60 -> 0
F21: =F20+1 -> 14 | G21: Standby tidak ada dozer | J21: =HOUR(I21-H21+24)+MINUTE(I21-H21+60)/60 -> 0
F22: =F21+1 -> 15 | G22: Tunggu penyiraman jalan | J22: =HOUR(I22-H22+24)+MINUTE(I22-H22+60)/60 -> 0
F23: =F22+1 -> 16 | G23: Distop safety | J23: =HOUR(I23-H23+24)+MINUTE(I23-H23+60)/60 -> 0
F24: =F23+1 -> 17 | G24: Pengukuran team survey | J24: =HOUR(I24-H24+24)+MINUTE(I24-H24+60)/60 -> 0
F25: =F24+1 -> 18 | G25: Tunggu Blasting | J25: =HOUR(I25-H25+24)+MINUTE(I25-H25+60)/60 -> 0
F26: =F25+1 -> 19
F27: =F26+1 -> 20 | G27: Kerusakan Unit (BD) | J27: =HOUR(I27-H27+24)+MINUTE(I27-H27+60)/60 -> 0
F28: =F27+1 -> 21 | G28: Reaksi RM | J28: =HOUR(I28-H28+24)+MINUTE(I28-H28+60)/60 -> 0
F29: =F28+1 -> 22 | G29: Maintenance | J29: =HOUR(I29-H29+24)+MINUTE(I29-H29+60)/60 -> 0
F30: =F29+1 -> 23 | J30: =HOUR(I30-H30+24)+MINUTE(I30-H30+60)/60 -> 0
F31: =F30+1 -> 24 | G31: Hujan | J31: =HOUR(I31-H31+24)+MINUTE(I31-H31+60)/60 -> 0
F32: =F31+1 -> 25 | G32: Slippery | J32: =HOUR(I32-H32+24)+MINUTE(I32-H32+60)/60 -> 0
F33: =F32+1 -> 26 | G33: Perawatan Jalan | J33: =HOUR(I33-H33+24)+MINUTE(I33-H33+60)/60 -> 0
F34: =F33+1 -> 27 | G34: Perbaikan Front Loading | J34: =HOUR(I34-H34+24)+MINUTE(I34-H34+60)/60 -> 0
F35: =F34+1 -> 28 | G35: Perawatan Disposal | J35: =HOUR(I35-H35+24)+MINUTE(I35-H35+60)/60 -> 0
G37: Total | J37: =SUM(J8:J36) -> 0

Sheet Sheet3
A1: MONITORING HARIAN PRODUKSI
A2: TANGGAL 15 mei 2023 | V2: SMJ(B)-S-MA-PR-V-02
A3: PIT 55 GAR
B4: EXCAVATOR | C4: OB | I4: Jam Effective | J4: HM engine | K4: KEBUTUHAN HD | M4: PRODUCTIVITY/JAM | Q4: Produksi yang harus di capai sesuai jam effective | R4: DEVIASI | S4: JARAK | T4: RIT HD/JAM | V4: REMARK
C5: PLAN | D5: ACTUAL | E5: MATERIAL SEAM | F5: DEVIASI | G5: PLAN JAM | H5: jam Available | K5: PLAN | L5: ACTUAL | M5: PLAN | N5: dari jam available | O5: Dari Jam effective | P5: Dari HM | S5: KM | U5: rit/hd
A6: SIANG | B6: PC 1250 - 05 | C6: 4000 | D6: =[1]Fleet!$G$10 -> 990 | E6: SL-5 Utara | F6: =C6-D6 -> 3010 | G6: 10 | H6: 4 | I6: 3.39 | J6: =[1]Fleet!$F$10 -> 4 | K6: 5 | L6: 4 | M6: =C6/10 -> 400 | N6: =+D6/H6 -> 247.5 | O6: =+IFERROR(D6/I6,0) -> 292.0354 | P6: =+IFERROR(D6/J6,0) -> 247.5 | Q6: =+M6*I6 -> 1356 | R6: =+Q6-D6 -> 366 | S6: 1.8 | T6: =+IFERROR(D6/J6/22,0) -> 11.25 | U6: =+IFERROR(P6/L6/22,0) -> 2.8125 | V6: star loading awal shift jam 15:01, standby No. hd jam 08:00 - 15:01 = 6 jam 1 menit, stop loading akhir shift jam 18:40 = 20 menit, total loss time tidak normal = 6 jam 21 menit
B7: lasarus rampa | F7: =C7-D7 -> 0
A8: SIANG | B8: PC 1250 - 09 | F8: =C8-D8 -> 0 | M8: =C8/10 -> 0 | N8: =+D8/H8 -> #DIV/0! | O8: =+IFERROR(D8/I8,0) -> 0 | P8: =+IFERROR(D8/J8,0) -> 0 | Q8: =+M8*I8 -> 0 | R8: =+Q8-D8 -> 0 | T8: =+IFERROR(D8/J8/22,0) -> 0 | U8: =+IFERROR(P8/L8/22,0) -> 0
A10: SIANG | B10: PC 1250 - 02 | C10: 4000 | D10: =[1]Fleet!$G$9 -> 1078 | E10: SL-5 Utara | F10: =C10-D10 -> 2922 | G10: 10 | H10: 5 | I10: 4.48 | J10: =[1]Fleet!$F$9 -> 6 | K10: 5 | L10: 4 | M10: =C10/10 -> 400 | N10: =+D10/H10 -> 215.6 | O10: =+IFERROR(D10/I10,0) -> 240.625 | P10: =+IFERROR(D10/J10,0) -> 179.66667 | Q10: =+M10*I10 -> 1792 | R10: =+Q10-D10 -> 714 | S10: 1.8 | T10: =+IFERROR(D10/J10/22,0) -> 8.1666667 | U10: =+IFERROR(P10/L10/22,0) -> 2.0416667 | V10: star loading awal shift jam 08:37, general perbaikan jalan jam 08:00 - 08:30 = 30 menit, perbaikan front jam 08:30 - 08:37 = 7 menit, isi fuel jam 09:55 - 10:05 = 10 menit, stop loading menjelang istirahat jam 11:50 = 10 menit, star loading setelah istirahat jam 13:08, perbaikan front jam 13:00 - 13:08 = 8 menit, stop loadinng karena breakdown jam 14:53 - 19:00 = 4 jam 7 menit, total loss time tidak normal = 5 jam 12 menit
B11: lasarus rampa | F11: =C11-D11 -> 0
A12: SIANG | B12: EC 750 - 02 | C12: 3500 | D12: =[1]Fleet!$G$17 -> 1804 | E12: SM-1 Utara | F12: =C12-D12 -> 1696 | G12: 10 | H12: 8 | I12: 7.53 | J12: =[1]Fleet!$F$17 -> 8 | K12: 5 | L12: 4 | M12: =C12/10 -> 350 | N12: =+D12/H12 -> 225.5 | O12: =+IFERROR(D12/I12,0) -> 239.57503 | P12: =+IFERROR(D12/J12,0) -> 225.5 | Q12: =+M12*I12 -> 2635.5 | R12: =+Q12-D12 -> 831.5 | S12: 1.8 | T12: =+IFERROR(D12/J12/22,0) -> 10.25 | U12: =+IFERROR(P12/L12/22,0) -> 2.5625 | V12: star loading awal shift jam 08:47, perbaikan jalan jam 08:00 - 08:47 = 47 menit, 08:47 - 09:36 = 49 menit, stop loading menjelang istirahat jam 11:50 = 10 menit, star loading setelah istirahat jam 13:11, perbaikan front jam 13:00 - 13:11 = 11 menit, stop loading akhir shift jam 18:50 = 10 menit, total loss time tidak normal = 2 jam 7 menit
A14: Total Shift SIANG | C14: =SUM(C6:C13) -> 11500 | D14: =SUM(D6:D12) -> 3872 | E14: =SUM(E6:E13) -> 0 | F14: =SUM(F6:F13) -> 7628 | G14: =SUM(G6:G13) -> 30 | K14: =SUM(K6:K13) -> 15 | M14: =+C14/G14 -> 383.33333 | N14: =+D14/H14 -> #DIV/0! | O14: =+D14/I14 -> #DIV/0! | P14: =+IFERROR(D14/J14,0) -> 0 | Q14: =SUM(Q6:Q13) -> 5783.5 | R14: =SUM(R6:R13) -> 1911.5
A15: MALAM | B15: PC 1250-09 | C15: 4000 | F15: =+D15-C15 -> -4000 | G15: 10 | K15: 5 | M15: =C15/10 -> 400 | N15: =+D15/H15 -> #DIV/0! | O15: =+IFERROR(D15/I15,0) -> 0 | P15: =+IFERROR(D15/J15,0) -> 0 | Q15: =+M15*I15 -> 0 | R15: =+Q15-D15 -> 0 | T15: =+IFERROR(D15/J15/22,0) -> 0 | U15: =+IFERROR(P15/L15/22,0) -> 0 | X15: =50+12 -> 62
A17: MALAM | B17: PC 1250-02 | C17: 4000 | D17: =[1]Fleet!$G$27 -> 154 | E17: SL-5 Utara | F17: =C17-D17 -> 3846 | G17: 10 | H17: 1 | I17: 0.44 | J17: =[1]Fleet!$F$27 -> 1 | K17: 5 | L17: 4 | M17: =C17/10 -> 400 | N17: =+D17/H17 -> 154 | O17: =+IFERROR(D17/I17,0) -> 350 | P17: =+IFERROR(D17/J17,0) -> 154 | Q17: =+M17*I17 -> 176 | R17: =+Q17-D17 -> 22 | S17: 1.8 | T17: =+IFERROR(D17/J17/22,0) -> 7 | U17: =+IFERROR(P17/L17/22,0) -> 1.75 | V17: star loading awal shift jam 02:30, standby No. hd jam 20:00 - 02:30 = 5 jam 30 menit, stop loading karena hujan jam 03:19 - 04:45 = 1 jam 26 menit, slippery jam 04:50 - 07:00 = 2 jam 10 menit, total loss time tidak normal = 9 jam 16 menit
B18: yohanis | O18: =+IFERROR(D18/I18,0) -> 0
A19: MALAM | B19: PC 1250-05 | C19: 4000 | D19: =[1]Fleet!$G$29 -> 880 | E19: SM-1 Utara | F19: =C19-D19 -> 3120 | G19: 10 | H19: 4 | I19: 3.25 | J19: =[1]Fleet!$F$29 -> 4 | K19: 5 | L19: 4 | M19: =C19/10 -> 400 | N19: =+D19/H19 -> 220 | O19: =+IFERROR(D19/I19,0) -> 270.76923 | P19: =+IFERROR(D19/J19,0) -> 220 | Q19: =+M19*I19 -> 1300 | R19: =+Q19-D19 -> 420 | S19: 2.1 | T19: =+IFERROR(D19/J19/22,0) -> 10 | U19: =+IFERROR(P19/L19/22,0) -> 2.5 | V19: star loading awal shift jam 20:05, perbaikan front jam 20:00 - 20:05 = 5 menit, hujan jam 21:08 - 21:23 = 15 menit, stop loading menjelang istirahat jam 23:45 = 15 menit, standby menunggu fuel jam 01:00 - 02:30 = 1 jam 30 menit, kemudian digantikan dengan PC.1250-02, karena PC 1250-05 tidak ada fuel jam 02:30 - 07:00 = 4 jam 30 menit, total loss time tidak normal = 6 jam 35 menit
B20: yohanis | O20: =+IFERROR(D20/I20,0) -> 0
A21: MALAM | B21: EC 750 - 02 | C21: 3500 | D21: =[1]Fleet!$G$35 -> 836 | E21: SM-1 Utara | F21: =C21-D21 -> 2664 | G21: 10 | H21: 3 | I21: 2.21 | J21: =[1]Fleet!$F$35 -> 5 | K21: 4 | L21: 4 | M21: =C21/10 -> 350 | N21: =+D21/H21 -> 278.66667 | O21: =+IFERROR(D21/I21,0) -> 378.28054 | P21: =+IFERROR(D21/J21,0) -> 167.2 | Q21: =+M21*I21 -> 773.5 | R21: =+Q21-D21 -> -62.5 | S21: 2.1 | T21: =+IFERROR(D21/J21/22,0) -> 7.6 | U21: =+IFERROR(P21/L21/22,0) -> 1.9 | V21: star loading awal shift jam 19:39, greassing jam 19:58 - 20:08 = 8 menit, hujan jam 21:08 - 21:23 = 15 menit, stop loading karena fuel habis jam 23:30 = 30 menit, tunggu fuel jam 01:00 - 02:30 = 1 jam 30 menit, isi fuel jam 02:30 - 02:45 = 15 menit, general front baru jam 02:50 - 03:15 = 25 menit, hujan jam 03:19 - 04:50 = 1 jam 31 menit, slippery jam 04:55 - 07:00 = 2 jam 5 menit, total loss time tidak normal = 7 jam 39 menit
A24: Total Shift MALAM | C24: =SUM(C15:C22) -> 15500 | D24: =SUM(D19+D21+D17) -> 1870 | E24: =SUM(E15:E22) -> 0 | F24: =SUM(F15:F22) -> 5630 | G24: =SUM(G15:G22) -> 40 | H24: =SUM(H15:H22) -> 8 | I24: =SUM(I15:I22) -> 5.9 | J24: =SUM(J15:J22) -> 10 | K24: 5 | L24: =SUM(L15:L22) -> 12 | M24: =C24/G24 -> 387.5 | N24: =+D24/H24 -> 233.75 | O24: =+D24/I24 -> 316.94915 | P24: =+D24/J24 -> 187 | Q24: =SUM(Q15:Q22) -> 2249.5 | R24: =SUM(R15:R22) -> 379.5
B25: Prepare By | K25: Approve By
B34: Winarno | K34: Winarno
B35: KTT | K35: Project Manager

Sheet fleet
A1: PT. SUMBER MITRA JAYA | T1: Lampiran
A2: FLEET PERFORMANCE
A5: PAGI
A6: TGL | B6: EXCAVATOR | C6: NAMA OPERATOR | D6: HM AWAL | E6: HM AKHIR | F6: TOTAL HM | G6: PRODUKSI | H6: LOKASI KERJA | J6: PRODUKTIVITAS | M6: JARAK (KM) | N6: JML DT | O6: SUPPORT | P6: Aktivitas | Q6: HM Awal | R6: HM Akhir | S6: TOTAL HM | T6: KETERANGAN
H7: PIT | I7: SEAM/ BLOK | J7: PLAN | K7: ACTUAL | L7: % | O7: DOZER
A8: 45604 | B8: PC.1250-01 | F8: =E8-D8 -> 0 | H8: Pit GAR 50 | J8: 400
A9: =$A$8 -> 45604 | B9: PC.1250-02 | F9: =E9-D9 -> 0 | H9: Pit GAR 55 | J9: 400 | K9: 297 | L9: 0.7425 | T9: breakdown
A10: =$A$8 -> 45604 | B10: CAT.395-02 | F10: =E10-D10 -> 0 | H10: Pit GAR 55 | J10: 400 | K10: 264 | L10: 0.66 | T10: No. hd
A11: =$A$8 -> 45604 | B11: PC.1250-06 | C11: IGNASIUS | D11: 41200 | E11: 41210 | F11: =E11-D11 -> 10 | G11: =+(44+46+44+35+1)*22 -> 3740 | H11: Pit GAR 50 | J11: 400 | N11: 3 | S11: 0
A12: =$A$8 -> 45604 | B12: PC.1250-07 | F12: =E12-D12 -> 0 | H12: Pit GAR 50 | J12: 400 | K12: 176 | L12: 0.44 | S12: 0 | T12: breakdown
A13: =$A$8 -> 45604 | B13: PC.1250-05 | F13: =E13-D13 -> 0 | H13: Pit GAR 55 | J13: 400
A14: =$A$8 -> 45604 | B14: PC.1250-08 | F14: =E14-D14 -> 0 | H14: Pit GAR 50 | J14: 400 | S14: 0 | T14: stanby No. hd
A15: =$A$8 -> 45604 | B15: PC.1250-10 | F15: =E15-D15 -> 0 | H15: Pit GAR 55 | J15: 400 | K15: 154 | L15: 0.385 | T15: breakdown | Z15: 0 | AA15: #DIV/0!
A16: =$A$8 -> 45604 | B16: PC.1250-09 | C16: AMRAN PURBA | D16: 29827 | E16: 29837 | F16: =E16-D16 -> 10 | G16: =+(38+37+31+36+29)*22 -> 3762 | H16: Pit GAR 55 | J16: 400 | N16: 3
A17: =$A$8 -> 45604 | B17: EC.750-01 | C17: GRADUS NGGERE | D17: 12686 | E17: 12696 | F17: =E17-D17 -> 10 | G17: =+(38+36+26+33+12)*22 -> 3190 | H17: Pit GAR 50 | J17: 350 | K17: 166.5 | L17: 0.47571429 | N17: 3 | S17: 0 | T17: breakdown | Z17: 0 | AA17: #DIV/0!
A18: =$A$8 -> 45604 | B18: EC.750-02 | F18: =E18-D18 -> 0 | H18: Pit GAR 55 | J18: 350 | K18: 265.12821 | L18: 0.75750916 | Z18: 0 | AA18: #DIV/0!
A19: =$A$8 -> 45604 | B19: CAT.395-01 | C19: MARTHEN P | D19: 5156 | E19: 5166 | F19: =E19-D19 -> 10 | G19: =+(43+11+42+34+28+26)*22 -> 4048 | H19: Pit GAR 55 | J19: 350 | T19: breakdown | Z19: 0 | AA19: #DIV/0!
A20: =$A$8 -> 45604 | B20: CAT.330-03 | F20: =E20-D20 -> 0 | H20: Pit GAR 55 | J20: 350 | Z20: 0 | AA20: #DIV/0!
A21: =$A$8 -> 45604 | B21: PC.1250-11 | C21: LEONARDUS | D21: 15062 | E21: 15072 | F21: =E21-D21 -> 10 | G21: =+(61+64+53+54+1+6)*22 -> 5258 | H21: Pit GAR 50 | J21: 500 | S21: 0 | Z21: 0 | AA21: #DIV/0!
B22: TOTAL | F22: =SUM(F8:F21) -> 50 | G22: =SUM(G8:G21) -> 19998 | S22: 0 | Z22: 0 | AA22: #DIV/0!
N23: 1.4
A24: MALAM
A25: TGL | B25: EXCAVATOR | C25: NAMA OPERATOR | D25: HM AWAL | E25: HM AKHIR | F25: TOTAL HM | G25: PRODUKSI | H25: LOKASI KERJA | J25: PRODUKTIVITAS | M25: JARAK (KM) | N25: JML DT | O25: SUPPORT | P25: Aktivitas | Q25: HM AWAL | R25: HM AKHIR | S25: TOTAL HM | T25: KETERANGAN
H26: PIT | I26: SEAM/ BLOK | J26: PLAN | K26: ACTUAL | L26: % | O26: DOZER
A27: =$A$8 -> 45604 | B27: PC.1250-01 | F27: =E27-D27 -> 0 | H27: Pit GAR 50 | J27: 500 | M27: 1.08 | N27: 5 | T27: breakdown
A28: =$A$8 -> 45604 | B28: PC.1250-02 | F28: =E28-D28 -> 0 | H28: Pit GAR 55 | J28: 400 | K28: 280 | L28: 0.7 | M28: 1.05 | N28: 5 | T28: breakdown
A29: =$A$8 -> 45604 | B29: PC.1250-05 | F29: =E29-D29 -> 0 | H29: Pit GAR 55 | J29: 400 | M29: 1.05 | N29: 5 | T29: breakdown
A30: =$A$8 -> 45604 | B30: PC.1250-10 | F30: =E30-D30 -> 0 | H30: Pit GAR 55 | J30: 400 | M30: 2.02 | N30: 4 | T30: breakdown
A31: =$A$8 -> 45604 | B31: PC.1250-06 | C31: EVENSIUS | D31: 41210 | E31: 41220 | F31: =E31-D31 -> 10 | G31: =+(13+51+51+30)*22 -> 3190 | H31: Pit GAR 50 | J31: 385 | N31: 3
A32: =$A$8 -> 45604 | B32: PC.1250-07 | F32: =E32-D32 -> 0 | H32: Pit GAR 50 | J32: 350 | K32: 292.6 | L32: 0.836 | M32: 2.2 | N32: 4 | T32: No. hd
A33: =$A$8 -> 45604 | B33: CAT.395-01 | C33: OBETH | D33: 6166 | E33: 6176 | F33: =E33-D33 -> 10 | G33: =+(76+74+71+52)*22 -> 6006 | H33: Pit GAR 55 | J33: 385 | M33: 1.49 | N33: 4.5
A34: =$A$8 -> 45604 | B34: PC.1250-08 | F34: =E34-D34 -> 0 | H34: Pit GAR 50 | J34: 385 | T34: breakdown
A35: =$A$8 -> 45604 | B35: PC.1250-09 | C35: M ARDAN | D35: 29838 | E35: 29848 | F35: =E35-D35 -> 10 | G35: =+(44+44+30+43+23)*22 -> 4048 | H35: Pit GAR 50 | J35: 385 | T35: breakdown
A36: =$A$8 -> 45604 | B36: PC.1250-10 | F36: =E36-D36 -> 0 | H36: Pit GAR 50 | J36: 385 | K36: 234.66667 | L36: 0.60952381 | T36: breakdown
A37: =$A$8 -> 45604 | B37: CAT.395-02 | F37: =E37-D37 -> 0 | H37: Pit GAR 55 | J37: 400 | K37: 259.6 | L37: 0.649 | T37: breakdown | Z37: 110 | AA37: 2 | AB37: 55
A38: =$A$8 -> 45604 | B38: EC.750-02 | F38: =E38-D38 -> 0 | H38: Pit GAR 55 | J38: 350 | K38: 17.701149 | L38: 0.050574713 | M38: 1.4 | N38: 3 | S38: 0 | Z38: 132 | AA38: 2.5 | AB38: 52.8
A39: =$A$8 -> 45604 | B39: EC.750-01 | C39: KARMAN | D39: 12696 | E39: 12705 | F39: =E39-D39 -> 9 | G39: =+(50+48+50+10)*22 -> 3476 | H39: Pit GAR 50 | J39: 350 | K39: 194.6 | L39: 0.556 | M39: 2.2 | N39: 4 | T39: breakdown | Z39: 132 | AA39: 2.5 | AB39: 52.8
A40: =$A$8 -> 45604 | B40: PC.1250-11 | C40: ARKADIUS | D40: 15072 | E40: 15082 | F40: =E40-D40 -> 10 | G40: =+(40+45+46+43+20)*22 -> 4268 | H40: Pit GAR 50 | J40: 500 | M40: 1.2 | N40: 4 | S40: 0 | Z40: 154 | AA40: 3 | AB40: 51.333333
B41: TOTAL | F41: =SUM(F27:F40) -> 49 | G41: =SUM(G27:G40) -> 20988 | S41: 0 | Z41: 0 | AA41: #DIV/0!
A43: BATUBARA
...

Sheet 12
A1: MONITORING HARIAN PRODUKSI
A2: TANGGAL 12 AGUSTUS 2024 | Z2: SMJ(B)-S-MA-PR-V-02
A3: PIT 50 GAR
A4: SHIFT | B4: EXCAVATOR | C4: OB | J4: Jam Effective | K4: HM engine | L4: KEBUTUHAN HD | N4: PRODUCTIVITY/JAM | R4: Produksi yang harus di capai sesuai jam effective | S4: DEV BY EWH | T4: Produksi yang harus di capai sesuai HM | U4: DEV BY HM | V4: JARAK | W4: % | X4: RIT HD/JAM | Z4: REMARK
C5: PLAN | D5: ACTUAL | E5: % | F5: MATERIAL SEAM | G5: DEVIASI | H5: PLAN JAM | I5: jam Available | L5: PLAN | M5: ACTUAL | N5: PLAN | O5: dari jam available | P5: Dari Jam effective | Q5: Dari HM | V5: KM | Y5: rit/hd
A6: SIANG | B6: PC.1250-01 | D6: =fleet!G8 -> 0 | E6: =D6/C6 -> #DIV/0! | F6: Seam ST-1 | G6: =C6-D6 -> 0 | H6: 10 | K6: =fleet!F8 -> 0 | N6: 500 | O6: =+D6/I6 -> #DIV/0! | P6: =+IFERROR(D6/J6,0) -> 0 | Q6: =+IFERROR(D6/K6,0) -> 0 | R6: =+N6*J6 -> 0 | S6: =+R6-D6 -> 0 | T6: =+N6*K6 -> 0 | U6: =T6-D6 -> 0 | W6: =D6/C6 -> #DIV/0! | X6: =+IFERROR(D6/K6/22,0) -> 0 | Y6: =+IFERROR(P6/M6/22,0) -> 0 | Z6: b/d
B7: =fleet!C8 -> 0
A8: SIANG | B8: PC 1250 06 | C8: 5000 | D8: =fleet!G11 -> 3740 | E8: =D8/C8 -> 0.748 | F8: Seam G-6 | G8: =C8-D8 -> 1260 | H8: 10 | I8: 10 | J8: =9+(23/60) -> 9.3833333 | K8: =fleet!F11 -> 10 | L8: 4 | M8: 4 | N8: 500 | O8: =+D8/I8 -> 374 | P8: =+IFERROR(D8/J8,0) -> 398.57904 | Q8: =+IFERROR(D8/K8,0) -> 374 | R8: =+N8*J8 -> 4691.6667 | S8: =+R8-D8 -> 951.66667 | T8: =+N8*K8 -> 5000 | U8: =T8-D8 -> 1260 | V8: 1.02 | W8: =D8/C8 -> 0.748 | X8: =+IFERROR(D8/K8/22,0) -> 17 | Y8: =+IFERROR(P8/M8/22,0) -> 4.5293073 | Z8: lubrikasi jam 07:40 - 08:05 = 5 menit, isi fuel jam 08:05 - 08:15 = 10 menit, star laoding awal shift jam 08:15, stop loading menjelang istirahat jam 11:54 = 6 menit, star loading setelah istirahat jam 13:01 = 1 menit, stop loading akhir shift jam 18:50 = 10 menit, total loss time tidak normal = 37 menit
B9: =fleet!C11 -> IGNASIUS
A10: SIANG | B10: PC 1250 08 | D10: =fleet!G14 -> 0 | E10: =D10/C10 -> #DIV/0! | F10: Seam ST-1 | G10: =C10-D10 -> 0 | H10: 10 | K10: =fleet!F14 -> 0 | N10: 500 | O10: =+D10/I10 -> #DIV/0! | P10: =+IFERROR(D10/J10,0) -> 0 | Q10: =+IFERROR(D10/K10,0) -> 0 | R10: =+N10*J10 -> 0 | S10: =+R10-D10 -> 0 | T10: =+N10*K10 -> 0 | U10: =T10-D10 -> 0 | W10: =D10/C10 -> #DIV/0! | X10: =+IFERROR(D10/K10/16,0) -> 0 | Y10: =+IFERROR(P10/M10/22,0) -> 0 | Z10: b/d
B11: =fleet!C14 -> 0
A12: SIANG | B12: CAT.395-01 | C12: 5000 | D12: =fleet!G19 -> 4048 | E12: =D12/C12 -> 0.8096 | F12: Seam G-6 | G12: =C12-D12 -> 952 | H12: 10 | I12: 10 | J12: =9+(36/60) -> 9.6 | K12: =fleet!F19 -> 10 | L12: 4 | M12: 5 | N12: 500 | O12: =+D12/I12 -> 404.8 | P12: =+IFERROR(D12/J12,0) -> 421.66667 | Q12: =+IFERROR(D12/K12,0) -> 404.8 | R12: =+N12*J12 -> 4800 | S12: =+R12-D12 -> 752 | T12: =+N12*K12 -> 5000 | U12: =T12-D12 -> 952 | V12: 1.02 | W12: =D12/C12 -> 0.8096 | X12: =+IFERROR(D12/K12/22,0) -> 18.4 | Y12: =+IFERROR(P12/M12/22,0) -> 3.8333333 | Z12: star loading awal shift jam 07:56, isi fuel jam 10:15 - 10:22 = 7 menit, stop loading menjelang istirahat jam 11:56 = 4 menit, star loading setelah istirahat jam 13:03 = 3 menit, stop loading akhir shift jam 18:50 = 10 menit, total loss time tidak normal = 24 menit
B13: =fleet!C19 -> MARTHEN P
A14: SIANG | B14: PC 1250 09 | C14: 5000 | D14: =fleet!G16 -> 3762 | E14: =D14/C14 -> 0.7524 | F14: Seam X-5 | G14: =C14-D14 -> 1238 | H14: 10 | I14: 10 | J14: =8+(58/60) -> 8.9666667 | K14: =fleet!F16 -> 10 | L14: 5 | M14: 5 | N14: 500 | O14: =+D14/I14 -> 376.2 | P14: =+IFERROR(D14/J14,0) -> 419.5539 | Q14: =+IFERROR(D14/K14,0) -> 376.2 | R14: =+N14*J14 -> 4483.3333 | S14: =+R14-D14 -> 721.33333 | T14: =+N14*K14 -> 5000 | U14: =T14-D14 -> 1238 | V14: 1.34 | W14: =D14/C14 -> 0.7524 | X14: =+IFERROR(D14/K14/22,0) -> 17.1 | Y14: =+IFERROR(P14/M14/22,0) -> 3.8141264 | Z14: evakuasi unit hd 48 yang rebah jam 08:00 - 08:20 = 20 menit, lubrikasi jam 08:25 - 08:35 = 10 menit, greassing jam 08:35 - 08:40 = 5 menit, isi air radiator jam 08:40 - 08:45 = 5 menit, perbaikan front jam 08:40 - 08:55 = 15 menit, star laoding awal shift jam 08:55, stop loading menjelang istirahat jam 11:56 = 4 menit, star laoding setelah istirahat jam 13:00, stop loading akhir shift jam 18:57 = 3 menit, total loss time tidak normal = 1 jam 2 menit
B15: =fleet!C16 -> AMRAN PURBA | N15: =C15/10 -> 0 | P15: =+IFERROR(D15/J15,0) -> 0 | Q15: =+IFERROR(D15/K15,0) -> 0 | R15: =+N15*J15 -> 0 | S15: =+R15-D15 -> 0
A16: SIANG | B16: PC 1250 11 | C16: =H16*N16 -> 5000 | D16: =fleet!G21 -> 5258 | E16: =D16/C16 -> 1.0516 | F16: Seam ST-1 | G16: =C16-D16 -> -258 | H16: 10 | I16: 10 | J16: =9+(46/60) -> 9.7666667 | K16: =fleet!F21 -> 10 | L16: 4 | M16: 4 | N16: 500 | O16: =+D16/I16 -> 525.8 | P16: =+IFERROR(D16/J16,0) -> 538.36177 | Q16: =+IFERROR(D16/K16,0) -> 525.8 | R16: =+N16*J16 -> 4883.3333 | S16: =+R16-D16 -> -374.66667 | T16: =+N16*K16 -> 5000 | U16: =T16-D16 -> -258 | V16: 1.02 | W16: =D16/C16 -> 1.0516 | X16: =+IFERROR(D16/K16/22,0) -> 23.9 | Y16: =+IFERROR(P16/M16/22,0) -> 6.1177474 | Z16: star loading awal shift jam 07:54, stop loading menjelang istirahat jam 11:58 = 2 menit, star loading setelah istirahat jam 13:04, perbaikan front jam 13:00 - 13:04 = 4 menit, stop loading akhir shift jam 18:52 = 8 menit, total loss time tidak normal = 14 menit
B17: =fleet!C21 -> LEONARDUS
A18: SIANG | B18: EC 750 01 | C18: 3500 | D18: =fleet!G17 -> 3190 | E18: =D18/C18 -> 0.91142857 | F18: Seam ST-1 | G18: =C18-D18 -> 310 | H18: 10 | I18: 10 | J18: =7+(26/60) -> 7.4333333 | K18: =fleet!F17 -> 10 | M18: 4 | N18: 350 | O18: =+D18/I18 -> 319 | P18: =+IFERROR(D18/J18,0) -> 429.14798 | Q18: =+IFERROR(D18/K18,0) -> 319 | R18: =+N18*J18 -> 2601.6667 | S18: =+R18-D18 -> -588.33333 | T18: =+N18*K18 -> 3500 | U18: =T18-D18 -> 310 | V18: 1.02 | W18: =D18/C18 -> 0.91142857 | X18: =+IFERROR(D18/K18/22,0) -> 14.5 | Y18: =+IFERROR(P18/M18/22,0) -> 4.8766816 | Z18: travel dari selatan bawah ke selatan ujung jam 08:00 - 09:04 = 1 jam 4 menit, star loading awal shift jam 09:04, stop loading menjelang istirahat jam 11:56 = 4 menit, perbaikan fronr jam 13:00 - 13:06 = 6 menit, star loading setelah istirahat jam 13:06, stop loading evakuasi hd amblas jam 17:50 - 19:00 = 1 jam 10 menit, total loss time tidak normal = 2 jam 34 menit
B19: =fleet!C17 -> GRADUS NGGERE
A20: Total Shift SIANG | C20: =+(C6+C8+C10+C12+C14+C16+C18) -> 23500 | D20: =SUM(D6:D18) -> 19998 | E20: =D20/C20 -> 0.85097872 | F20: =SUM(F6:F12) -> 0 | G20: 13196 | H20: =SUM(H6:H17) -> 60 | I20: =SUM(I6:I17) -> 40 | J20: =SUM(J6:J18) -> 45.15 | K20: =SUM(K6:K17) -> 40 | L20: =SUM(L6:L17) -> 17 | M20: =SUM(M6:M17) -> 18 | N20: =C20/H20 -> 391.66667 | O20: =+D20/I20 -> 499.95 | P20: =D20/J20 -> 442.92359 | Q20: =D20/K20 -> 499.95 | R20: =SUM(R6:R17) -> 18858.333 | S20: =SUM(S6:S17) -> 2050.3333
A21: MALAM | B21: PC 1250 01 | D21: =fleet!G27 -> 0 | E21: =D21/C21 -> #DIV/0! | F21: Seam G-6 | G21: =C21-D21 -> 0 | H21: 10 | I21: 10 | K21: =fleet!F27 -> 0 | L21: 5 | N21: 500 | O21: =+D21/I21 -> 0 | P21: =+IFERROR(D21/J21,0) -> 0 | Q21: =+IFERROR(D21/K21,0) -> 0 | R21: =+N21*J21 -> 0 | S21: =+R21-D21 -> 0 | T21: =+N21*K21 -> 0 | U21: =T21-D21 -> 0 | V21: 1.02 | W21: =D21/C21 -> #DIV/0! | X21: =+IFERROR(D21/K21/22,0) -> 0 | Y21: =+IFERROR(P21/M21/22,0) -> 0 | Z21: b/d
B22: =fleet!C27 -> 0
A23: MALAM | B23: PC 1250 06 | C23: 5000 | D23: =fleet!G31 -> 3190 | E23: =D23/C23 -> 0.638 | F23: Seam ST-1 | G23: =C23-D23 -> 1810 | H23: 10 | I23: 10 | J23: =9+(20/60) -> 9.3333333 | K23: =fleet!F31 -> 10 | L23: 3 | M23: 4 | N23: 500 | O23: =+D23/I23 -> 319 | P23: =+IFERROR(D23/J23,0) -> 341.78571 | Q23: =+IFERROR(D23/K23,0) -> 319 | R23: =+N23*J23 -> 4666.6667 | S23: =+R23-D23 -> 1476.6667 | T23: =+N23*K23 -> 5000 | U23: =T23-D23 -> 1810 | V23: 1.02 | W23: =D23/C23 -> 0.638 | X23: =+IFERROR(D23/K23/22,0) -> 14.5 | Y23: =+IFERROR(P23/M23/22,0) -> 3.8839286 | Z23: greassing jam 19:45 - 20:06 = 6 menit star laoding awal shift jam 20:06, pindah front jam 21:30 - 21:41 = 11 menit, stop loading menjelang istirahat jam 23:50 = 10 menit, star loading setelah istirahat jam 01:08, perbaikan front jam 01:00 - 01:08 = 8 menit, stop loading akhir shift jam 06:55 = 5 menit, total loss time tidak normal = 40 menit
B24: =fleet!C31 -> EVENSIUS
A25: MALAM | B25: PC 1250-08 | D25: =fleet!G34 -> 0 | E25: =D25/C25 -> #DIV/0! | F25: Seam ST-1 | G25: =C25-D25 -> 0 | H25: 10 | K25: =fleet!F34 -> 0 | L25: 3 | N25: 500 | O25: =+D25/I25 -> #DIV/0! | P25: =+IFERROR(D25/J25,0) -> 0 | Q25: =+IFERROR(D25/K25,0) -> 0 | R25: =+N25*J25 -> 0 | S25: =+R25-D25 -> 0 | T25: =+N25*K25 -> 0 | U25: =T25-D25 -> 0 | W25: =D25/C25 -> #DIV/0! | X25: =+IFERROR(D25/K25/22,0) -> 0 | Y25: =+IFERROR(P25/M25/22,0) -> 0 | Z25: b/d
B26: =fleet!C34 -> 0
A28: MALAM | B28: PC 1250-09 | C28: 5000 | D28: =fleet!G35 -> 4048 | E28: =D28/C28 -> 0.8096 | F28: Seam ST-1 | G28: =C28-D28 -> 952 | H28: 10 | I28: 10 | J28: =9+(32/60) -> 9.5333333 | K28: =fleet!F35 -> 10 | L28: 4 | M28: 5 | N28: 500 | O28: =+D28/I28 -> 404.8 | P28: =+IFERROR(D28/J28,0) -> 424.61538 | Q28: =+IFERROR(D28/K28,0) -> 404.8 | R28: =+N28*J28 -> 4766.6667 | S28: =+R28-D28 -> 718.66667 | T28: =+N28*K28 -> 5000 | U28: =T28-D28 -> 952 | V28: 1.34 | W28: =D28/C28 -> 0.8096 | X28: =+IFERROR(D28/K28/16,0) -> 25.3 | Y28: =+IFERROR(P28/M28/22,0) -> 3.8601399 | Z28: star laoding awal shift jam 19:35, isi fuel jam 20:17 - 20:28 = 11 menit, stop loading menjelang istirahat jam 23:50 = 10 menit, star laoding setelah istirahat jam 01:00, stop loading kahir shift jam 06:53 = 7 menit, total loss time tidak normal = 28 menit
B29: =fleet!C35 -> M ARDAN
A30: MALAM | B30: CAT 395-01 | C30: 5000 | D30: =fleet!G33 -> 6006 | E30: =D30/C30 -> 1.2012 | F30: Seam ST-1 | G30: =C30-D30 -> -1006 | H30: 10 | I30: 10 | J30: =9+(48/60) -> 9.8 | K30: =fleet!F33 -> 10 | L30: 4 | M30: 4 | N30: 500 | O30: =+D30/I30 -> 600.6 | P30: =+IFERROR(D30/J30,0) -> 612.85714 | Q30: =+IFERROR(D30/K30,0) -> 600.6 | R30: =+N30*J30 -> 4900 | S30: =+R30-D30 -> -1106 | T30: =+N30*K30 -> 5000 | U30: =T30-D30 -> -1006 | V30: 1.02 | W30: =D30/C30 -> 1.2012 | X30: =+IFERROR(D30/K30/22,0) -> 27.3 | Y30: =+IFERROR(P30/M30/22,0) -> 6.9642857 | Z30: star laoding awal shift jam 19:40, stop loading menjelang istirahat jam 23:58 = 2 menit, star laoding setelah istirahat jam 01:05 = 5 menit, stop loading akhir shfit jam 06:55 = 5 menit, total loss time tidak normal = 12 menit
B31: =fleet!C33 -> OBETH
A33: MALAM | B33: PC 1250 11 | C33: 5000 | D33: =fleet!G40 -> 4268 | E33: =D33/C33 -> 0.8536 | F33: Seam ST-1 | G33: =C33-D33 -> 732 | H33: 10 | I33: 10 | J33: =9+(38/60) -> 9.6333333 | K33: =fleet!F40 -> 10 | L33: 4 | M33: 4 | N33: 500 | O33: =+D33/I33 -> 426.8 | P33: =+IFERROR(D33/J33,0) -> 443.04498 | Q33: =+IFERROR(D33/K33,0) -> 426.8 | R33: =+N33*J33 -> 4816.6667 | S33: =+R33-D33 -> 548.66667 | T33: =+N33*K33 -> 5000 | U33: =T33-D33 -> 732 | V33: 1.02 | W33: =D33/C33 -> 0.8536 | X33: =+IFERROR(D33/K33/22,0) -> 19.4 | Y33: =+IFERROR(P33/M33/22,0) -> 5.0346021 | Z33: star loading awal shift jam 19:53, stop loading menjelang istirahat jam 23:51 = 9 menit, star loading setelah istirahat jam 01:03 = 3 menit, stop loading akhir shift jam 06:50 = 10 menit, total loss time tidak normal = 22 menit
B34: =fleet!C40 -> ARKADIUS
A35: MALAM | B35: EC 750 01 | C35: 3500 | D35: =fleet!G39 -> 3476 | E35: =D35/C35 -> 0.99314286 | F35: Seam ST-1 | G35: =C35-D35 -> 24 | H35: 10 | I35: 10 | J35: =8+(14/60) -> 8.2333333 | K35: =fleet!F39 -> 9 | L35: 3 | M35: 3 | N35: 350 | O35: =+D35/I35 -> 347.6 | P35: =+IFERROR(D35/J35,0) -> 422.18623 | Q35: =+IFERROR(D35/K35,0) -> 386.22222 | R35: =+N35*J35 -> 2881.6667 | S35: =+R35-D35 -> -594.33333 | T35: =+N35*K35 -> 3150 | U35: =T35-D35 -> -326 | V35: 1.02 | W35: =D35/C35 -> 0.99314286 | X35: =+IFERROR(D35/K35/22,0) -> 17.555556 | Y35: =+IFERROR(P35/M35/22,0) -> 6.3967611 | Z35: travel jam 08:00 - 08:20 = 20 menit, star loading awal shift jam 08:20, stop loading menjelang istirahat jam 23:50 = 10 menit, star laoding setelah istirahat jam 13:06 = 6 menit, stop loading akhir shift jam 06:50 = 10 menit, total loss time tidak normal = 46 menit
B36: =fleet!C39 -> KARMAN
A37: Total Shift malam | C37: =+(C21+C23+C25+C28+C30+C33+C35) -> 23500 | D37: =SUM(D21:D35) -> 20988 | E37: =D37/C37 -> 0.89310638 | F37: =SUM(F21:F29) -> 0 | G37: =SUM(G21:G35) -> 2512 | H37: =SUM(H21:H35) -> 70 | I37: =SUM(I21:I35) -> 60 | J37: =SUM(J21:J35) -> 46.533333 | K37: =SUM(K21:K35) -> 49 | L37: =SUM(L21:L35) -> 26 | M37: =SUM(M21:M35) -> 20 | N37: =SUM(N21:N35) -> 3350 | ... S37: =SUM(S21:S35) -> 1043.6667
B40: Dibuat oleh | G40: Diperiksa oleh | S40: DIKETAHUI OLEH
B47: Berto | G47: Hadinoor | J47: Bonar Sari monang Naibaho | S47: Deddy Darmawan | X47: Ikhsan Nur Ramadhani
B48: Forman MCC | G48: SPI Produksi | J48: Manager Engineering | S48: Manager Produksi | X48: DGM Operation

Sheet SUMMARY
A2: TANGGAL 12 AGUSTUS 2024 2024 PIT 50
A4: SHIFT SIANG | B4: SELATAN | P4: BATU BARA | R4: SR
B5: Unit | C5: plan | D5: Jarak | E5: Target Rit/jam | F5: Jumlah HD | G5: JAM Efektif | H5: HM Engine | I5: Aktual Ritase | J5: Seharusnya | K5: Aktual BCM | L5: % | M5: Prod by EWH | N5: Prod by HM | O5: Rit / Jam
B6: 1250-01 | C6: 500 | D6: 1.02 | E6: 6 | F6: ='12'!M6 -> 0 | G6: ='12'!J6 -> 0 | H6: ='12'!K6 -> 0 | I6: =+K6/22 -> 0 | J6: =C6*H6 -> 0 | K6: ='12'!D6 -> 0 | L6: =K6/J6 -> #DIV/0! | M6: ='12'!P6 -> 0 | N6: ='12'!Q6 -> 0 | O6: ='12'!Y6 -> 0 | P6: 1830.65 | R6: =+IFERROR(K16/P6,0) -> 10.923989
B7: 1250-06 | C7: 500 | D7: 1.02 | E7: 6 | F7: ='12'!M8 -> 4 | G7: ='12'!J8 -> 9.3833333 | H7: ='12'!K8 -> 10 | I7: =+K7/22 -> 170 | J7: =C7*H7 -> 5000 | K7: ='12'!D8 -> 3740 | L7: =K7/J7 -> 0.748 | M7: ='12'!P8 -> 398.57904 | N7: ='12'!Q8 -> 374 | O7: ='12'!Y8 -> 4.5293073
B8: EC750-01 | C8: 350 | D8: 1.02 | E8: 6 | F8: ='12'!M18 -> 4 | G8: ='12'!J18 -> 7.4333333 | H8: ='12'!K18 -> 10 | I8: =+K8/22 -> 145 | J8: =C8*H8 -> 3500 | K8: ='12'!D18 -> 3190 | L8: =K8/J8 -> 0.91142857 | M8: ='12'!P18 -> 429.14798 | N8: ='12'!Q18 -> 319 | O8: ='12'!Y18 -> 4.8766816
B9: 1250-11 | C9: 500 | D9: 1.02 | E9: 6 | F9: ='12'!M16 -> 4 | G9: ='12'!J16 -> 9.7666667 | H9: ='12'!K16 -> 10 | I9: =+K9/22 -> 239 | J9: =C9*H9 -> 5000 | K9: ='12'!D16 -> 5258 | L9: =K9/J9 -> 1.0516 | M9: ='12'!P16 -> 538.36177 | N9: ='12'!Q16 -> 525.8 | O9: ='12'!Y16 -> 6.1177474
B10: CAT395-01 | C10: 500 | D10: 1.02 | E10: 6 | F10: ='12'!M12 -> 5 | G10: ='12'!J12 -> 9.6 | H10: ='12'!K12 -> 10 | I10: =+K10/22 -> 184 | J10: =C10*H10 -> 5000 | K10: ='12'!D12 -> 4048 | L10: =K10/J10 -> 0.8096 | M10: ='12'!P12 -> 421.66667 | N10: ='12'!Q12 -> 404.8 | O10: ='12'!Y12 -> 3.8333333
B11: TOTAL | G11: =SUM(G6:G10) -> 36.183333 | H11: =SUM(H6:H10) -> 40 | I11: =SUM(I7:I8) -> 315 | J11: =SUM(J6:J10) -> 18500 | K11: =SUM(K6:K10) -> 16236 | L11: =K11/J11 -> 0.87762162 | M11: =IFERROR(K11/G11,0) -> 448.71488 | N11: =IFERROR(K11/H11,0) -> 405.9
B12: UTARA | C12: plan | D12: Jarak | E12: Target Rit/jam | F12: Jumlah HD | G12: JAM Efektif | H12: HM Engine | I12: Aktual Ritase | J12: Seharusnya | K12: Aktual BCM | L12: % | M12: Prod by EWH | N12: Prod by HM | O12: Rit / Jam
B13: 1250-08 | C13: 500 | G13: ='12'!J10 -> 0 | H13: ='12'!K10 -> 0 | I13: =+K13/22 -> 0 | J13: =C13*H13 -> 0 | K13: ='12'!D10 -> 0 | L13: =K13/J13 -> #DIV/0! | M13: ='12'!P10 -> 0 | N13: ='12'!Q10 -> 0 | O13: ='12'!Y10 -> 0
B14: 1250-09 | C14: 500 | D14: 1.34 | E14: 5 | F14: ='12'!M14 -> 5 | G14: ='12'!J14 -> 8.9666667 | H14: ='12'!K14 -> 10 | I14: =+K14/22 -> 171 | J14: =C14*H14 -> 5000 | K14: ='12'!D14 -> 3762 | L14: =K14/J14 -> 0.7524 | M14: ='12'!P14 -> 419.5539 | N14: ='12'!Q14 -> 376.2 | O14: ='12'!Y14 -> 3.8141264
B15: TOTAL | G15: =SUM(G13:G14) -> 8.9666667 | H15: =SUM(H13:H14) -> 10 | I15: =SUM(I13:I14) -> 171 | J15: =SUM(J13:J14) -> 5000 | K15: =SUM(K13:K14) -> 3762 | L15: =K15/J15 -> 0.7524 | M15: =IFERROR(K15/G15,0) -> 419.5539 | N15: =IFERROR(K15/H15,0) -> 376.2
A16: TOTAL SHIFT PAGI | G16: =G11+G15 -> 45.15 | H16: =H11+H15 -> 50 | I16: =I11+I15 -> 486 | J16: =J11+J15 -> 23500 | K16: =K11+K15 -> 19998 | L16: =K16/J16 -> 0.85097872 | M16: =IFERROR(K16/G16,0) -> 442.92359 | N16: =IFERROR(K16/H16,0) -> 399.96
A19: SHIFT MALAM | B19: SELATAN | P19: BATU BARA | R19: SR
B20: Unit | C20: plan | D20: Jarak | E20: Target Rit/jam | F20: Jumlah HD | G20: JAM Efektif | H20: HM Engine | I20: Aktual Ritase | J20: Seharusnya | K20: Aktual BCM | L20: % | M20: Prod by EWH | N20: Prod by HM | O20: Rit / Jam
B21: 1250-01 | C21: 500 | D21: 1.02 | E21: 5 | F21: ='12'!M21 -> 0 | G21: ='12'!J21 -> 0 | H21: ='12'!K21 -> 0 | I21: =+K21/22 -> 0 | J21: =C21*H21 -> 0 | K21: ='12'!D21 -> 0 | L21: =K21/J21 -> #DIV/0! | M21: ='12'!P21 -> 0 | N21: ='12'!Q21 -> 0 | O21: ='12'!Y21 -> 0 | P21: 1830.65 | R21: =+IFERROR(K31/P21,0) -> 11.46478
B22: 1250-06 | C22: 500 | D22: 1.02 | E22: 5 | F22: ='12'!M23 -> 4 | G22: ='12'!J23 -> 9.3333333 | H22: ='12'!K23 -> 10 | I22: =+K22/22 -> 145 | J22: =C22*H22 -> 5000 | K22: ='12'!D23 -> 3190 | L22: =K22/J22 -> 0.638 | M22: ='12'!P23 -> 341.78571 | N22: ='12'!Q23 -> 319 | O22: ='12'!Y23 -> 3.8839286
B23: 1250-11 | C23: 500 | D23: 1.02 | E23: 5 | F23: ='12'!M33 -> 4 | G23: ='12'!J33 -> 9.6333333 | H23: ='12'!K33 -> 10 | I23: =+K23/22 -> 194 | J23: =C23*H23 -> 5000 | K23: ='12'!D33 -> 4268 | L23: =K23/J23 -> 0.8536 | M23: ='12'!P33 -> 443.04498 | N23: ='12'!Q33 -> 426.8 | O23: ='12'!Y33 -> 5.0346021
B24: EC750-01 | C24: 350 | D24: 1.02 | E24: 5 | F24: ='12'!M35 -> 3 | G24: ='12'!J35 -> 8.2333333 | H24: ='12'!K35 -> 9 | I24: =+K24/22 -> 158 | J24: =C24*H24 -> 3150 | K24: ='12'!D35 -> 3476 | L24: =K24/J24 -> 1.1034921 | M24: ='12'!P35 -> 422.18623 | N24: ='12'!Q35 -> 386.22222 | O24: ='12'!Y35 -> 6.3967611
B25: CAT395-01 | C25: 500 | D25: 1.02 | E25: 5 | F25: ='12'!M30 -> 4 | G25: ='12'!J30 -> 9.8 | H25: ='12'!K30 -> 10 | I25: =+K25/22 -> 273 | J25: =C25*H25 -> 5000 | K25: ='12'!D30 -> 6006 | L25: =K25/J25 -> 1.2012 | M25: ='12'!P30 -> 612.85714 | N25: ='12'!Q30 -> 600.6 | O25: ='12'!Y30 -> 6.9642857
B26: TOTAL | G26: =SUM(G21:G25) -> 37 | H26: =SUM(H21:H25) -> 39 | I26: =SUM(I21:I25) -> 770 | J26: =SUM(J21:J25) -> 18150 | K26: =SUM(K22:K25) -> 16940 | L26: =K26/J26 -> 0.93333333 | M26: =K26/G26 -> 457.83784 | N26: =K26/H26 -> 434.35897
B27: UTARA | C27: plan | D27: Jarak | E27: Target Rit/jam | F27: Jumlah HD | G27: JAM Efektif | H27: HM Engine | I27: Aktual Ritase | J27: Seharusnya | K27: Aktual BCM | L27: % | M27: Prod by EWH | N27: Prod by HM | O27: Rit / Jam
B28: 1250-08 | C28: 500 | D28: 1.34 | E28: 5 | F28: ='12'!M25 -> 0 | G28: ='12'!J25 -> 0 | H28: ='12'!K25 -> 0 | I28: =+K28/22 -> 0 | J28: =C28*H28 -> 0 | K28: ='12'!D25 -> 0 | L28: =K28/J28 -> #DIV/0! | M28: ='12'!P25 -> 0 | N28: ='12'!Q25 -> 0 | O28: ='12'!Y25 -> 0
B29: 1250-09 | C29: 500 | D29: 1.34 | E29: 5 | F29: ='12'!M28 -> 5 | G29: ='12'!J28 -> 9.5333333 | H29: ='12'!K28 -> 10 | I29: =+K29/22 -> 184 | J29: =C29*H29 -> 5000 | K29: ='12'!D28 -> 4048 | L29: =K29/J29 -> 0.8096 | M29: ='12'!P28 -> 424.61538 | N29: ='12'!Q28 -> 404.8 | O29: ='12'!Y28 -> 3.8601399
B30: TOTAL | G30: =SUM(G28:G29) -> 9.5333333 | H30: =SUM(H28:H29) -> 10 | I30: =SUM(I28:I29) -> 184 | J30: =SUM(J28:J29) -> 5000 | K30: =SUM(K28:K29) -> 4048 | L30: =K30/J30 -> 0.8096 | M30: =K30/G30 -> 424.61538 | N30: =K30/H30 -> 404.8
A31: TOTAL SHIFT MALAM | G31: =G26+G30 -> 46.533333 | H31: =H26+H30 -> 49 | I31: =I26+I30 -> 954 | J31: =J26+J30 -> 23150 | K31: =K26+K30 -> 20988 | L31: =K31/J31 -> 0.90660907 | M31: =K31/G31 -> 451.03152 | N31: =K31/H31 -> 428.32653
A33: TOTAL SIANG MALAM | G33: =G16+G31 -> 91.683333 | H33: =+H16+H31 -> 99 | I33: =I16+I31 -> 1440 | J33: =(J16+J31) -> 46650 | K33: =K31+K16 -> 40986 | L33: =K33/J33 -> 0.87858521 | M33: =K33/G33 -> 447.03872 | N33: =K33/H33 -> 414 | P33: =P6+P21 -> 3661.3 | R33: =IFERROR(K33/P33,0) -> 11.194385

Sheet Sheet2
B4: 0.74305556 | C4: 0.79166667 | D4: =C4-B4 -> 0.048611111
